<?xml version="1.0" ?>
<!-- =================================================================================== -->
<!-- |    This document was autogenerated by xacro from ur5_joint_limited_robot.urdf.xacro | -->
<!-- |    EDITING THIS FILE BY HAND IS NOT RECOMMENDED                                 | -->
<!-- =================================================================================== -->
<robot name="Theia" xmlns:xacro="http://wiki.ros.org/xacro">
 
 <link name="table_base_link">
     <tag part="base"/>
 </link>
 
 <joint name="table_base" type="fixed">
     <parent link="table_base_link"/>
     <child link="table"/>
     <origin rpy="0 0 0" xyz="0.2 0 -0.4"/>
     <axis xyz="0 0 1"/>
 </joint>
  
 <link name="table">
     <visual>
        <geometry>
          <box size="0.6 1.2 0.8"/>
        </geometry>
     </visual>
     <collision>
        <geometry>
          <box size="0.6 1.2 0.8"/>
        </geometry>
     </collision>
     <inertial>
        <mass value="150.0"/>
        <origin rpy="0.0 0.0 0.0" xyz="0.0 0.0 0.0"/>
        <inertia ixx="0.00443333156" ixy="0.0" ixz="0.0" iyy="0.00443333156" iyz="0.0" izz="0.0072"/>
     </inertial>
     <tag part="base"/>
 </link>

    <joint name="head_base_joint" type="fixed">
        <parent link="table_base_link"/>
        <child link="head_base"/>
        <origin rpy="0 0 1.57080" xyz="0 0 0"/>
        <axis xyz="0 0 1"/>
    </joint>
    
    <link name="head_base">
        <visual>
            <geometry>
                <!--- 0.0 0 -0.04  1.5708 3.14159-->
                <mesh filename="meshes/elephantbot/base.dae"/>
            </geometry>
            <origin xyz = "0.0 0 0 " rpy = " 0 0 1.5708"/>
        </visual>
        <collision>
            <geometry>
                <!--- 0.0 0 -0.04  1.5708 3.14159-->
                <mesh filename="meshes/elephantbot/base.dae"/>
            </geometry>
            <origin xyz = "0.0 0 0 " rpy = " 0 0 1.5708"/>
        </collision>
    </link>

    <joint name="head_joint2_to_joint1" type="revolute">
        <axis xyz="0 0 1"/>
        <limit effort = "1000.0" lower = "-2.96" upper = "2.96" velocity = "0"/>
        <parent link="head_base"/>
        <child link="head_link1"/>
        <origin xyz= "0 0 0.173" rpy = "0 0 0"/>
    </joint>

    <link name="head_link1">
        <visual>
            <geometry>
                <mesh filename="meshes/elephantbot/link1.dae"/>
            </geometry>

            <origin xyz = "0.0 0.0 -0.078 " rpy = " 0 0 1.5708"/>
        </visual>
        <collision>
            <geometry>
                <mesh filename="meshes/elephantbot/link1.dae"/>
            </geometry>
            <origin xyz = "0.0 0.0 -0.078 " rpy = " 0 0 1.5708"/>
        </collision>
    </link>

    <joint name="head_joint3_to_joint2" type="revolute">
        <axis xyz="0 0 1"/>
        <limit effort = "1000.0" lower = "-2.79" upper = "2.79" velocity = "0"/>
        <parent link="head_link1"/>
        <child link="head_link2"/>
        <origin xyz= "-0.086 0 0" rpy = "0 1.57080 3.14"/>
    </joint>

    <link name="head_link2">
        <visual>
            <geometry>
                <mesh filename="meshes/elephantbot/link2.dae"/>
            </geometry>
            <origin xyz = "0.0 0.0 -0.04" rpy = " 1.5708 3.14 0"/>
        </visual>
        <collision>
            <geometry>
                <mesh filename="meshes/elephantbot/link2.dae"/>
            </geometry>
            <origin xyz = "0.0 0.0 -0.04" rpy = " 1.5708 3.14 0"/>
        </collision>
    </link>

    <joint name="head_joint4_to_joint3" type="revolute">
        <axis xyz=" 0 0 1"/>
        <limit effort = "1000.0" lower = "-2.79" upper = "2.79" velocity = "0"/>
        <parent link="head_link2"/>
        <child link="head_link3"/>
        <origin xyz= "-0.13635 0 -0.086" rpy = "1.5708 0 0"/>
    </joint>

    <link name="head_link3">
        <visual>
            <geometry>
                <!--- 0.0 0 -0.04 -->
                <mesh filename="meshes/elephantbot/link3.dae"/>
            </geometry>
            <origin xyz = "0.0 0.04 0 " rpy = "1.5708 0 -1.5708"/>
        </visual>
        <collision>
            <geometry>
                <mesh filename="meshes/elephantbot/link3.dae"/>
            </geometry>
            <origin xyz = "0.0 0.04 0 " rpy = "1.5708 0 -1.5708"/>
        </collision>
    </link>

    <joint name="head_joint5_to_joint4" type="revolute">
        <axis xyz=" 0 0 1"/>
        <limit effort = "1000.0" lower = "-2.79" upper = "2.79" velocity = "0"/>
        <parent link="head_link3"/>
        <child link="head_link4"/>
        <origin xyz = "-0.1195 0.082 0" rpy = " 0 0 1.57080"/>
    </joint>

    <link name="head_link4">
        <visual>
            <geometry>
                <!--- 0.0 0 -0.04 -->
                <mesh filename="meshes/elephantbot/link4.dae"/>
            </geometry>
            <origin xyz = "-0.0024 -0.05 0" rpy = "1.5708 0 -1.5708"/>
        </visual>
        <collision>
            <geometry>
                <!--- 0.0 0 -0.04 -->
                <mesh filename="meshes/elephantbot/link4.dae"/>
            </geometry>
            <origin xyz = "-0.0024 -0.05 0" rpy = "1.5708 0 -1.5708"/>
        </collision>
    </link>

    <joint name="head_joint6_to_joint5" type="revolute">
        <axis xyz="0 0 1"/>
        <limit effort = "1000.0" lower = "-2.96" upper = "2.96" velocity = "0"/>
        <parent link="head_link4"/>
        <child link="head_link5"/>
        <origin xyz= "-0.09415 0 0" rpy = "0 1.5708 0"/>
    </joint>

    <link name="head_link5">
        <visual>
            <geometry>
                <!--- 0.0 0 -0.04 -->
                <mesh filename="meshes/elephantbot/link5.dae"/>
            </geometry>
            <origin xyz = "0.0 -0.0015 0.05" rpy = "3.14 0 1.5708"/>
        </visual>
        <collision>
            <geometry>
                <!--- 0.0 0 -0.04 -->
                <mesh filename="meshes/elephantbot/link5.dae"/>
            </geometry>
            <origin xyz = "0.0 -0.0015 0.05" rpy = "3.14 0 1.5708"/>
        </collision>
    </link>
    
    <joint name="head_joint6output_to_joint6" type="revolute">
        <axis xyz="0 0 1"/>
        <limit effort = "1000.0" lower = "-3.05" upper = "3.05" velocity = "0"/>
        <parent link="head_link5"/>
        <child link="head_link6"/>
        <origin xyz= "0 -0.06635 0" rpy = "1.5708 0 0"/>
    </joint>

    <link name="head_link6">
        <visual>
            <geometry>
                <!--- 0.0 0 -0.04 -->
                <mesh filename="meshes/elephantbot/link6.dae"/>
            </geometry>
            <origin xyz = "0.0 0.0 -0.0215 " rpy = " 1.5708 1.5708 0"/>
        </visual>
        <collision>
            <geometry>
                <!--- 0.0 0 -0.04 -->
                <mesh filename="meshes/elephantbot/link6.dae"/>
            </geometry>
            <origin xyz = "0.0 0.0 -0.0215 " rpy = " 1.5708 1.5708 0"/>
        </collision>
        <tag part="head"/>
    </link>
    
  <joint name="right_arm_joint" type="fixed">
    <parent link="table_base_link"/>
    <child link="right_base_link"/>
    <origin rpy="0 0 3.148" xyz="0 -0.4 0"/>
    <axis xyz="0 0 1"/>
  </joint>
  <link name="right_base_link">
    <visual>
      <geometry>
        <mesh filename="meshes/ur5/visual/base.dae"/>
      </geometry>
      <material name="LightGrey">
        <color rgba="0.7 0.7 0.7 1.0"/>
      </material>
    </visual>
    <collision>
      <geometry>
        <mesh filename="meshes/ur5/collision/base.dae"/>
      </geometry>
    </collision>
    <inertial>
      <mass value="4.0"/>
      <origin rpy="0 0 0" xyz="0.0 0.0 0.0"/>
      <inertia ixx="0.00443333156" ixy="0.0" ixz="0.0" iyy="0.00443333156" iyz="0.0" izz="0.0072"/>
    </inertial>
  </link>
  <joint name="right_shoulder_pan_joint" type="revolute">
    <parent link="right_base_link"/>
    <child link="right_shoulder_link"/>
    <origin rpy="0.0 0.0 0.0" xyz="0.0 0.0 0.089159"/>
    <axis xyz="0 0 1"/>
    <limit effort="150.0" lower="-3.14159265359" upper="3.14159265359" velocity="3.15"/>
    <dynamics damping="0.0" friction="0.0"/>
  </joint>
  <link name="right_shoulder_link">
    <visual>
      <geometry>
        <mesh filename="meshes/ur5/visual/shoulder.dae"/>
      </geometry>
    </visual>
    <collision>
      <geometry>
        <mesh filename="meshes/ur5/collision/shoulder.dae"/>
      </geometry>
    </collision>
    <inertial>
      <mass value="3.7"/>
      <origin rpy="0 0 0" xyz="0.0 0.0 0.0"/>
      <inertia ixx="0.010267495893" ixy="0.0" ixz="0.0" iyy="0.010267495893" iyz="0.0" izz="0.00666"/>
    </inertial>
  </link>
  <joint name="right_shoulder_lift_joint" type="revolute">
    <parent link="right_shoulder_link"/>
    <child link="right_upper_arm_link"/>
    <origin rpy="0.0 1.57079632679 0.0" xyz="0.0 0.13585 0.0"/>
    <axis xyz="0 1 0"/>
    <limit effort="150.0" lower="-3.14159265359" upper="3.14159265359" velocity="3.15"/>
    <dynamics damping="0.0" friction="0.0"/>
  </joint>
  <link name="right_upper_arm_link">
    <visual>
      <geometry>
        <mesh filename="meshes/ur5/visual/upperarm.dae"/>
      </geometry>
      <material name="LightGrey">
        <color rgba="0.7 0.7 0.7 1.0"/>
      </material>
    </visual>
    <collision>
      <geometry>
        <mesh filename="meshes/ur5/collision/upperarm.dae"/>
      </geometry>
    </collision>
    <inertial>
      <mass value="8.393"/>
      <origin rpy="0 0 0" xyz="0.0 0.0 0.28"/>
      <inertia ixx="0.22689067591" ixy="0.0" ixz="0.0" iyy="0.22689067591" iyz="0.0" izz="0.0151074"/>
    </inertial>
  </link>
  <joint name="right_elbow_joint" type="revolute">
    <parent link="right_upper_arm_link"/>
    <child link="right_forearm_link"/>
    <origin rpy="0.0 0.0 0.0" xyz="0.0 -0.1197 0.425"/>
    <axis xyz="0 1 0"/>
    <limit effort="150.0" lower="0" upper="3.14159265359" velocity="3.15"/>
    <dynamics damping="0.0" friction="0.0"/>
  </joint>
  <link name="right_forearm_link">
    <visual>
      <geometry>
        <mesh filename="meshes/ur5/visual/forearm.dae"/>
      </geometry>
      <material name="LightGrey">
        <color rgba="0.7 0.7 0.7 1.0"/>
      </material>
    </visual>
    <collision>
      <geometry>
        <mesh filename="meshes/ur5/collision/forearm.dae"/>
      </geometry>
    </collision>
    <inertial>
      <mass value="2.275"/>
      <origin rpy="0 0 0" xyz="0.0 0.0 0.196125"/>
      <inertia ixx="0.0312167910289" ixy="0.0" ixz="0.0" iyy="0.0312167910289" iyz="0.0" izz="0.004095"/>
    </inertial>
  </link>
  <joint name="right_wrist_1_joint" type="revolute">
    <parent link="right_forearm_link"/>
    <child link="right_wrist_1_link"/>
    <origin rpy="0.0 1.57079632679 0.0" xyz="0.0 0.0 0.39225"/>
    <axis xyz="0 1 0"/>
    <limit effort="28.0" lower="-3.14159265359" upper="3.14159265359" velocity="3.2"/>
    <dynamics damping="0.0" friction="0.0"/>
  </joint>
  <link name="right_wrist_1_link">
    <visual>
      <geometry>
        <mesh filename="meshes/ur5/visual/wrist1.dae"/>
      </geometry>
      <material name="LightGrey">
        <color rgba="0.7 0.7 0.7 1.0"/>
      </material>
    </visual>
    <collision>
      <geometry>
        <mesh filename="meshes/ur5/collision/wrist1.dae"/>
      </geometry>
    </collision>
    <inertial>
      <mass value="1.219"/>
      <origin rpy="0 0 0" xyz="0.0 0.093 0.0"/>
      <inertia ixx="0.00255989897604" ixy="0.0" ixz="0.0" iyy="0.00255989897604" iyz="0.0" izz="0.0021942"/>
    </inertial>
  </link>
  <joint name="right_wrist_2_joint" type="revolute">
    <parent link="right_wrist_1_link"/>
    <child link="right_wrist_2_link"/>
    <origin rpy="0.0 0.0 0.0" xyz="0.0 0.093 0.0"/>
    <axis xyz="0 0 1"/>
    <limit effort="28.0" lower="-3.14159265359" upper="3.14159265359" velocity="3.2"/>
    <dynamics damping="0.0" friction="0.0"/>
  </joint>
  <link name="right_wrist_2_link">
    <visual>
      <geometry>
        <mesh filename="meshes/ur5/visual/wrist2.dae"/>
      </geometry>
      <material name="LightGrey">
        <color rgba="0.7 0.7 0.7 1.0"/>
      </material>
    </visual>
    <collision>
      <geometry>
        <mesh filename="meshes/ur5/collision/wrist2.dae"/>
      </geometry>
    </collision>
    <inertial>
      <mass value="1.219"/>
      <origin rpy="0 0 0" xyz="0.0 0.0 0.09465"/>
      <inertia ixx="0.00255989897604" ixy="0.0" ixz="0.0" iyy="0.00255989897604" iyz="0.0" izz="0.0021942"/>
    </inertial>
  </link>
  <joint name="right_wrist_3_joint" type="revolute">
    <parent link="right_wrist_2_link"/>
    <child link="right_wrist_3_link"/>
    <origin rpy="0.0 0.0 0.0" xyz="0.0 0.0 0.09465"/>
    <axis xyz="0 1 0"/>
    <limit effort="28.0" lower="-3.14159265359" upper="3.14159265359" velocity="3.2"/>
    <dynamics damping="0.0" friction="0.0"/>
  </joint>
  <link name="right_wrist_3_link">
    <visual>
      <geometry>
        <mesh filename="meshes/ur5/visual/wrist3.dae"/>
      </geometry>
      <material name="LightGrey">
        <color rgba="0.7 0.7 0.7 1.0"/>
      </material>
    </visual>
    <collision>
      <geometry>
        <mesh filename="meshes/ur5/collision/wrist3.dae"/>
      </geometry>
    </collision>
    <inertial>
      <mass value="0.1879"/>
      <origin rpy="1.57079632679 0 0" xyz="0.0 0.06505 0.0"/>
      <inertia ixx="8.46958911216e-05" ixy="0.0" ixz="0.0" iyy="8.46958911216e-05" iyz="0.0" izz="0.0001321171875"/>
    </inertial>
  </link>
  <joint name="right_ee_fixed_joint" type="fixed">
    <parent link="right_wrist_3_link"/>
    <child link="right_ee_link"/>
    <origin rpy="0.0 0.0 1.57079632679" xyz="0.0 0.0823 0.0"/>
  </joint>
  <link name="right_ee_link">
    <collision>
      <geometry>
        <box size="0.01 -0.01 0.01"/>
      </geometry>
      <origin rpy="0 0 0" xyz="-0.01 0 0"/>
    </collision>
  </link>
  
  <joint name="virtual_right" type="fixed">
      <origin xyz="0.025 0 0" rpy="0 0 0"/>
      <parent link="right_ee_link"/>
      <child link="right_buffer_link"/>
  </joint>
  
  <link name="right_buffer_link"> 
      <visual>
          <geometry>
            <box size="0.05 0.05 0.05"/>
          </geometry>
        </visual>
        <collision>
          <geometry>
            <box size="0.05 0.05 0.05"/>
          </geometry>
        </collision>
        <inertial>
          <mass value="150.0"/>
          <origin rpy="0.0 0.0 0.0" xyz="0.0 0.0 0.0"/>
          <inertia ixx="0.00443333156" ixy="0.0" ixz="0.0" iyy="0.00443333156" iyz="0.0" izz="0.0072"/>
        </inertial>
  </link>
  
  <joint name="right_buffer_joint" type="fixed">
      <origin xyz="-0.12 -0.29 0" rpy="3.14 0 1.57"/>
      <parent link="right_buffer_link"/>
      <child link="right_forearm_and_palm_subassembly"/>
  </joint>

    <joint name="grasping_frame_joint_right" type="fixed">
        <origin xyz="0.07 0 0" rpy="0 0 0"/>
        <parent link="right_buffer_link"/>
        <child link="grasping_frame_right"/>
    </joint>

    <link name="grasping_frame_right">
        <tag part="right_hand"/>
    </link>
  
  <link name="right_forearm_and_palm_subassembly">
  </link>
  
  <link name="Rpart_1_1">
  <visual>
  <origin xyz="-0.005 0 -0.0185" rpy="-1.5708 0 0" />
  <geometry>
  <mesh filename="meshes/right_artus/part_1_1.stl"/>
  </geometry>
  <material name="part_1_1_material">
  <color rgba="0.647 0.647 0.647 1.0"/>
  </material>
  </visual>
  <collision>
  <origin xyz="-0.005 0 -0.0185" rpy="-1.5708 0 0" />
  <geometry>
  <mesh filename="meshes/right_artus/part_1_1.stl"/>
  </geometry>
  </collision>
  <inertial>
  <origin xyz="0 0 0" rpy="0 0 0"/>
  <mass value="0" />
  <inertia ixx="0" ixy="0"  ixz="0" iyy="0" iyz="0" izz="0" />
  </inertial>
  </link>
  
  <link name="Rpart_1_6">
  <visual>
  <origin xyz="-0.02855 -0.00785 -0.006" rpy="-3.14 0 0" />
  <geometry>
  <mesh filename="meshes/right_artus/part_1_6.stl"/>
  </geometry>
  <material name="part_1_6_material">
  <color rgba="0.6156 0.81176 0.9294 1.0"/>
  </material>
  </visual>
  <collision>
  <origin xyz="-0.02855 -0.00785 -0.006" rpy="-3.14 0 0" />
  <geometry>
  <mesh filename="meshes/right_artus/part_1_6.stl"/>
  </geometry>
  </collision>
  <inertial>
  <origin xyz="0 0 0" rpy="0 0 0"/>
  <mass value="0" />
  <inertia ixx="0" ixy="0"  ixz="0" iyy="0" iyz="0" izz="0" />
  </inertial>
  </link>
  
  <link name="Rpart_1_12">
      <visual>
      <origin xyz="-0.0175 -0.00712 -0.005" rpy="-3.14 0 0" />
      <geometry>
      <mesh filename="meshes/right_artus/part_1_12.stl"/>
      </geometry>
      <material name="part_1_12_material">
      <color rgba="0.9176 0.9176 0.9176 1.0"/>
      </material>
      </visual>
      <collision>
      <origin xyz="-0.0175 -0.00712 -0.005" rpy="-3.14 0 0" />
      <geometry>
      <mesh filename="meshes/right_artus/part_1_12.stl"/>
      </geometry>
      </collision>
      <inertial>
      <origin xyz="0 0 0" rpy="0 0 0"/>
      <mass value="0" />
      <inertia ixx="0" ixy="0"  ixz="0" iyy="0" iyz="0" izz="0" />
      </inertial>
  </link>
  
  <link name="Rd1_urdf_mk_5_1">
      <visual>
          <origin xyz="-0.009 -0.006 -0.00475" rpy="-3.14 0 0" />
          <geometry>
            <mesh filename="meshes/right_artus/d1_urdf_mk_5_1.stl"/>
          </geometry>
          <material name="d1_urdf_mk_5_1_material">
            <color rgba="0.2313 0.3803 0.7058 1.0"/>
          </material>
      </visual>
      <collision>
          <origin xyz="-0.009 -0.006 -0.00475" rpy="-3.14 0 0" />
          <geometry>
            <mesh filename="meshes/right_artus/d1_urdf_mk_5_1.stl"/>
          </geometry>
      </collision>
      <inertial>
          <origin xyz="0 0 0" rpy="0 0 0"/>
          <mass value="0" />
          <inertia ixx="0" ixy="0"  ixz="0" iyy="0" iyz="0" izz="0" />
      </inertial>
  </link>
  
  <joint name="Rpinky_34" type="revolute">
  <origin xyz="-0.025 0 -0.00025" rpy="0 0 0" />
  <parent link="Rpart_1_12" />
  <child link="Rd1_urdf_mk_5_1" />
  <axis xyz="0 0 1"/>
  <limit effort="100" velocity="20" lower="0" upper="1.570796326794896558"/>
  <joint_properties friction="0.0"/>
  </joint>
  
  <joint name="Rpinky_23" type="revolute">
  <origin xyz="-0.038 0.00075 -0.00075" rpy="0 0 0" />
  <parent link="Rpart_1_6" />
  <child link="Rpart_1_12" />
  <axis xyz="0 0 1"/>
  <limit effort="100" velocity="20" lower="0" upper="1.570796326794896558"/>
  <joint_properties friction="0.0"/>
  </joint>
  
  <joint name="Rpinky_12" type="revolute">
  <origin xyz="-0.01475 -0.006 -0.0095" rpy="1.5707 -0.017066 0" />
  <parent link="Rpart_1_1" />
  <child link="Rpart_1_6" />
  <axis xyz="0 0 1"/>
  <limit effort="100" velocity="20" lower="0" upper="1.570796326794896558"/>
  <joint_properties friction="0.0"/>
  </joint>
  
  <joint name="Rpinky_01" type="revolute">
  <origin xyz="0.312 0.209 0.0232" rpy="0 0 -1.6929693744344997963" />
  <parent link="right_forearm_and_palm_subassembly" />
  <child link="Rpart_1_1" />
  <axis xyz="0 0 1"/>
  <limit effort="100" velocity="20" lower="-0.29670597283903604735" upper="0.29670597283903604735"/>
  <joint_properties friction="0.0"/>
  </joint>
  
  <link name="Rpart_1_2">
  <visual>
  <origin xyz="-0.005 0 -0.0185" rpy="-1.5708 0 0" />
  <geometry>
  <mesh filename="meshes/right_artus/part_1_2.stl"/>
  </geometry>
  <material name="part_1_2_material">
  <color rgba="0.6470 0.6470 0.6470 1.0"/>
  </material>
  </visual>
  <collision>
  <origin xyz="-0.005 0 -0.0185" rpy="-1.5708 0 0" />
  <geometry>
  <mesh filename="meshes/right_artus/part_1_2.stl"/>
  </geometry>
  </collision>
  <inertial>
  <origin xyz="0 0 0" rpy="0 0 0"/>
  <mass value="0" />
  <inertia ixx="0" ixy="0"  ixz="0" iyy="0" iyz="0" izz="0" />
  </inertial>
  </link>
  
  <link name="Rpart_1_7">
  <visual>
  <origin xyz="-0.0285 -0.0078 -0.006" rpy="-3.14 0 0" />
  <geometry>
  <mesh filename="meshes/right_artus/part_1_7.stl"/>
  </geometry>
  <material name="part_1_7_material">
  <color rgba="0.6156 0.8117 0.9294 1.0"/>
  </material>
  </visual>
  <collision>
  <origin xyz="-0.0285 -0.0078 -0.006" rpy="-3.14 0 0" />
  <geometry>
  <mesh filename="meshes/right_artus/part_1_7.stl"/>
  </geometry>
  </collision>
  <inertial>
  <origin xyz="0 0 0" rpy="0 0 0"/>
  <mass value="0" />
  <inertia ixx="0" ixy="0"  ixz="0" iyy="0" iyz="0" izz="0" />
  </inertial>
  </link>
  
  <link name="Rpart_1_11">
  <visual>
  <origin xyz="-0.0175 -0.00712 -0.00525" rpy="-3.14 0 0" />
  <geometry>
  <mesh filename="meshes/right_artus/part_1_11.stl"/>
  </geometry>
  <material name="part_1_11_material">
  <color rgba="0.91764 0.91764 0.91764 1.0"/>
  </material>
  </visual>
  <collision>
  <origin xyz="-0.017524 -0.00712 -0.00525" rpy="-3.14 0 0" />
  <geometry>
  <mesh filename="meshes/right_artus/part_1_11.stl"/>
  </geometry>
  </collision>
  <inertial>
  <origin xyz="0 0 0" rpy="0 0 0"/>
  <mass value="0" />
  <inertia ixx="0" ixy="0"  ixz="0" iyy="0" iyz="0" izz="0" />
  </inertial>
  </link>
  
  <link name="Rd1_urdf_mk_5_4">
  <visual>
  <origin xyz="-0.009 -0.006 -0.00475" rpy="-3.14 0 0" />
  <geometry>
  <mesh filename="meshes/right_artus/d1_urdf_mk_5_4.stl"/>
  </geometry>
  <material name="d1_urdf_mk_5_4_material">
  <color rgba="0.2313 0.3804 0.70588 1.0"/>
  </material>
  </visual>
  <collision>
  <origin xyz="-0.009 -0.006 -0.00475" rpy="-3.14 0 0" />
  <geometry>
  <mesh filename="meshes/right_artus/d1_urdf_mk_5_4.stl"/>
  </geometry>
  </collision>
  <inertial>
  <origin xyz="0 0 0" rpy="0 0 0"/>
  <mass value="0" />
  <inertia ixx="0" ixy="0"  ixz="0" iyy="0" iyz="0" izz="0" />
  </inertial>
  </link>
  
  <joint name="Rring_34" type="revolute">
  <origin xyz="-0.025 0 -0.0005" rpy="0 0 0" />
  <parent link="Rpart_1_11" />
  <child link="Rd1_urdf_mk_5_4" />
  <axis xyz="0 0 1"/>
  <limit effort="100" velocity="20" lower="0" upper="1.570796326794896558"/>
  <joint_properties friction="0.0"/>
  </joint>
  
  <joint name="Rring_23" type="revolute">
  <origin xyz="-0.038 0.00075 -0.00075" rpy="0 0 0" />
  <parent link="Rpart_1_7" />
  <child link="Rpart_1_11" />
  <axis xyz="0 0 1"/>
  <limit effort="100" velocity="20" lower="0" upper="1.570796326794896558"/>
  <joint_properties friction="0.0"/>
  </joint>
  
  <joint name="Rring_12" type="revolute">
  <origin xyz="-0.01475 -0.006 -0.0095" rpy="1.57079632679489678 0 0" />
  <parent link="Rpart_1_2" />
  <child link="Rpart_1_7" />
  <axis xyz="0 0 1"/>
  <limit effort="100" velocity="20" lower="0" upper="1.570796326794896558"/>
  <joint_properties friction="0.0"/>
  </joint>
  
  <joint name="Rring_01" type="revolute">
  <origin xyz="0.2915 0.2167 0.0262" rpy="0 0 -1.6406" />
  <parent link="right_forearm_and_palm_subassembly" />
  <child link="Rpart_1_2" />
  <axis xyz="0 0 1"/>
  <limit effort="100" velocity="20" lower="-0.29670597283903604735" upper="0.29670597283903604735"/>
  <joint_properties friction="0.0"/>
  </joint>
  
  <link name="Rpart_1_4">
  <visual>
  <origin xyz="-0.005 0 -0.0185" rpy="-1.5708 0 0" />
  <geometry>
  <mesh filename="meshes/right_artus/part_1_4.stl"/>
  </geometry>
  <material name="part_1_4_material">
  <color rgba="0.6470 0.6470 0.6470 1.0"/>
  </material>
  </visual>
  <collision>
  <origin xyz="-0.005 0 -0.0185" rpy="-1.5708 0 0" />
  <geometry>
  <mesh filename="meshes/right_artus/part_1_4.stl"/>
  </geometry>
  </collision>
  <inertial>
  <origin xyz="0 0 0" rpy="0 0 0"/>
  <mass value="0" />
  <inertia ixx="0" ixy="0"  ixz="0" iyy="0" iyz="0" izz="0" />
  </inertial>
  </link>
  
  <link name="Rpart_1_5">
  <visual>
  <origin xyz="-0.02855 -0.007859 -0.006" rpy="-3.14 0 0" />
  <geometry>
  <mesh filename="meshes/right_artus/part_1_5.stl"/>
  </geometry>
  <material name="part_1_5_material">
  <color rgba="0.6156 0.8117 0.9294 1.0"/>
  </material>
  </visual>
  <collision>
  <origin xyz="-0.0285 -0.00786 -0.006" rpy="-3.14 0 0" />
  <geometry>
  <mesh filename="meshes/right_artus/part_1_5.stl"/>
  </geometry>
  </collision>
  <inertial>
  <origin xyz="0 0 0" rpy="0 0 0"/>
  <mass value="0" />
  <inertia ixx="0" ixy="0"  ixz="0" iyy="0" iyz="0" izz="0" />
  </inertial>
  </link>
  
  <link name="Rpart_1_10">
  <visual>
  <origin xyz="-0.01752 -0.00713 -0.00525" rpy="-3.14 0 0" />
  <geometry>
  <mesh filename="meshes/right_artus/part_1_10.stl"/>
  </geometry>
  <material name="part_1_10_material">
  <color rgba="0.917 0.917 0.917 1.0"/>
  </material>
  </visual>
  <collision>
  <origin xyz="-0.0175 -0.0071296 -0.00525" rpy="-3.14 0 0" />
  <geometry>
  <mesh filename="meshes/right_artus/part_1_10.stl"/>
  </geometry>
  </collision>
  <inertial>
  <origin xyz="0 0 0" rpy="0 0 0"/>
  <mass value="0" />
  <inertia ixx="0" ixy="0"  ixz="0" iyy="0" iyz="0" izz="0" />
  </inertial>
  </link>
  
  <link name="Rd1_urdf_mk_5_2">
  <visual>
  <origin xyz="-0.009 -0.006 -0.00475" rpy="-3.14 0 0" />
  <geometry>
  <mesh filename="meshes/right_artus/d1_urdf_mk_5_2.stl"/>
  </geometry>
  <material name="d1_urdf_mk_5_2_material">
  <color rgba="0.2313 0.3803 0.7058 1.0"/>
  </material>
  </visual>
  <collision>
  <origin xyz="-0.009 -0.006 -0.00475" rpy="-3.14 0 0" />
  <geometry>
  <mesh filename="meshes/right_artus/d1_urdf_mk_5_2.stl"/>
  </geometry>
  </collision>
  <inertial>
  <origin xyz="0 0 0" rpy="0 0 0"/>
  <mass value="0" />
  <inertia ixx="0" ixy="0"  ixz="0" iyy="0" iyz="0" izz="0" />
  </inertial>
  </link>
  
  <joint name="Rmiddle_34" type="revolute">
  <origin xyz="-0.025 0 -0.0005" rpy="0 0 0" />
  <parent link="Rpart_1_10" />
  <child link="Rd1_urdf_mk_5_2" />
  <axis xyz="0 0 1"/>
  <limit effort="100" velocity="20" lower="0" upper="1.570796326794896558"/>
  <joint_properties friction="0.0"/>
  </joint>
  
  <joint name="Rmiddle_23" type="revolute">
  <origin xyz="-0.038 0.00075 -0.00075" rpy="0 0 0" />
  <parent link="Rpart_1_5" />
  <child link="Rpart_1_10" />
  <axis xyz="0 0 1"/>
  <limit effort="100" velocity="20" lower="0" upper="1.570796326794896558"/>
  <joint_properties friction="0.0"/>
  </joint>
  
  <joint name="Rmiddle_12" type="revolute">
  <origin xyz="-0.01475 -0.006 -0.0095" rpy="1.570796326794896558 -0.0022 0" />
  <parent link="Rpart_1_4" />
  <child link="Rpart_1_5" />
  <axis xyz="0 0 1"/>
  <limit effort="100" velocity="20" lower="0" upper="1.570796326794896558"/>
  <joint_properties friction="0.0"/>
  </joint>
  
  <joint name="Rmiddle_01" type="revolute">
  <origin xyz="0.2702 0.2211 0.0292" rpy="0 0 -1.570796326794896558" />
  <parent link="right_forearm_and_palm_subassembly" />
  <child link="Rpart_1_4" />
  <axis xyz="0 0 1"/>
  <limit effort="100" velocity="20" lower="-0.29670597283903604735" upper="0.29670597283903604735"/>
  <joint_properties friction="0.0"/>
  </joint>
  
  <link name="Rpart_1_3">
  <visual>
  <origin xyz="-0.005 0 -0.018" rpy="-1.5708 0 0" />
  <geometry>
  <mesh filename="meshes/right_artus/part_1_3.stl"/>
  </geometry>
  <material name="part_1_3_material">
  <color rgba="0.6470 0.6470 0.6470 1.0"/>
  </material>
  </visual>
  <collision>
  <origin xyz="-0.005 0 -0.0183" rpy="0 0 0" />
  <geometry>
  <mesh filename="meshes/right_artus/part_1_3.stl"/>
  </geometry>
  </collision>
  <inertial>
  <origin xyz="0 0 0" rpy="0 0 0"/>
  <mass value="0" />
  <inertia ixx="0" ixy="0"  ixz="0" iyy="0" iyz="0" izz="0" />
  </inertial>
  </link>
  
  <link name="Rpart_1_8">
  <visual>
  <origin xyz="-0.02855 -0.00786 -0.006" rpy="-3.14 0 0" />
  <geometry>
  <mesh filename="meshes/right_artus/part_1_8.stl"/>
  </geometry>
  <material name="part_1_8_material">
  <color rgba="0.6156 0.8117 0.9294 1.0"/>
  </material>
  </visual>
  <collision>
  <origin xyz="-0.0285 -0.0078 -0.006" rpy="-3.14 0 0" />
  <geometry>
  <mesh filename="meshes/right_artus/part_1_8.stl"/>
  </geometry>
  </collision>
  <inertial>
  <origin xyz="0 0 0" rpy="0 0 0"/>
  <mass value="0" />
  <inertia ixx="0" ixy="0"  ixz="0" iyy="0" iyz="0" izz="0" />
  </inertial>
  </link>
  
  <link name="Rpart_1_9">
  <visual>
  <origin xyz="-0.01752 -0.007129 -0.00525" rpy="-3.14 0 0" />
  <geometry>
  <mesh filename="meshes/right_artus/part_1_9.stl"/>
  </geometry>
  <material name="part_1_9_material">
  <color rgba="0.91764705882352937127 0.91764705882352937127 0.91764705882352937127 1.0"/>
  </material>
  </visual>
  <collision>
  <origin xyz="-0.017524803018038770386 -0.0071295923980055943281 -0.005250000000000198952" rpy="-3.14 0 0" />
  <geometry>
  <mesh filename="meshes/right_artus/part_1_9.stl"/>
  </geometry>
  </collision>
  <inertial>
  <origin xyz="0 0 0" rpy="0 0 0"/>
  <mass value="0" />
  <inertia ixx="0" ixy="0"  ixz="0" iyy="0" iyz="0" izz="0" />
  </inertial>
  </link>
  
  <link name="Rd1_urdf_mk_5_3">
  <visual>
  <origin xyz="-0.0090000000000002300382 -0.0059999999999999654304 -0.0047499999999967568165" rpy="-3.14 0 0" />
  <geometry>
  <mesh filename="meshes/right_artus/d1_urdf_mk_5_3.stl"/>
  </geometry>
  <material name="d1_urdf_mk_5_3_material">
  <color rgba="0.2313725490196078538 0.38039215686274507888 0.7058823529411765163 1.0"/>
  </material>
  </visual>
  <collision>
  <origin xyz="-0.0090000000000002300382 -0.0059999999999999654304 -0.0047499999999967568165" rpy="-3.14 0 0" />
  <geometry>
  <mesh filename="meshes/right_artus/d1_urdf_mk_5_3.stl"/>
  </geometry>
  </collision>
  <inertial>
  <origin xyz="0 0 0" rpy="0 0 0"/>
  <mass value="0" />
  <inertia ixx="0" ixy="0"  ixz="0" iyy="0" iyz="0" izz="0" />
  </inertial>
  </link>
  
  <joint name="Rindex_34" type="revolute">
  <origin xyz="-0.024999999999999911182 -7.0082828429463006614e-16 0.00025000000000013899992" rpy="0 0 0" />
  <parent link="Rpart_1_9" />
  <child link="Rd1_urdf_mk_5_3" />
  <axis xyz="0 0 1"/>
  <limit effort="100" velocity="20" lower="0" upper="1.570796326794896558"/>
  <joint_properties friction="0.0"/>
  </joint>
  
  <joint name="Rindex_23" type="revolute">
  <origin xyz="-0.038000000000001032952 0.00075000000000002495226 1.1102230246251565404e-16" rpy="0 0 0" />
  <parent link="Rpart_1_8" />
  <child link="Rpart_1_9" />
  <axis xyz="0 0 1"/>
  <limit effort="100" velocity="20" lower="0" upper="1.570796326794896558"/>
  <joint_properties friction="0.0"/>
  </joint>
  
  <joint name="Rindex_12" type="revolute">
  <origin xyz="-0.014749999999999957589 -0.0060000000000002273737 -0.0093145856533065340965" rpy="1.5707963267948945596 -0.0030671090189098395608 0" />
  <parent link="Rpart_1_3" />
  <child link="Rpart_1_8" />
  <axis xyz="0 0 1"/>
  <limit effort="100" velocity="20" lower="0" upper="1.570796326794896558"/>
  <joint_properties friction="0.0"/>
  </joint>
  
  <joint name="Rindex_01" type="revolute">
  <origin xyz="0.24859938690798402683 0.21811973915038307403 0.026259033846879248353" rpy="0 0 -1.500983156715123501" />
  <parent link="right_forearm_and_palm_subassembly" />
  <child link="Rpart_1_3" />
  <axis xyz="0 0 1"/>
  <limit effort="100" velocity="20" lower="-0.29670597283903604735" upper="0.29670597283903604735"/>
  <joint_properties friction="0.0"/>
  </joint>
  
  <link name="Rpart_1_13">
  <visual>
  <origin xyz="-0.0050000000000000044409 0 0.00062867965644042289597" rpy="-3.141592653589793116 0 0" />
  <geometry>
  <mesh filename="meshes/right_artus/part_1_13.stl"/>
  </geometry>
  <material name="part_1_13_material">
  <color rgba="0.2313725490196078538 0.38039215686274507888 0.7058823529411765163 1.0"/>
  </material>
  </visual>
  <collision>
  <origin xyz="-0.0050000000000000044409 0 0.00062867965644042289597" rpy="-3.141592653589793116 0 0" />
  <geometry>
  <mesh filename="meshes/right_artus/part_1_13.stl"/>
  </geometry>
  </collision>
  <inertial>
  <origin xyz="0 0 0" rpy="0 0 0"/>
  <mass value="0" />
  <inertia ixx="0" ixy="0"  ixz="0" iyy="0" iyz="0" izz="0" />
  </inertial>
  </link>
  
  <link name="Rpart_1_14">
  <visual>
  <origin xyz="-0.029277356236810214707 -0.0078134566939175309486 -0.0067500000000003251843" rpy="-1.5707963267948961139 3.9585767009635685762e-16 3.162545811456038734e-17" />
  <geometry>
  <mesh filename="meshes/right_artus/part_1_14.stl"/>
  </geometry>
  <material name="part_1_14_material">
  <color rgba="0.64705882352941179736 0.64705882352941179736 0.64705882352941179736 1.0"/>
  </material>
  </visual>
  <collision>
  <origin xyz="-0.029277356236810214707 -0.0078134566939175309486 -0.0067500000000003251843" rpy="-1.5707963267948961139 3.9585767009635685762e-16 3.162545811456038734e-17" />
  <geometry>
  <mesh filename="meshes/right_artus/part_1_14.stl"/>
  </geometry>
  </collision>
  <inertial>
  <origin xyz="0 0 0" rpy="0 0 0"/>
  <mass value="0" />
  <inertia ixx="0" ixy="0"  ixz="0" iyy="0" iyz="0" izz="0" />
  </inertial>
  </link>
  
  <link name="Rpart_1_15">
  <visual>
  <origin xyz="-0.017524803018038631608 -0.0071295923980052022806 -0.0062499999999999639178" rpy="-1.57079632679489678 5.4727023498301658739e-16 -6.7447808807866834097e-18" />
  <geometry>
  <mesh filename="meshes/right_artus/part_1_15.stl"/>
  </geometry>
  <material name="part_1_15_material">
  <color rgba="0.61568627450980395466 0.81176470588235294379 0.92941176470588238168 1.0"/>
  </material>
  </visual>
  <collision>
  <origin xyz="-0.017524803018038631608 -0.0071295923980052022806 -0.0062499999999999639178" rpy="-1.57079632679489678 5.4727023498301658739e-16 -6.7447808807866834097e-18" />
  <geometry>
  <mesh filename="meshes/right_artus/part_1_15.stl"/>
  </geometry>
  </collision>
  <inertial>
  <origin xyz="0 0 0" rpy="0 0 0"/>
  <mass value="0" />
  <inertia ixx="0" ixy="0"  ixz="0" iyy="0" iyz="0" izz="0" />
  </inertial>
  </link>
  
  <link name="Rpart_1_16">
  <visual>
  <origin xyz="-0.0089999999999997512545 -0.0060000000000001163514 -0.0057500000000044876325" rpy="-1.570796326794896558 2.7383719824292942009e-16 1.1406760560585945855e-17" />
  <geometry>
  <mesh filename="meshes/right_artus/part_1_16.stl"/>
  </geometry>
  <material name="part_1_16_material">
  <color rgba="0.49803921568627451677 0.49803921568627451677 0.49803921568627451677 1.0"/>
  </material>
  </visual>
  <collision>
  <origin xyz="-0.0089999999999997512545 -0.0060000000000001163514 -0.0057500000000044876325" rpy="-1.570796326794896558 2.7383719824292942009e-16 1.1406760560585945855e-17" />
  <geometry>
  <mesh filename="meshes/right_artus/part_1_16.stl"/>
  </geometry>
  </collision>
  <inertial>
  <origin xyz="0 0 0" rpy="0 0 0"/>
  <mass value="0" />
  <inertia ixx="0" ixy="0"  ixz="0" iyy="0" iyz="0" izz="0" />
  </inertial>
  </link>
  
  <joint name="Rthumb_34" type="revolute">
  <origin xyz="-0.024999999999999703015 -4.4408920985006261617e-16 0.0010000000000001119105" rpy="7.190853025056170776e-15 1.5881675766873069476e-14 -1.0527834464743926316e-13" />
  <parent link="Rpart_1_15" />
  <child link="Rpart_1_16" />
  <axis xyz="0 0 1"/>
  <limit effort="100" velocity="20" lower="0" upper="1.570796326794896558"/>
  <joint_properties friction="0.0"/>
  </joint>
  
  <joint name="Rthumb_23" type="revolute">
  <origin xyz="-0.038000000000000797029 0.00075000000000041699977 -0.00050000000000000044409" rpy="-2.3414011226030129463e-15 -3.6553634511977772008e-14 2.2018853588283082281e-14" />
  <parent link="Rpart_1_14" />
  <child link="Rpart_1_15" />
  <axis xyz="0 0 1"/>
  <limit effort="100" velocity="20" lower="0" upper="1.570796326794896558"/>
  <joint_properties friction="0.0"/>
  </joint>
  
  <joint name="Rthumb_12" type="revolute">
  <origin xyz="-0.014749999999999971467 0.006750000000000019873 -0.0077499999999999236167" rpy="-1.57079632679489678 4.8576610287913724728e-06 -1.1395153954890297715e-14" />
  <parent link="Rpart_1_13" />
  <child link="Rpart_1_14" />
  <axis xyz="0 0 1"/>
  <limit effort="100" velocity="20" lower="0" upper="1.570796326794896558"/>
  <joint_properties friction="0.0"/>
  </joint>
  
  <joint name="Rthumb_01" type="revolute">
  <origin xyz="0.25975933290346764348 0.17603301569461013432 -0.0045818118468336655608" rpy="-2.0752759914175813449 -1.0057357117290099957 3.3224635203616947282e-14" />
  <parent link="right_forearm_and_palm_subassembly" />
  <child link="Rpart_1_13" />
  <axis xyz="0 0 1"/>
  <limit effort="100" velocity="20" lower="-0.64577182323790194296" upper="0.64577182323790194296"/>
  <joint_properties friction="0.0"/>
  </joint>

  
  
  <joint name="left_arm_joint" type="fixed">
      <parent link="table_base_link"/>
      <child link="left_base_link"/>
      <origin rpy="0 0 0" xyz="0 0.4 0"/>
      <axis xyz="0 0 1"/>
    </joint>
    <link name="left_base_link">
      <visual>
        <geometry>
          <mesh filename="meshes/ur5/visual/base.dae"/>
        </geometry>
        <material name="LightGrey">
          <color rgba="0.7 0.7 0.7 1.0"/>
        </material>
      </visual>
      <collision>
        <geometry>
          <mesh filename="meshes/ur5/collision/base.dae"/>
        </geometry>
      </collision>
      <inertial>
        <mass value="4.0"/>
        <origin rpy="0 0 0" xyz="0.0 0.0 0.0"/>
        <inertia ixx="0.00443333156" ixy="0.0" ixz="0.0" iyy="0.00443333156" iyz="0.0" izz="0.0072"/>
      </inertial>
    </link>
    <joint name="left_shoulder_pan_joint" type="revolute">
      <parent link="left_base_link"/>
      <child link="left_shoulder_link"/>
      <origin rpy="0.0 0.0 0.0" xyz="0.0 0.0 0.089159"/>
      <axis xyz="0 0 1"/>
      <limit effort="150.0" lower="-3.14159265359" upper="3.14159265359" velocity="3.15"/>
      <dynamics damping="0.0" friction="0.0"/>
    </joint>
    <link name="left_shoulder_link">
      <visual>
        <geometry>
          <mesh filename="meshes/ur5/visual/shoulder.dae"/>
        </geometry>
      </visual>
      <collision>
        <geometry>
          <mesh filename="meshes/ur5/collision/shoulder.dae"/>
        </geometry>
      </collision>
      <inertial>
        <mass value="3.7"/>
        <origin rpy="0 0 0" xyz="0.0 0.0 0.0"/>
        <inertia ixx="0.010267495893" ixy="0.0" ixz="0.0" iyy="0.010267495893" iyz="0.0" izz="0.00666"/>
      </inertial>
    </link>
    <joint name="left_shoulder_lift_joint" type="revolute">
      <parent link="left_shoulder_link"/>
      <child link="left_upper_arm_link"/>
      <origin rpy="0.0 1.57079632679 0.0" xyz="0.0 0.13585 0.0"/>
      <axis xyz="0 1 0"/>
      <limit effort="150.0" lower="-3.14159265359" upper="3.14159265359" velocity="3.15"/>
      <dynamics damping="0.0" friction="0.0"/>
    </joint>
    <link name="left_upper_arm_link">
      <visual>
        <geometry>
          <mesh filename="meshes/ur5/visual/upperarm.dae"/>
        </geometry>
        <material name="LightGrey">
          <color rgba="0.7 0.7 0.7 1.0"/>
        </material>
      </visual>
      <collision>
        <geometry>
          <mesh filename="meshes/ur5/collision/upperarm.dae"/>
        </geometry>
      </collision>
      <inertial>
        <mass value="8.393"/>
        <origin rpy="0 0 0" xyz="0.0 0.0 0.28"/>
        <inertia ixx="0.22689067591" ixy="0.0" ixz="0.0" iyy="0.22689067591" iyz="0.0" izz="0.0151074"/>
      </inertial>
    </link>
    <joint name="left_elbow_joint" type="revolute">
      <parent link="left_upper_arm_link"/>
      <child link="left_forearm_link"/>
      <origin rpy="0.0 0.0 0.0" xyz="0.0 -0.1197 0.425"/>
      <axis xyz="0 1 0"/>
      <limit effort="150.0" lower="0" upper="3.14159265359" velocity="3.15"/>
      <dynamics damping="0.0" friction="0.0"/>
    </joint>
    <link name="left_forearm_link">
      <visual>
        <geometry>
          <mesh filename="meshes/ur5/visual/forearm.dae"/>
        </geometry>
        <material name="LightGrey">
          <color rgba="0.7 0.7 0.7 1.0"/>
        </material>
      </visual>
      <collision>
        <geometry>
          <mesh filename="meshes/ur5/collision/forearm.dae"/>
        </geometry>
      </collision>
      <inertial>
        <mass value="2.275"/>
        <origin rpy="0 0 0" xyz="0.0 0.0 0.196125"/>
        <inertia ixx="0.0312167910289" ixy="0.0" ixz="0.0" iyy="0.0312167910289" iyz="0.0" izz="0.004095"/>
      </inertial>
    </link>
    <joint name="left_wrist_1_joint" type="revolute">
      <parent link="left_forearm_link"/>
      <child link="left_wrist_1_link"/>
      <origin rpy="0.0 1.57079632679 0.0" xyz="0.0 0.0 0.39225"/>
      <axis xyz="0 1 0"/>
      <limit effort="28.0" lower="-3.14159265359" upper="3.14159265359" velocity="3.2"/>
      <dynamics damping="0.0" friction="0.0"/>
    </joint>
    <link name="left_wrist_1_link">
      <visual>
        <geometry>
          <mesh filename="meshes/ur5/visual/wrist1.dae"/>
        </geometry>
        <material name="LightGrey">
          <color rgba="0.7 0.7 0.7 1.0"/>
        </material>
      </visual>
      <collision>
        <geometry>
          <mesh filename="meshes/ur5/collision/wrist1.dae"/>
        </geometry>
      </collision>
      <inertial>
        <mass value="1.219"/>
        <origin rpy="0 0 0" xyz="0.0 0.093 0.0"/>
        <inertia ixx="0.00255989897604" ixy="0.0" ixz="0.0" iyy="0.00255989897604" iyz="0.0" izz="0.0021942"/>
      </inertial>
    </link>
    <joint name="left_wrist_2_joint" type="revolute">
      <parent link="left_wrist_1_link"/>
      <child link="left_wrist_2_link"/>
      <origin rpy="0.0 0.0 0.0" xyz="0.0 0.093 0.0"/>
      <axis xyz="0 0 1"/>
      <limit effort="28.0" lower="-3.14159265359" upper="3.14159265359" velocity="3.2"/>
      <dynamics damping="0.0" friction="0.0"/>
    </joint>
    <link name="left_wrist_2_link">
      <visual>
        <geometry>
          <mesh filename="meshes/ur5/visual/wrist2.dae"/>
        </geometry>
        <material name="LightGrey">
          <color rgba="0.7 0.7 0.7 1.0"/>
        </material>
      </visual>
      <collision>
        <geometry>
          <mesh filename="meshes/ur5/collision/wrist2.dae"/>
        </geometry>
      </collision>
      <inertial>
        <mass value="1.219"/>
        <origin rpy="0 0 0" xyz="0.0 0.0 0.09465"/>
        <inertia ixx="0.00255989897604" ixy="0.0" ixz="0.0" iyy="0.00255989897604" iyz="0.0" izz="0.0021942"/>
      </inertial>
    </link>
    <joint name="left_wrist_3_joint" type="revolute">
      <parent link="left_wrist_2_link"/>
      <child link="left_wrist_3_link"/>
      <origin rpy="0.0 0.0 0.0" xyz="0.0 0.0 0.09465"/>
      <axis xyz="0 1 0"/>
      <limit effort="28.0" lower="-3.14159265359" upper="3.14159265359" velocity="3.2"/>
      <dynamics damping="0.0" friction="0.0"/>
    </joint>
    <link name="left_wrist_3_link">
      <visual>
        <geometry>
          <mesh filename="meshes/ur5/visual/wrist3.dae"/>
        </geometry>
        <material name="LightGrey">
          <color rgba="0.7 0.7 0.7 1.0"/>
        </material>
      </visual>
      <collision>
        <geometry>
          <mesh filename="meshes/ur5/collision/wrist3.dae"/>
        </geometry>
      </collision>
      <inertial>
        <mass value="0.1879"/>
        <origin rpy="1.57079632679 0 0" xyz="0.0 0.06505 0.0"/>
        <inertia ixx="8.46958911216e-05" ixy="0.0" ixz="0.0" iyy="8.46958911216e-05" iyz="0.0" izz="0.0001321171875"/>
      </inertial>
    </link>
    <joint name="left_ee_fixed_joint" type="fixed">
      <parent link="left_wrist_3_link"/>
      <child link="left_ee_link"/>
      <origin rpy="0.0 0.0 1.57079632679" xyz="0.0 0.0823 0.0"/>
    </joint>
    
    <link name="left_ee_link">
      <collision>
        <geometry>
          <box size="0.01 -0.01 0.01"/>
        </geometry>
        <origin rpy="0 0 0" xyz="-0.01 0 0"/>
      </collision>
      <objective>
        <type name="position" weight="100" xyz="-0.2324 0.9384 0.313" />
        <type name="orientation" weight="300" rpy="0 -90 0"/>
     </objective>
     <tag part="left_hand"/>      
    </link>
    
    <joint name="virtual_left" type="fixed">
        <origin xyz="0.025 0 0" rpy="0 0 0"/>
        <parent link="left_ee_link"/>
        <child link="left_buffer_link"/>
    </joint>
    
    <link name="left_buffer_link"> 
        <visual>
            <geometry>
              <box size="0.05 0.05 0.05"/>
            </geometry>
          </visual>
          <collision>
            <geometry>
              <box size="0.05 0.05 0.05"/>
            </geometry>
          </collision>
          <inertial>
            <mass value="150.0"/>
            <origin rpy="0.0 0.0 0.0" xyz="0.0 0.0 0.0"/>
            <inertia ixx="0.00443333156" ixy="0.0" ixz="0.0" iyy="0.00443333156" iyz="0.0" izz="0.0072"/>
          </inertial>
    </link>

    <joint name="grasping_frame_joint_left" type="fixed">
        <origin xyz="0.07 0 0" rpy="0 0 0"/>
        <parent link="left_buffer_link"/>
        <child link="grasping_frame_left"/>
    </joint>

    <link name="grasping_frame_left">
        <tag part="left_hand"/>
    </link>
    
    <joint name="left_buffer_joint" type="fixed">
        <origin xyz="-0.05 0.2 0" rpy="3.14 0 1.57"/>
        <parent link="left_buffer_link"/>
        <child link="left_forearm_and_palm_subassembly"/>
    </joint>
    
    <link name="left_forearm_and_palm_subassembly">
    </link>
    
    <link name="Lpart_1_3">
        <visual>
        <origin xyz="-0.0049999999999999766853 2.7755575615628913511e-17 -0.018500000000000103167" rpy="-1.5708 0 0" />
        <geometry>
        <mesh filename="meshes/left_artus/part_1_3.stl"/>
        </geometry>
        <material name="part_1_3_material">
        <color rgba="0.64705882352941179736 0.64705882352941179736 0.64705882352941179736 1.0"/>
        </material>
        </visual>
        <collision>
        <origin xyz="-0.0049999999999999766853 2.7755575615628913511e-17 -0.018500000000000103167" rpy="-1.5708 0 0" />
        <geometry>
        <mesh filename="meshes/left_artus/part_1_3.stl"/>
        </geometry>
        </collision>
        <inertial>
        <origin xyz="0 0 0" rpy="0 0 0"/>
        <mass value="0" />
        <inertia ixx="0" ixy="0"  ixz="0" iyy="0" iyz="0" izz="0" />
        </inertial>
    </link>
    
    <link name="Lpart_1_8">
        <visual>
        <origin xyz="-0.028552407289709647031 -0.0078589767938891941235 -0.006000000000005112355" rpy="-3.14 0 0" />
        <geometry>
        <mesh filename="meshes/left_artus/part_1_8.stl"/>
        </geometry>
        <material name="part_1_8_material">
        <color rgba="0.61568627450980395466 0.81176470588235294379 0.92941176470588238168 1.0"/>
        </material>
        </visual>
        <collision>
        <origin xyz="-0.028552407289709647031 -0.0078589767938891941235 -0.006000000000005112355" rpy="-3.14 0 0" />
        <geometry>
        <mesh filename="meshes/left_artus/part_1_8.stl"/>
        </geometry>
        </collision>
        <inertial>
        <origin xyz="0 0 0" rpy="0 0 0"/>
        <mass value="0" />
        <inertia ixx="0" ixy="0"  ixz="0" iyy="0" iyz="0" izz="0" />
        </inertial>
    </link>
    
    <link name="Lpart_1_9">
        <visual>
        <origin xyz="-0.017524803018038770386 -0.0071295923980055951955 -0.005250000000000198952" rpy="-3.14 0 0" />
        <geometry>
        <mesh filename="meshes/left_artus/part_1_9.stl"/>
        </geometry>
        <material name="part_1_9_material">
        <color rgba="0.91764705882352937127 0.91764705882352937127 0.91764705882352937127 1.0"/>
        </material>
        </visual>
        <collision>
        <origin xyz="-0.017524803018038770386 -0.0071295923980055951955 -0.005250000000000198952" rpy="-3.14 0 0" />
        <geometry>
        <mesh filename="meshes/left_artus/part_1_9.stl"/>
        </geometry>
        </collision>
        <inertial>
        <origin xyz="0 0 0" rpy="0 0 0"/>
        <mass value="0" />
        <inertia ixx="0" ixy="0"  ixz="0" iyy="0" iyz="0" izz="0" />
        </inertial>
    </link>
    
    <link name="Ld1_urdf_mk_5_3">
        <visual>
        <origin xyz="-0.0090000000000002022826 -0.0060000000000000001249 -0.0047499999999967290609" rpy="-3.14 0 0" />
        <geometry>
        <mesh filename="meshes/left_artus/d1_urdf_mk_5_3.stl"/>
        </geometry>
        <material name="d1_urdf_mk_5_3_material">
        <color rgba="0.2313725490196078538 0.38039215686274507888 0.7058823529411765163 1.0"/>
        </material>
        </visual>
        <collision>
        <origin xyz="-0.0090000000000002022826 -0.0060000000000000001249 -0.0047499999999967290609" rpy="-3.14 0 0" />
        <geometry>
        <mesh filename="meshes/left_artus/d1_urdf_mk_5_3.stl"/>
        </geometry>
        </collision>
        <inertial>
        <origin xyz="0 0 0" rpy="0 0 0"/>
        <mass value="0" />
        <inertia ixx="0" ixy="0"  ixz="0" iyy="0" iyz="0" izz="0" />
        </inertial>
    </link>
    
    <joint name="Lindex_34" type="revolute">
        <origin xyz="-0.024999999999999855671 -6.9735883734267645195e-16 -0.00049999999999991717736" rpy="0 0 0" />
        <parent link="Lpart_1_9" />
        <child link="Ld1_urdf_mk_5_3" />
        <axis xyz="0 0 1"/>
        <limit effort="100" velocity="20" lower="0" upper="1.570796326794896558"/>
        <joint_properties friction="0.0"/>
    </joint>
    
    <joint name="Lindex_23" type="revolute">
        <origin xyz="-0.038000000000001032952 0.0007499999999999017869 -0.00074999999999991739941" rpy="0 0 0" />
        <parent link="Lpart_1_8" />
        <child link="Lpart_1_9" />
        <axis xyz="0 0 1"/>
        <limit effort="100" velocity="20" lower="0" upper="1.570796326794896558"/>
        <joint_properties friction="0.0"/>
    </joint>
    
    <joint name="Lindex_12" type="revolute">
    <origin xyz="-0.014749999999999902078 -0.0060000000000000053291 -0.0095000000000000240502" rpy="1.570796326794896558 0 0" />
    <parent link="Lpart_1_3" />
    <child link="Lpart_1_8" />
    <axis xyz="0 0 1"/>
    <limit effort="100" velocity="20" lower="0" upper="1.570796326794896558"/>
    <joint_properties friction="0.0"/>
    </joint>
    
    <joint name="Lindex_01" type="revolute">
    <origin xyz="-0.16028164023610538824 0.14948044673134122662 0.018238679244508611971" rpy="0 0 -1.6406094968746700591" />
    <parent link="left_forearm_and_palm_subassembly" />
    <child link="Lpart_1_3" />
    <axis xyz="0 0 1"/>
    <limit effort="100" velocity="20" lower="-0.29670597283903604735" upper="0.29670597283903604735"/>
    <joint_properties friction="0.0"/>
    </joint>
    
    <link name="Lpart_1_2">
    <visual>
    <origin xyz="-0.0049999999999999766853 0 -0.018500000000000099698" rpy="-1.5708 0 0" />
    <geometry>
    <mesh filename="meshes/left_artus/part_1_2.stl"/>
    </geometry>
    <material name="part_1_2_material">
    <color rgba="0.64705882352941179736 0.64705882352941179736 0.64705882352941179736 1.0"/>
    </material>
    </visual>
    <collision>
    <origin xyz="-0.0049999999999999766853 0 -0.018500000000000099698" rpy="-1.5708 0 0" />
    <geometry>
    <mesh filename="meshes/left_artus/part_1_2.stl"/>
    </geometry>
    </collision>
    <inertial>
    <origin xyz="0 0 0" rpy="0 0 0"/>
    <mass value="0" />
    <inertia ixx="0" ixy="0"  ixz="0" iyy="0" iyz="0" izz="0" />
    </inertial>
    </link>
    
    <link name="Lpart_1_7">
    <visual>
    <origin xyz="-0.028552407289709619276 -0.0078589767938891941235 -0.0060000000000050845994" rpy="-3.14 0 0" />
    <geometry>
    <mesh filename="meshes/left_artus/part_1_7.stl"/>
    </geometry>
    <material name="part_1_7_material">
    <color rgba="0.61568627450980395466 0.81176470588235294379 0.92941176470588238168 1.0"/>
    </material>
    </visual>
    <collision>
    <origin xyz="-0.028552407289709619276 -0.0078589767938891941235 -0.0060000000000050845994" rpy="-3.14 0 0" />
    <geometry>
    <mesh filename="meshes/left_artus/part_1_7.stl"/>
    </geometry>
    </collision>
    <inertial>
    <origin xyz="0 0 0" rpy="0 0 0"/>
    <mass value="0" />
    <inertia ixx="0" ixy="0"  ixz="0" iyy="0" iyz="0" izz="0" />
    </inertial>
    </link>
    
    <link name="Lpart_1_11">
    <visual>
    <origin xyz="-0.017524803018038798141 -0.0071295923980049134491 -0.0052500000000001711964" rpy="-3.14 0 0" />
    <geometry>
    <mesh filename="meshes/left_artus/part_1_11.stl"/>
    </geometry>
    <material name="part_1_11_material">
    <color rgba="0.91764705882352937127 0.91764705882352937127 0.91764705882352937127 1.0"/>
    </material>
    </visual>
    <collision>
    <origin xyz="-0.017524803018038798141 -0.0071295923980049134491 -0.0052500000000001711964" rpy="-3.14 0 0" />
    <geometry>
    <mesh filename="meshes/left_artus/part_1_11.stl"/>
    </geometry>
    </collision>
    <inertial>
    <origin xyz="0 0 0" rpy="0 0 0"/>
    <mass value="0" />
    <inertia ixx="0" ixy="0"  ixz="0" iyy="0" iyz="0" izz="0" />
    </inertial>
    </link>
    
    <link name="Ld1_urdf_mk_5_4">
    <visual>
    <origin xyz="-0.0090000000000002022826 -0.006000000000000002727 -0.0047499999999967013053" rpy="-3.14 0 0" />
    <geometry>
    <mesh filename="meshes/left_artus/d1_urdf_mk_5_4.stl"/>
    </geometry>
    <material name="d1_urdf_mk_5_4_material">
    <color rgba="0.2313725490196078538 0.38039215686274507888 0.7058823529411765163 1.0"/>
    </material>
    </visual>
    <collision>
    <origin xyz="-0.0090000000000002022826 -0.006000000000000002727 -0.0047499999999967013053" rpy="-3.14 0 0" />
    <geometry>
    <mesh filename="meshes/left_artus/d1_urdf_mk_5_4.stl"/>
    </geometry>
    </collision>
    <inertial>
    <origin xyz="0 0 0" rpy="0 0 0"/>
    <mass value="0" />
    <inertia ixx="0" ixy="0"  ixz="0" iyy="0" iyz="0" izz="0" />
    </inertial>
    </link>
    
    <joint name="Lring_34" type="revolute">
    <origin xyz="-0.024999999999999966693 -2.7755575615628913511e-17 -0.00050000000000002819966" rpy="0 0 0" />
    <parent link="Lpart_1_11" />
    <child link="Ld1_urdf_mk_5_4" />
    <axis xyz="0 0 1"/>
    <limit effort="100" velocity="20" lower="0" upper="1.570796326794896558"/>
    <joint_properties friction="0.0"/>
    </joint>
    
    <joint name="Lring_23" type="revolute">
    <origin xyz="-0.038000000000001032952 0.00074999999999993821609 -0.00074999999999994515498" rpy="0 0 0" />
    <parent link="Lpart_1_7" />
    <child link="Lpart_1_11" />
    <axis xyz="0 0 1"/>
    <limit effort="100" velocity="20" lower="0" upper="1.570796326794896558"/>
    <joint_properties friction="0.0"/>
    </joint>
    
    <joint name="Lring_12" type="revolute">
    <origin xyz="-0.014749999999999957589 -0.0060000000000000330846 -0.0095000000000000413974" rpy="1.570796326794896558 0 0" />
    <parent link="Lpart_1_2" />
    <child link="Lpart_1_7" />
    <axis xyz="0 0 1"/>
    <limit effort="100" velocity="20" lower="0" upper="1.570796326794896558"/>
    <joint_properties friction="0.0"/>
    </joint>
    
    <joint name="Lring_01" type="revolute">
    <origin xyz="-0.20326918124942178201 0.14809262510567919313 0.018238679244508650135" rpy="0 0 -1.50098315671495941" />
    <parent link="left_forearm_and_palm_subassembly" />
    <child link="Lpart_1_2" />
    <axis xyz="0 0 1"/>
    <limit effort="100" velocity="20" lower="-0.29670597283903604735" upper="0.29670597283903604735"/>
    <joint_properties friction="0.0"/>
    </joint>
    
    <link name="Lpart_1_4">
    <visual>
    <origin xyz="-0.0049999999999999766853 2.7755575615628913511e-17 -0.018500000000000099698" rpy="-1.5708 0 0" />
    <geometry>
    <mesh filename="meshes/left_artus/part_1_4.stl"/>
    </geometry>
    <material name="part_1_4_material">
    <color rgba="0.64705882352941179736 0.64705882352941179736 0.64705882352941179736 1.0"/>
    </material>
    </visual>
    <collision>
    <origin xyz="-0.0049999999999999766853 2.7755575615628913511e-17 -0.018500000000000099698" rpy="-1.5708 0 0" />
    <geometry>
    <mesh filename="meshes/left_artus/part_1_4.stl"/>
    </geometry>
    </collision>
    <inertial>
    <origin xyz="0 0 0" rpy="0 0 0"/>
    <mass value="0" />
    <inertia ixx="0" ixy="0"  ixz="0" iyy="0" iyz="0" izz="0" />
    </inertial>
    </link>
    
    <link name="Lpart_1_5">
    <visual>
    <origin xyz="-0.028552407289709674787 -0.0078589767938891941235 -0.0060000000000051401106" rpy="-3.14 0 0" />
    <geometry>
    <mesh filename="meshes/left_artus/part_1_5.stl"/>
    </geometry>
    <material name="part_1_5_material">
    <color rgba="0.61568627450980395466 0.81176470588235294379 0.92941176470588238168 1.0"/>
    </material>
    </visual>
    <collision>
    <origin xyz="-0.028552407289709674787 -0.0078589767938891941235 -0.0060000000000051401106" rpy="-3.14 0 0" />
    <geometry>
    <mesh filename="meshes/left_artus/part_1_5.stl"/>
    </geometry>
    </collision>
    <inertial>
    <origin xyz="0 0 0" rpy="0 0 0"/>
    <mass value="0" />
    <inertia ixx="0" ixy="0"  ixz="0" iyy="0" iyz="0" izz="0" />
    </inertial>
    </link>
    
    <link name="Lpart_1_10">
    <visual>
    <origin xyz="-0.017524803018038770386 -0.0071295923980049125818 -0.005250000000000198952" rpy="-3.14 0 0" />
    <geometry>
    <mesh filename="meshes/left_artus/part_1_10.stl"/>
    </geometry>
    <material name="part_1_10_material">
    <color rgba="0.91764705882352937127 0.91764705882352937127 0.91764705882352937127 1.0"/>
    </material>
    </visual>
    <collision>
    <origin xyz="-0.017524803018038770386 -0.0071295923980049125818 -0.005250000000000198952" rpy="-3.14 0 0" />
    <geometry>
    <mesh filename="meshes/left_artus/part_1_10.stl"/>
    </geometry>
    </collision>
    <inertial>
    <origin xyz="0 0 0" rpy="0 0 0"/>
    <mass value="0" />
    <inertia ixx="0" ixy="0"  ixz="0" iyy="0" iyz="0" izz="0" />
    </inertial>
    </link>
    
    <link name="Ld1_urdf_mk_5_2">
    <visual>
    <origin xyz="-0.0090000000000001745271 -0.0059999999999999645631 -0.0047499999999967013053" rpy="-3.14 0 0" />
    <geometry>
    <mesh filename="meshes/left_artus/d1_urdf_mk_5_2.stl"/>
    </geometry>
    <material name="d1_urdf_mk_5_2_material">
    <color rgba="0.2313725490196078538 0.38039215686274507888 0.7058823529411765163 1.0"/>
    </material>
    </visual>
    <collision>
    <origin xyz="-0.0090000000000001745271 -0.0059999999999999645631 -0.0047499999999967013053" rpy="-3.14 0 0" />
    <geometry>
    <mesh filename="meshes/left_artus/d1_urdf_mk_5_2.stl"/>
    </geometry>
    </collision>
    <inertial>
    <origin xyz="0 0 0" rpy="0 0 0"/>
    <mass value="0" />
    <inertia ixx="0" ixy="0"  ixz="0" iyy="0" iyz="0" izz="0" />
    </inertial>
    </link>
    
    <joint name="Lmiddle_34" type="revolute">
    <origin xyz="-0.024999999999999994449 -2.9490299091605720605e-17 -0.00050000000000000044409" rpy="0 0 0" />
    <parent link="Lpart_1_10" />
    <child link="Ld1_urdf_mk_5_2" />
    <axis xyz="0 0 1"/>
    <limit effort="100" velocity="20" lower="0" upper="1.570796326794896558"/>
    <joint_properties friction="0.0"/>
    </joint>
    
    <joint name="Lmiddle_23" type="revolute">
    <origin xyz="-0.038000000000001060707 0.00074999999999993648137 -0.00075000000000000066613" rpy="0 0 0" />
    <parent link="Lpart_1_5" />
    <child link="Lpart_1_10" />
    <axis xyz="0 0 1"/>
    <limit effort="100" velocity="20" lower="0" upper="1.570796326794896558"/>
    <joint_properties friction="0.0"/>
    </joint>
    
    <joint name="Lmiddle_12" type="revolute">
    <origin xyz="-0.014749999999999929834 -0.0059999999999999775735 -0.0095000000000000413974" rpy="1.570796326794896558 0 0" />
    <parent link="Lpart_1_4" />
    <child link="Lpart_1_5" />
    <axis xyz="0 0 1"/>
    <limit effort="100" velocity="20" lower="0" upper="1.570796326794896558"/>
    <joint_properties friction="0.0"/>
    </joint>
    
    <joint name="Lmiddle_01" type="revolute">
    <origin xyz="-0.18190440495078175065 0.15253711492388191684 0.021238679244508618105" rpy="0 0 -1.5707963267948421571" />
    <parent link="left_forearm_and_palm_subassembly" />
    <child link="Lpart_1_4" />
    <axis xyz="0 0 1"/>
    <limit effort="100" velocity="20" lower="-0.29670597283903604735" upper="0.29670597283903604735"/>
    <joint_properties friction="0.0"/>
    </joint>
    
    <link name="Lpart_1_1">
    <visual>
    <origin xyz="-0.0049999999999999766853 2.7755575615628913511e-17 -0.018500000000000099698" rpy="-1.5708 0 0" />
    <geometry>
    <mesh filename="meshes/left_artus/part_1_1.stl"/>
    </geometry>
    <material name="part_1_1_material">
    <color rgba="0.64705882352941179736 0.64705882352941179736 0.64705882352941179736 1.0"/>
    </material>
    </visual>
    <collision>
    <origin xyz="-0.0049999999999999766853 2.7755575615628913511e-17 -0.018500000000000099698" rpy="-1.5708 0 0" />
    <geometry>
    <mesh filename="meshes/left_artus/part_1_1.stl"/>
    </geometry>
    </collision>
    <inertial>
    <origin xyz="0 0 0" rpy="0 0 0"/>
    <mass value="0" />
    <inertia ixx="0" ixy="0"  ixz="0" iyy="0" iyz="0" izz="0" />
    </inertial>
    </link>
    
    <link name="Lpart_1_6">
    <visual>
    <origin xyz="-0.028552407289709619276 -0.0078589767938891108567 -0.006000000000005112355" rpy="-3.14 0 0" />
    <geometry>
    <mesh filename="meshes/left_artus/part_1_6.stl"/>
    </geometry>
    <material name="part_1_6_material">
    <color rgba="0.61568627450980395466 0.81176470588235294379 0.92941176470588238168 1.0"/>
    </material>
    </visual>
    <collision>
    <origin xyz="-0.028552407289709619276 -0.0078589767938891108567 -0.006000000000005112355" rpy="-3.14 0 0" />
    <geometry>
    <mesh filename="meshes/left_artus/part_1_6.stl"/>
    </geometry>
    </collision>
    <inertial>
    <origin xyz="0 0 0" rpy="0 0 0"/>
    <mass value="0" />
    <inertia ixx="0" ixy="0"  ixz="0" iyy="0" iyz="0" izz="0" />
    </inertial>
    </link>
    
    <link name="Lpart_1_12">
    <visual>
    <origin xyz="-0.017524803018038770386 -0.0071295923980055934607 -0.0052500000000001711964" rpy="-3.14 0 0" />
    <geometry>
    <mesh filename="meshes/left_artus/part_1_12.stl"/>
    </geometry>
    <material name="part_1_12_material">
    <color rgba="0.91764705882352937127 0.91764705882352937127 0.91764705882352937127 1.0"/>
    </material>
    </visual>
    <collision>
    <origin xyz="-0.017524803018038770386 -0.0071295923980055934607 -0.0052500000000001711964" rpy="-3.14 0 0" />
    <geometry>
    <mesh filename="meshes/left_artus/part_1_12.stl"/>
    </geometry>
    </collision>
    <inertial>
    <origin xyz="0 0 0" rpy="0 0 0"/>
    <mass value="0" />
    <inertia ixx="0" ixy="0"  ixz="0" iyy="0" iyz="0" izz="0" />
    </inertial>
    </link>
    
    <link name="Ld1_urdf_mk_5_1">
    <visual>
    <origin xyz="-0.0090000000000001745271 -0.0059999999999999636957 -0.0047499999999966735498" rpy="-3.14 0 0" />
    <geometry>
    <mesh filename="meshes/left_artus/d1_urdf_mk_5_1.stl"/>
    </geometry>
    <material name="d1_urdf_mk_5_1_material">
    <color rgba="0.2313725490196078538 0.38039215686274507888 0.7058823529411765163 1.0"/>
    </material>
    </visual>
    <collision>
    <origin xyz="-0.0090000000000001745271 -0.0059999999999999636957 -0.0047499999999966735498" rpy="-3.14 0 0" />
    <geometry>
    <mesh filename="meshes/left_artus/d1_urdf_mk_5_1.stl"/>
    </geometry>
    </collision>
    <inertial>
    <origin xyz="0 0 0" rpy="0 0 0"/>
    <mass value="0" />
    <inertia ixx="0" ixy="0"  ixz="0" iyy="0" iyz="0" izz="0" />
    </inertial>
    </link>
    
    <joint name="Lpinky_34" type="revolute">
    <origin xyz="-0.024999999999999938938 -7.0689981646054889097e-16 -0.00050000000000000044409" rpy="0 0 0" />
    <parent link="Lpart_1_12" />
    <child link="Ld1_urdf_mk_5_1" />
    <axis xyz="0 0 1"/>
    <limit effort="100" velocity="20" lower="0" upper="1.570796326794896558"/>
    <joint_properties friction="0.0"/>
    </joint>
    
    <joint name="Lpinky_23" type="revolute">
    <origin xyz="-0.038000000000001032952 0.00075000000000002148282 -0.00074999999999997291056" rpy="0 0 0" />
    <parent link="Lpart_1_6" />
    <child link="Lpart_1_12" />
    <axis xyz="0 0 1"/>
    <limit effort="100" velocity="20" lower="0" upper="1.570796326794896558"/>
    <joint_properties friction="0.0"/>
    </joint>
    
    <joint name="Lpinky_12" type="revolute">
    <origin xyz="-0.014749999999999985345 -0.0059999999999999498179 -0.0095000000000000396627" rpy="1.570796326794896558 0 0" />
    <parent link="Lpart_1_1" />
    <child link="Lpart_1_6" />
    <axis xyz="0 0 1"/>
    <limit effort="100" velocity="20" lower="0" upper="1.570796326794896558"/>
    <joint_properties friction="0.0"/>
    </joint>
    
    <joint name="Lpinky_01" type="revolute">
    <origin xyz="-0.22372307409338731965 0.14057577467475887434 0.015238679244508579816" rpy="0 0 -1.4486232791552937638" />
    <parent link="left_forearm_and_palm_subassembly" />
    <child link="Lpart_1_1" />
    <axis xyz="0 0 1"/>
    <limit effort="100" velocity="20" lower="-0.29670597283903604735" upper="0.29670597283903604735"/>
    <joint_properties friction="0.0"/>
    </joint>
    
    <link name="Lpart_1_17">
    <visual>
    <origin xyz="-0.0049999999999999766853 0 0.00062867965644033962924" rpy="-3.141592653589793116 0 0" />
    <geometry>
    <mesh filename="meshes/left_artus/part_1_17.stl"/>
    </geometry>
    <material name="part_1_17_material">
    <color rgba="0.2313725490196078538 0.38039215686274507888 0.7058823529411765163 1.0"/>
    </material>
    </visual>
    <collision>
    <origin xyz="-0.0049999999999999766853 0 0.00062867965644033962924" rpy="-3.141592653589793116 0 0" />
    <geometry>
    <mesh filename="meshes/left_artus/part_1_17.stl"/>
    </geometry>
    </collision>
    <inertial>
    <origin xyz="0 0 0" rpy="0 0 0"/>
    <mass value="0" />
    <inertia ixx="0" ixy="0"  ixz="0" iyy="0" iyz="0" izz="0" />
    </inertial>
    </link>
    
    <link name="Lpart_1_18">
    <visual>
    <origin xyz="-0.029277356236810186951 -0.0078134566939178085043 -0.0067500000000003251843" rpy="-1.570796326794896336 4.8623430361183478783e-16 -3.5162334485555108458e-17" />
    <geometry>
    <mesh filename="meshes/left_artus/part_1_18.stl"/>
    </geometry>
    <material name="part_1_18_material">
    <color rgba="0.64705882352941179736 0.64705882352941179736 0.64705882352941179736 1.0"/>
    </material>
    </visual>
    <collision>
    <origin xyz="-0.029277356236810186951 -0.0078134566939178085043 -0.0067500000000003251843" rpy="-1.570796326794896336 4.8623430361183478783e-16 -3.5162334485555108458e-17" />
    <geometry>
    <mesh filename="meshes/left_artus/part_1_18.stl"/>
    </geometry>
    </collision>
    <inertial>
    <origin xyz="0 0 0" rpy="0 0 0"/>
    <mass value="0" />
    <inertia ixx="0" ixy="0"  ixz="0" iyy="0" iyz="0" izz="0" />
    </inertial>
    </link>
    
    <link name="Lpart_1_19">
    <visual>
    <origin xyz="-0.017524803018038624669 -0.0071295923980052022806 -0.0062499999999999361622" rpy="-1.57079632679489678 6.3121236051819880868e-16 -2.6758692065306660511e-17" />
    <geometry>
    <mesh filename="meshes/left_artus/part_1_19.stl"/>
    </geometry>
    <material name="part_1_19_material">
    <color rgba="0.61568627450980395466 0.81176470588235294379 0.92941176470588238168 1.0"/>
    </material>
    </visual>
    <collision>
    <origin xyz="-0.017524803018038624669 -0.0071295923980052022806 -0.0062499999999999361622" rpy="-1.57079632679489678 6.3121236051819880868e-16 -2.6758692065306660511e-17" />
    <geometry>
    <mesh filename="meshes/left_artus/part_1_19.stl"/>
    </geometry>
    </collision>
    <inertial>
    <origin xyz="0 0 0" rpy="0 0 0"/>
    <mass value="0" />
    <inertia ixx="0" ixy="0"  ixz="0" iyy="0" iyz="0" izz="0" />
    </inertial>
    </link>
    
    <link name="Lpart_1_20">
    <visual>
    <origin xyz="-0.0089999999999997304378 -0.0060000000000001163514 -0.0057500000000045153881" rpy="-1.570796326794896558 2.2586083449859545637e-16 2.4580531496619517172e-17" />
    <geometry>
    <mesh filename="meshes/left_artus/part_1_20.stl"/>
    </geometry>
    <material name="part_1_20_material">
    <color rgba="0.49803921568627451677 0.49803921568627451677 0.49803921568627451677 1.0"/>
    </material>
    </visual>
    <collision>
    <origin xyz="-0.0089999999999997304378 -0.0060000000000001163514 -0.0057500000000045153881" rpy="-1.570796326794896558 2.2586083449859545637e-16 2.4580531496619517172e-17" />
    <geometry>
    <mesh filename="meshes/left_artus/part_1_20.stl"/>
    </geometry>
    </collision>
    <inertial>
    <origin xyz="0 0 0" rpy="0 0 0"/>
    <mass value="0" />
    <inertia ixx="0" ixy="0"  ixz="0" iyy="0" iyz="0" izz="0" />
    </inertial>
    </link>
    
    <joint name="Lthumb_34" type="revolute">
    <origin xyz="-0.025000000000000122818 -8.6042284408449631883e-16 0.0010000000000002229328" rpy="-4.7679692275343041977e-15 4.4959326954502218291e-15 1.6836456841789364934e-14" />
    <parent link="Lpart_1_19" />
    <child link="Lpart_1_20" />
    <axis xyz="0 0 1"/>
    <limit effort="100" velocity="20" lower="0" upper="1.570796326794896558"/>
    <joint_properties friction="0.0"/>
    </joint>
    
    <joint name="Lthumb_23" type="revolute">
    <origin xyz="-0.038000000000000769274 0.00075000000000011168844 -0.0004999999999999865663" rpy="9.8266833422420554545e-16 2.0874140411211021438e-16 -1.6707749441501944104e-14" />
    <parent link="Lpart_1_18" />
    <child link="Lpart_1_19" />
    <axis xyz="0 0 1"/>
    <limit effort="100" velocity="20" lower="0" upper="1.570796326794896558"/>
    <joint_properties friction="0.0"/>
    </joint>
    
    <joint name="Lthumb_12" type="revolute">
    <origin xyz="-0.014750000000000068612 0.0067500000000000753841 -0.0077500000000000068834" rpy="-1.5707963267948972241 -2.0836577888207361949e-15 1.908755618073153476e-14" />
    <parent link="Lpart_1_17" />
    <child link="Lpart_1_18" />
    <axis xyz="0 0 1"/>
    <limit effort="100" velocity="20" lower="0" upper="1.570796326794896558"/>
    <joint_properties friction="0.0"/>
    </joint>
    
    <joint name="Lthumb_01" type="revolute">
    <origin xyz="-0.17124158623158930448 0.10739372327556818976 -0.012602166449204452864" rpy="2.0752759914175786804 -1.0057357117289742465 3.141592653589763362" />
    <parent link="left_forearm_and_palm_subassembly" />
    <child link="Lpart_1_17" />
    <axis xyz="0 0 1"/>
    <limit effort="100" velocity="20" lower="-0.64577182323790194296" upper="0.64577182323790194296"/>
    <joint_properties friction="0.0"/>
    </joint>

</robot>

