<?xml version="1.0" ?>
<!-- =================================================================================== -->
<!-- |    This document was autogenerated by xacro from ../processed\Fanuc\M430ia2f\xacro\m430ia2f.xacro | -->
<!-- |    EDITING THIS FILE BY HAND IS NOT RECOMMENDED                                 | -->
<!-- =================================================================================== -->
<robot xmlns:xacro="http://wiki.ros.org/xacro" name="fanuc_m430ia2f">
  <link name="base_link">
    <visual>
      <origin xyz="0 0 0" rpy="0 0 0"/>
      <geometry>
        <mesh filename="package://fanuc_m430ia_support/meshes/m430ia2f/visual/base_link.stl"/>
      </geometry>
      <material name="">
        <color rgba="0.86 0.85 0.81 1.0"/>
      </material>
    </visual>
    <collision>
      <origin xyz="0 0 0" rpy="0 0 0"/>
      <geometry>
        <mesh filename="package://fanuc_m430ia_support/meshes/m430ia2f/collision/base_link.stl"/>
      </geometry>
    </collision>
  </link>
  <link name="link_1">
    <visual>
      <origin xyz="0 0 0" rpy="0 0 0"/>
      <geometry>
        <mesh filename="package://fanuc_m430ia_support/meshes/m430ia2f/visual/link_1.stl"/>
      </geometry>
      <material name="">
        <color rgba="0.86 0.85 0.81 1.0"/>
      </material>
    </visual>
    <collision>
      <origin xyz="0 0 0" rpy="0 0 0"/>
      <geometry>
        <mesh filename="package://fanuc_m430ia_support/meshes/m430ia2f/collision/link_1.stl"/>
      </geometry>
    </collision>
  </link>
  <link name="link_2">
    <visual>
      <origin xyz="0 0 0" rpy="0 0 0"/>
      <geometry>
        <mesh filename="package://fanuc_m430ia_support/meshes/m430ia2f/visual/link_2.stl"/>
      </geometry>
      <material name="">
        <color rgba="0.86 0.85 0.81 1.0"/>
      </material>
    </visual>
    <collision>
      <origin xyz="0 0 0" rpy="0 0 0"/>
      <geometry>
        <mesh filename="package://fanuc_m430ia_support/meshes/m430ia2f/collision/link_2.stl"/>
      </geometry>
    </collision>
  </link>
  <link name="link_3">
    <visual>
      <origin xyz="0 0 0" rpy="0 0 0"/>
      <geometry>
        <mesh filename="package://fanuc_m430ia_support/meshes/m430ia2f/visual/link_3.stl"/>
      </geometry>
      <material name="">
        <color rgba="0.86 0.85 0.81 1.0"/>
      </material>
    </visual>
    <collision>
      <origin xyz="0 0 0" rpy="0 0 0"/>
      <geometry>
        <mesh filename="package://fanuc_m430ia_support/meshes/m430ia2f/collision/link_3.stl"/>
      </geometry>
    </collision>
  </link>
  <link name="link_4">
    <visual>
      <origin xyz="0 0 0" rpy="0 0 0"/>
      <geometry>
        <mesh filename="package://fanuc_m430ia_support/meshes/m430ia2f/visual/link_4.stl"/>
      </geometry>
      <material name="">
        <color rgba="0.86 0.85 0.81 1.0"/>
      </material>
    </visual>
    <collision>
      <origin xyz="0 0 0" rpy="0 0 0"/>
      <geometry>
        <mesh filename="package://fanuc_m430ia_support/meshes/m430ia2f/collision/link_4.stl"/>
      </geometry>
    </collision>
  </link>
  <link name="link_5">
    <visual>
      <origin xyz="0 0 0" rpy="0 0 0"/>
      <geometry>
        <mesh filename="package://fanuc_m430ia_support/meshes/m430ia2f/visual/link_5.stl"/>
      </geometry>
      <material name="">
        <color rgba="0.86 0.85 0.81 1.0"/>
      </material>
    </visual>
    <collision>
      <origin xyz="0 0 0" rpy="0 0 0"/>
      <geometry>
        <mesh filename="package://fanuc_m430ia_support/meshes/m430ia2f/collision/link_5.stl"/>
      </geometry>
    </collision>
  </link>
  <joint name="joint_1" type="revolute">
    <origin xyz="0 0 0.440" rpy="0 0 0"/>
    <parent link="base_link"/>
    <child link="link_1"/>
    <axis xyz="0 0 1"/>
    <limit lower="-3.1415" upper="3.1415" effort="0" velocity="5.24"/>
  </joint>
  <joint name="joint_2" type="revolute">
    <origin xyz="0 0 0" rpy="0 0 0"/>
    <parent link="link_1"/>
    <child link="link_2"/>
    <axis xyz="0 1 0"/>
    <limit lower="-2.01" upper="2.01" effort="0" velocity="5.59"/>
  </joint>
  <joint name="joint_3" type="revolute">
    <origin xyz="0 -0.095 0.350" rpy="0 0 0"/>
    <parent link="link_2"/>
    <child link="link_3"/>
    <axis xyz="0 1 0"/>
    <limit lower="-3.34" upper="3.34" effort="0" velocity="5.59"/>
  </joint>
  <joint name="joint_4" type="revolute">
    <origin xyz="0 0 0.550" rpy="0 0 0"/>
    <parent link="link_3"/>
    <child link="link_4"/>
    <axis xyz="0 1 0"/>
    <limit lower="-2.62" upper="2.62" effort="0" velocity="6.28"/>
  </joint>
  <joint name="joint_5" type="revolute">
    <origin xyz="0 0 0.065" rpy="0 0 0"/>
    <parent link="link_4"/>
    <child link="link_5"/>
    <axis xyz="0 0 1"/>
    <limit lower="-4.71" upper="4.71" effort="0" velocity="20.94"/>
  </joint>
  <link name="base"/>
  <joint name="base_link-base" type="fixed">
    <origin xyz="0 0 0.440" rpy="0 0 0"/>
    <parent link="base_link"/>
    <child link="base"/>
  </joint>
  <link name="flange"/>
  <joint name="joint_5-flange" type="fixed">
    <origin xyz="0 0 0" rpy="0 -1.5707963267948966 0"/>
    <parent link="link_5"/>
    <child link="flange"/>
  </joint>
  <link name="tool0"/>
  <joint name="link_5-tool0" type="fixed">
    <origin xyz="0 0 0" rpy="0 0 0"/>
    <parent link="link_5"/>
    <child link="tool0"/>
  </joint>
</robot>
