<?xml version="1.0" ?>
<!-- =================================================================================== -->
<!-- |    This document was autogenerated by xacro from ../processed/KUKA/KR6R700sixx/xacro/kr6r700sixx.xacro | -->
<!-- |    EDITING THIS FILE BY HAND IS NOT RECOMMENDED                                 | -->
<!-- =================================================================================== -->
<robot xmlns:xacro="http://wiki.ros.org/xacro" name="kuka_kr6r700sixx">
  <link name="base_link">
    <visual>
      <origin xyz="0 0 0" rpy="0 0 0"/>
      <geometry>
        <mesh filename="package://kuka_kr6_support/meshes/kr6_agilus/visual/base_link.dae"/>
      </geometry>
      <material name="">
        <color rgba="0.5058823529411764 0.47058823529411764 0.38823529411764707 1.0"/>
      </material>
    </visual>
    <collision>
      <origin xyz="0 0 0" rpy="0 0 0"/>
      <geometry>
        <mesh filename="package://kuka_kr6_support/meshes/kr6_agilus/collision/base_link.stl"/>
      </geometry>
    </collision>
  </link>
  <link name="link_1">
    <visual>
      <origin xyz="0 0 0" rpy="0 0 0"/>
      <geometry>
        <mesh filename="package://kuka_kr6_support/meshes/kr6_agilus/visual/link_1.dae"/>
      </geometry>
      <material name="">
        <color rgba="0.9647058823529412 0.47058823529411764 0.1568627450980392 1.0"/>
      </material>
    </visual>
    <collision>
      <origin xyz="0 0 0" rpy="0 0 0"/>
      <geometry>
        <mesh filename="package://kuka_kr6_support/meshes/kr6_agilus/collision/link_1.stl"/>
      </geometry>
    </collision>
  </link>
  <link name="link_2">
    <visual>
      <origin xyz="0 0 0" rpy="0 0 0"/>
      <geometry>
        <mesh filename="package://kuka_kr6_support/meshes/kr6r700sixx/visual/link_2.dae"/>
      </geometry>
      <material name="">
        <color rgba="0.9647058823529412 0.47058823529411764 0.1568627450980392 1.0"/>
      </material>
    </visual>
    <collision>
      <origin xyz="0 0 0" rpy="0 0 0"/>
      <geometry>
        <mesh filename="package://kuka_kr6_support/meshes/kr6r700sixx/collision/link_2.stl"/>
      </geometry>
    </collision>
  </link>
  <link name="link_3">
    <visual>
      <origin xyz="0 0 0" rpy="0 0 0"/>
      <geometry>
        <mesh filename="package://kuka_kr6_support/meshes/kr6_agilus/visual/link_3.dae"/>
      </geometry>
      <material name="">
        <color rgba="0.9647058823529412 0.47058823529411764 0.1568627450980392 1.0"/>
      </material>
    </visual>
    <collision>
      <origin xyz="0 0 0" rpy="0 0 0"/>
      <geometry>
        <mesh filename="package://kuka_kr6_support/meshes/kr6_agilus/collision/link_3.stl"/>
      </geometry>
    </collision>
  </link>
  <link name="link_4">
    <visual>
      <origin xyz="0 0 0" rpy="0 0 0"/>
      <geometry>
        <mesh filename="package://kuka_kr6_support/meshes/kr6r700sixx/visual/link_4.dae"/>
      </geometry>
      <material name="">
        <color rgba="0.9647058823529412 0.47058823529411764 0.1568627450980392 1.0"/>
      </material>
    </visual>
    <collision>
      <origin xyz="0 0 0" rpy="0 0 0"/>
      <geometry>
        <mesh filename="package://kuka_kr6_support/meshes/kr6r700sixx/collision/link_4.stl"/>
      </geometry>
    </collision>
  </link>
  <link name="link_5">
    <visual>
      <origin xyz="0 0 0" rpy="0 0 0"/>
      <geometry>
        <mesh filename="package://kuka_kr6_support/meshes/kr6_agilus/visual/link_5.dae"/>
      </geometry>
      <material name="">
        <color rgba="0.9647058823529412 0.47058823529411764 0.1568627450980392 1.0"/>
      </material>
    </visual>
    <collision>
      <origin xyz="0 0 0" rpy="0 0 0"/>
      <geometry>
        <mesh filename="package://kuka_kr6_support/meshes/kr6_agilus/collision/link_5.stl"/>
      </geometry>
    </collision>
  </link>
  <link name="link_6">
    <visual>
      <origin xyz="0 0 0" rpy="0 0 0"/>
      <geometry>
        <mesh filename="package://kuka_kr6_support/meshes/kr6_agilus/visual/link_6.dae"/>
      </geometry>
      <material name="">
        <color rgba="0.5058823529411764 0.47058823529411764 0.38823529411764707 1.0"/>
      </material>
    </visual>
    <collision>
      <origin xyz="0 0 0" rpy="0 0 0"/>
      <geometry>
        <mesh filename="package://kuka_kr6_support/meshes/kr6_agilus/collision/link_6.stl"/>
      </geometry>
    </collision>
  </link>
  <link name="flange"/>
  <joint name="joint_a1" type="revolute">
    <origin xyz="0 0 0.4" rpy="0 0 0"/>
    <parent link="base_link"/>
    <child link="link_1"/>
    <axis xyz="0 0 -1"/>
    <limit lower="-2.9670597283903604" upper="2.9670597283903604" effort="0" velocity="6.283185307179586"/>
  </joint>
  <joint name="joint_a2" type="revolute">
    <origin xyz="0.025 0 0" rpy="0 0 0"/>
    <parent link="link_1"/>
    <child link="link_2"/>
    <axis xyz="0 1 0"/>
    <limit lower="-3.3161255787892263" upper="0.7853981633974483" effort="0" velocity="5.235987755982989"/>
  </joint>
  <joint name="joint_a3" type="revolute">
    <origin xyz="0.315 0 0" rpy="0 0 0"/>
    <parent link="link_2"/>
    <child link="link_3"/>
    <axis xyz="0 1 0"/>
    <limit lower="-2.0943951023931953" upper="2.722713633111154" effort="0" velocity="6.283185307179586"/>
  </joint>
  <joint name="joint_a4" type="revolute">
    <origin xyz="0 0 0.035" rpy="0 0 0"/>
    <parent link="link_3"/>
    <child link="link_4"/>
    <axis xyz="-1 0 0"/>
    <limit lower="-3.2288591161895095" upper="3.2288591161895095" effort="0" velocity="6.649704450098396"/>
  </joint>
  <joint name="joint_a5" type="revolute">
    <origin xyz="0.365 0 0" rpy="0 0 0"/>
    <parent link="link_4"/>
    <child link="link_5"/>
    <axis xyz="0 1 0"/>
    <limit lower="-2.0943951023931953" upper="2.0943951023931953" effort="0" velocity="6.771877497737998"/>
  </joint>
  <joint name="joint_a6" type="revolute">
    <origin xyz="0.080 0 0" rpy="0 0 0"/>
    <parent link="link_5"/>
    <child link="link_6"/>
    <axis xyz="-1 0 0"/>
    <limit lower="-6.1086523819801535" upper="6.1086523819801535" effort="0" velocity="10.733774899765127"/>
  </joint>
  <joint name="joint_a6-flange" type="fixed">
    <parent link="link_6"/>
    <child link="flange"/>
    <origin xyz="0 0 0" rpy="0 0 0"/>
  </joint>
  <link name="base"/>
  <joint name="base_link-base" type="fixed">
    <origin xyz="0 0 0" rpy="0 0 0"/>
    <parent link="base_link"/>
    <child link="base"/>
  </joint>
  <link name="tool0"/>
  <joint name="flange-tool0" type="fixed">
    <parent link="flange"/>
    <child link="tool0"/>
    <origin xyz="0 0 0" rpy="0 1.5707963267948966 0"/>
  </joint>
</robot>
