<?xml version="1.0" ?>
<!-- =================================================================================== -->
<!-- |    This document was autogenerated by xacro from ur5_joint_limited_robot.urdf.xacro | -->
<!-- |    EDITING THIS FILE BY HAND IS NOT RECOMMENDED                                 | -->
<!-- =================================================================================== -->
<robot name="ur5" xmlns:xacro="http://wiki.ros.org/xacro">
  <!-- measured from model -->
  <!--property name="shoulder_height" value="0.089159" /-->
  <!--property name="shoulder_offset" value="0.13585" /-->
  <!-- shoulder_offset - elbow_offset + wrist_1_length = 0.10915 -->
  <!--property name="upper_arm_length" value="0.42500" /-->
  <!--property name="elbow_offset" value="0.1197" /-->
  <!-- CAD measured -->
  <!--property name="forearm_length" value="0.39225" /-->
  <!--property name="wrist_1_length" value="0.093" /-->
  <!-- CAD measured -->
  <!--property name="wrist_2_length" value="0.09465" /-->
  <!-- In CAD this distance is 0.930, but in the spec it is 0.09465 -->
  <!--property name="wrist_3_length" value="0.0823" /-->
  <!-- manually measured -->
  <link name="arm_base_link">
      <visual>
        <geometry>
          <box size="0.2 0.1 0.2"/>
        </geometry>
      </visual>
      <collision>
      <geometry>
        <box size="0.2 0.1 0.2"/>
      </geometry>
      <origin rpy="0 0 0" xyz="0 0 0"/>
    </collision>
      <inertial>
        <mass value="150.0"/>
        <origin rpy="0.0 0.0 0.0" xyz="0.0 0.0 0.0"/>
        <inertia ixx="0.00443333156" ixy="0.0" ixz="0.0" iyy="0.00443333156" iyz="0.0" izz="0.0072"/>
      </inertial>
      <tag part="base"/>
    </link>
    
     <joint name="joint_1" type="revolute">
        <parent link="arm_base_link"/>
        <child link="joint_1_link"/>
        <origin rpy="0 0 0" xyz="0 0 1.4"/>
        <axis xyz="0 0 1"/>
        <limit effort="150.0" lower="-3.14159265359" upper="3.14159265359" velocity="3.15"/>
        <dynamics damping="0.0" friction="0.0"/>
     </joint>

     <link name="joint_1_link">
        <visual>
           <geometry>
             <box size="0.3385 0.1 0.1"/>
           </geometry>
           <origin rpy="0 0 0" xyz="0 0 0"/>
        </visual>
        <collision>
           <geometry>
             <box size="0.3385 0.1 0.1"/>
           </geometry>
           <origin rpy="0 0 0" xyz="0 0 0"/>
        </collision>
     </link>
    
    
    <joint name="right_arm_joint" type="fixed">
        <parent link="operator_chair"/>
        <child link="right_base_link"/>
        <origin rpy="1.5708 0 0" xyz="0.5 -0.23 1.78"/>
        <axis xyz="0 0 1"/>
      </joint>
  <link name="right_base_link">
    <visual>
      <geometry>
        <mesh filename="meshes/ur5/visual/base.dae"/>
      </geometry>
      <material name="LightGrey">
        <color rgba="0.7 0.7 0.7 1.0"/>
      </material>
    </visual>
    <collision>
      <geometry>
        <mesh filename="meshes/ur5/collision/base.dae"/>
      </geometry>
    </collision>
    <inertial>
      <mass value="4.0"/>
      <origin rpy="0 0 0" xyz="0.0 0.0 0.0"/>
      <inertia ixx="0.00443333156" ixy="0.0" ixz="0.0" iyy="0.00443333156" iyz="0.0" izz="0.0072"/>
    </inertial>
  </link>
  <joint name="right_shoulder_pan_joint" type="revolute">
    <parent link="right_base_link"/>
    <child link="right_shoulder_link"/>
    <origin rpy="0.0 0.0 0.0" xyz="0.0 0.0 0.089159"/>
    <axis xyz="0 0 1"/>
    <limit effort="150.0" lower="-3.14159265359" upper="3.14159265359" velocity="3.15"/>
    <dynamics damping="0.0" friction="0.0"/>
  </joint>
  <link name="right_shoulder_link">
    <visual>
      <geometry>
        <mesh filename="meshes/ur5/visual/shoulder.dae"/>
      </geometry>
    </visual>
    <collision>
      <geometry>
        <mesh filename="meshes/ur5/collision/shoulder.dae"/>
      </geometry>
    </collision>
    <inertial>
      <mass value="3.7"/>
      <origin rpy="0 0 0" xyz="0.0 0.0 0.0"/>
      <inertia ixx="0.010267495893" ixy="0.0" ixz="0.0" iyy="0.010267495893" iyz="0.0" izz="0.00666"/>
    </inertial>
  </link>
  <joint name="right_shoulder_lift_joint" type="revolute">
    <parent link="right_shoulder_link"/>
    <child link="right_upper_arm_link"/>
    <origin rpy="0.0 1.57079632679 0.0" xyz="0.0 0.13585 0.0"/>
    <axis xyz="0 1 0"/>
    <limit effort="150.0" lower="-3.14159265359" upper="3.14159265359" velocity="3.15"/>
    <dynamics damping="0.0" friction="0.0"/>
  </joint>
  <link name="right_upper_arm_link">
    <visual>
      <geometry>
        <mesh filename="meshes/ur5/visual/upperarm.dae"/>
      </geometry>
      <material name="LightGrey">
        <color rgba="0.7 0.7 0.7 1.0"/>
      </material>
    </visual>
    <collision>
      <geometry>
        <mesh filename="meshes/ur5/collision/upperarm.dae"/>
      </geometry>
    </collision>
    <inertial>
      <mass value="8.393"/>
      <origin rpy="0 0 0" xyz="0.0 0.0 0.28"/>
      <inertia ixx="0.22689067591" ixy="0.0" ixz="0.0" iyy="0.22689067591" iyz="0.0" izz="0.0151074"/>
    </inertial>
  </link>
  <joint name="right_elbow_joint" type="revolute">
    <parent link="right_upper_arm_link"/>
    <child link="right_forearm_link"/>
    <origin rpy="0.0 0.0 0.0" xyz="0.0 -0.1197 0.425"/>
    <axis xyz="0 1 0"/>
    <limit effort="150.0" lower="0" upper="3.14159265359" velocity="3.15"/>
    <dynamics damping="0.0" friction="0.0"/>
  </joint>
  <link name="right_forearm_link">
    <visual>
      <geometry>
        <mesh filename="meshes/ur5/visual/forearm.dae"/>
      </geometry>
      <material name="LightGrey">
        <color rgba="0.7 0.7 0.7 1.0"/>
      </material>
    </visual>
    <collision>
      <geometry>
        <mesh filename="meshes/ur5/collision/forearm.dae"/>
      </geometry>
    </collision>
    <inertial>
      <mass value="2.275"/>
      <origin rpy="0 0 0" xyz="0.0 0.0 0.196125"/>
      <inertia ixx="0.0312167910289" ixy="0.0" ixz="0.0" iyy="0.0312167910289" iyz="0.0" izz="0.004095"/>
    </inertial>
  </link>
  <joint name="right_wrist_1_joint" type="revolute">
    <parent link="right_forearm_link"/>
    <child link="right_wrist_1_link"/>
    <origin rpy="0.0 1.57079632679 0.0" xyz="0.0 0.0 0.39225"/>
    <axis xyz="0 1 0"/>
    <limit effort="28.0" lower="-3.14159265359" upper="3.14159265359" velocity="3.2"/>
    <dynamics damping="0.0" friction="0.0"/>
  </joint>
  <link name="right_wrist_1_link">
    <visual>
      <geometry>
        <mesh filename="meshes/ur5/visual/wrist1.dae"/>
      </geometry>
      <material name="LightGrey">
        <color rgba="0.7 0.7 0.7 1.0"/>
      </material>
    </visual>
    <collision>
      <geometry>
        <mesh filename="meshes/ur5/collision/wrist1.dae"/>
      </geometry>
    </collision>
    <inertial>
      <mass value="1.219"/>
      <origin rpy="0 0 0" xyz="0.0 0.093 0.0"/>
      <inertia ixx="0.00255989897604" ixy="0.0" ixz="0.0" iyy="0.00255989897604" iyz="0.0" izz="0.0021942"/>
    </inertial>
  </link>
  <joint name="right_wrist_2_joint" type="revolute">
    <parent link="right_wrist_1_link"/>
    <child link="right_wrist_2_link"/>
    <origin rpy="0.0 0.0 0.0" xyz="0.0 0.093 0.0"/>
    <axis xyz="0 0 1"/>
    <limit effort="28.0" lower="-3.14159265359" upper="3.14159265359" velocity="3.2"/>
    <dynamics damping="0.0" friction="0.0"/>
  </joint>
  <link name="right_wrist_2_link">
    <visual>
      <geometry>
        <mesh filename="meshes/ur5/visual/wrist2.dae"/>
      </geometry>
      <material name="LightGrey">
        <color rgba="0.7 0.7 0.7 1.0"/>
      </material>
    </visual>
    <collision>
      <geometry>
        <mesh filename="meshes/ur5/collision/wrist2.dae"/>
      </geometry>
    </collision>
    <inertial>
      <mass value="1.219"/>
      <origin rpy="0 0 0" xyz="0.0 0.0 0.09465"/>
      <inertia ixx="0.00255989897604" ixy="0.0" ixz="0.0" iyy="0.00255989897604" iyz="0.0" izz="0.0021942"/>
    </inertial>
  </link>
  <joint name="right_wrist_3_joint" type="revolute">
    <parent link="right_wrist_2_link"/>
    <child link="right_wrist_3_link"/>
    <origin rpy="0.0 0.0 0.0" xyz="0.0 0.0 0.09465"/>
    <axis xyz="0 1 0"/>
    <limit effort="28.0" lower="-3.14159265359" upper="3.14159265359" velocity="3.2"/>
    <dynamics damping="0.0" friction="0.0"/>
  </joint>
  <link name="right_wrist_3_link">
    <visual>
      <geometry>
        <mesh filename="meshes/ur5/visual/wrist3.dae"/>
      </geometry>
      <material name="LightGrey">
        <color rgba="0.7 0.7 0.7 1.0"/>
      </material>
    </visual>
    <collision>
      <geometry>
        <mesh filename="meshes/ur5/collision/wrist3.dae"/>
      </geometry>
    </collision>
    <inertial>
      <mass value="0.1879"/>
      <origin rpy="1.57079632679 0 0" xyz="0.0 0.06505 0.0"/>
      <inertia ixx="8.46958911216e-05" ixy="0.0" ixz="0.0" iyy="8.46958911216e-05" iyz="0.0" izz="0.0001321171875"/>
    </inertial>
  </link>
  <joint name="right_ee_fixed_joint" type="fixed">
    <parent link="right_wrist_3_link"/>
    <child link="right_ee_link"/>
    <origin rpy="0.0 0.0 1.57079632679" xyz="0.0 0.0823 0.0"/>
  </joint>
  <link name="right_ee_link">
    <collision>
      <geometry>
        <box size="0.01 -0.01 0.01"/>
      </geometry>
      <origin rpy="0 0 0" xyz="-0.01 0 0"/>
    </collision>
    <objective>
         <type name="position" weight="100" xyz="0.2324 0.9384 0.313" />
         <type name="orientation" weight="300" rpy="0 -90 0"/>
    </objective>
    <tag part="right_hand"/>
  </link>
  
  <joint name="left_arm_joint" type="fixed">
          <parent link="operator_chair"/>
          <child link="left_base_link"/>
          <origin rpy="-1.5708 0 0" xyz="0.5 0.21 1.78"/>
          <axis xyz="0 0 1"/>
        </joint>
    <link name="left_base_link">
      <visual>
        <geometry>
          <mesh filename="meshes/ur5/visual/base.dae"/>
        </geometry>
        <material name="LightGrey">
          <color rgba="0.7 0.7 0.7 1.0"/>
        </material>
      </visual>
      <collision>
        <geometry>
          <mesh filename="meshes/ur5/collision/base.dae"/>
        </geometry>
      </collision>
      <inertial>
        <mass value="4.0"/>
        <origin rpy="0 0 0" xyz="0.0 0.0 0.0"/>
        <inertia ixx="0.00443333156" ixy="0.0" ixz="0.0" iyy="0.00443333156" iyz="0.0" izz="0.0072"/>
      </inertial>
    </link>
    <joint name="left_shoulder_pan_joint" type="revolute">
      <parent link="left_base_link"/>
      <child link="left_shoulder_link"/>
      <origin rpy="0.0 0.0 0.0" xyz="0.0 0.0 0.089159"/>
      <axis xyz="0 0 1"/>
      <limit effort="150.0" lower="-3.14159265359" upper="3.14159265359" velocity="3.15"/>
      <dynamics damping="0.0" friction="0.0"/>
    </joint>
    <link name="left_shoulder_link">
      <visual>
        <geometry>
          <mesh filename="meshes/ur5/visual/shoulder.dae"/>
        </geometry>
      </visual>
      <collision>
        <geometry>
          <mesh filename="meshes/ur5/collision/shoulder.dae"/>
        </geometry>
      </collision>
      <inertial>
        <mass value="3.7"/>
        <origin rpy="0 0 0" xyz="0.0 0.0 0.0"/>
        <inertia ixx="0.010267495893" ixy="0.0" ixz="0.0" iyy="0.010267495893" iyz="0.0" izz="0.00666"/>
      </inertial>
    </link>
    <joint name="left_shoulder_lift_joint" type="revolute">
      <parent link="left_shoulder_link"/>
      <child link="left_upper_arm_link"/>
      <origin rpy="0.0 1.57079632679 0.0" xyz="0.0 0.13585 0.0"/>
      <axis xyz="0 1 0"/>
      <limit effort="150.0" lower="-3.14159265359" upper="3.14159265359" velocity="3.15"/>
      <dynamics damping="0.0" friction="0.0"/>
    </joint>
    <link name="left_upper_arm_link">
      <visual>
        <geometry>
          <mesh filename="meshes/ur5/visual/upperarm.dae"/>
        </geometry>
        <material name="LightGrey">
          <color rgba="0.7 0.7 0.7 1.0"/>
        </material>
      </visual>
      <collision>
        <geometry>
          <mesh filename="meshes/ur5/collision/upperarm.dae"/>
        </geometry>
      </collision>
      <inertial>
        <mass value="8.393"/>
        <origin rpy="0 0 0" xyz="0.0 0.0 0.28"/>
        <inertia ixx="0.22689067591" ixy="0.0" ixz="0.0" iyy="0.22689067591" iyz="0.0" izz="0.0151074"/>
      </inertial>
    </link>
    <joint name="left_elbow_joint" type="revolute">
      <parent link="left_upper_arm_link"/>
      <child link="left_forearm_link"/>
      <origin rpy="0.0 0.0 0.0" xyz="0.0 -0.1197 0.425"/>
      <axis xyz="0 1 0"/>
      <limit effort="150.0" lower="0" upper="3.14159265359" velocity="3.15"/>
      <dynamics damping="0.0" friction="0.0"/>
    </joint>
    <link name="left_forearm_link">
      <visual>
        <geometry>
          <mesh filename="meshes/ur5/visual/forearm.dae"/>
        </geometry>
        <material name="LightGrey">
          <color rgba="0.7 0.7 0.7 1.0"/>
        </material>
      </visual>
      <collision>
        <geometry>
          <mesh filename="meshes/ur5/collision/forearm.dae"/>
        </geometry>
      </collision>
      <inertial>
        <mass value="2.275"/>
        <origin rpy="0 0 0" xyz="0.0 0.0 0.196125"/>
        <inertia ixx="0.0312167910289" ixy="0.0" ixz="0.0" iyy="0.0312167910289" iyz="0.0" izz="0.004095"/>
      </inertial>
    </link>
    <joint name="left_wrist_1_joint" type="revolute">
      <parent link="left_forearm_link"/>
      <child link="left_wrist_1_link"/>
      <origin rpy="0.0 1.57079632679 0.0" xyz="0.0 0.0 0.39225"/>
      <axis xyz="0 1 0"/>
      <limit effort="28.0" lower="-3.14159265359" upper="3.14159265359" velocity="3.2"/>
      <dynamics damping="0.0" friction="0.0"/>
    </joint>
    <link name="left_wrist_1_link">
      <visual>
        <geometry>
          <mesh filename="meshes/ur5/visual/wrist1.dae"/>
        </geometry>
        <material name="LightGrey">
          <color rgba="0.7 0.7 0.7 1.0"/>
        </material>
      </visual>
      <collision>
        <geometry>
          <mesh filename="meshes/ur5/collision/wrist1.dae"/>
        </geometry>
      </collision>
      <inertial>
        <mass value="1.219"/>
        <origin rpy="0 0 0" xyz="0.0 0.093 0.0"/>
        <inertia ixx="0.00255989897604" ixy="0.0" ixz="0.0" iyy="0.00255989897604" iyz="0.0" izz="0.0021942"/>
      </inertial>
    </link>
    <joint name="left_wrist_2_joint" type="revolute">
      <parent link="left_wrist_1_link"/>
      <child link="left_wrist_2_link"/>
      <origin rpy="0.0 0.0 0.0" xyz="0.0 0.093 0.0"/>
      <axis xyz="0 0 1"/>
      <limit effort="28.0" lower="-3.14159265359" upper="3.14159265359" velocity="3.2"/>
      <dynamics damping="0.0" friction="0.0"/>
    </joint>
    <link name="left_wrist_2_link">
      <visual>
        <geometry>
          <mesh filename="meshes/ur5/visual/wrist2.dae"/>
        </geometry>
        <material name="LightGrey">
          <color rgba="0.7 0.7 0.7 1.0"/>
        </material>
      </visual>
      <collision>
        <geometry>
          <mesh filename="meshes/ur5/collision/wrist2.dae"/>
        </geometry>
      </collision>
      <inertial>
        <mass value="1.219"/>
        <origin rpy="0 0 0" xyz="0.0 0.0 0.09465"/>
        <inertia ixx="0.00255989897604" ixy="0.0" ixz="0.0" iyy="0.00255989897604" iyz="0.0" izz="0.0021942"/>
      </inertial>
    </link>
    <joint name="left_wrist_3_joint" type="revolute">
      <parent link="left_wrist_2_link"/>
      <child link="left_wrist_3_link"/>
      <origin rpy="0.0 0.0 0.0" xyz="0.0 0.0 0.09465"/>
      <axis xyz="0 1 0"/>
      <limit effort="28.0" lower="-3.14159265359" upper="3.14159265359" velocity="3.2"/>
      <dynamics damping="0.0" friction="0.0"/>
    </joint>
    <link name="left_wrist_3_link">
      <visual>
        <geometry>
          <mesh filename="meshes/ur5/visual/wrist3.dae"/>
        </geometry>
        <material name="LightGrey">
          <color rgba="0.7 0.7 0.7 1.0"/>
        </material>
      </visual>
      <collision>
        <geometry>
          <mesh filename="meshes/ur5/collision/wrist3.dae"/>
        </geometry>
      </collision>
      <inertial>
        <mass value="0.1879"/>
        <origin rpy="1.57079632679 0 0" xyz="0.0 0.06505 0.0"/>
        <inertia ixx="8.46958911216e-05" ixy="0.0" ixz="0.0" iyy="8.46958911216e-05" iyz="0.0" izz="0.0001321171875"/>
      </inertial>
    </link>
    <joint name="left_ee_fixed_joint" type="fixed">
      <parent link="left_wrist_3_link"/>
      <child link="left_ee_link"/>
      <origin rpy="0.0 0.0 1.57079632679" xyz="0.0 0.0823 0.0"/>
    </joint>
    <link name="left_ee_link">
      <collision>
        <geometry>
          <box size="0.01 -0.01 0.01"/>
        </geometry>
        <origin rpy="0 0 0" xyz="-0.01 0 0"/>
      </collision>
      <objective>
         <type name="position" weight="100" xyz="-0.2324 0.9384 0.313" />
         <type name="orientation" weight="300" rpy="0 -90 0"/>
      </objective>
      <tag part="left_hand"/>
    </link>
</robot>

