<?xml version="1.0" ?>
<robot name="miro_robot">

  <link name="miro_robot__body">
    <inertial>
      <mass value="1.570796"/>
      <origin rpy="0 0 0" xyz="-0.06  0    0.05"/>
      <inertia ixx="0.00523599" ixy="0.0" ixz="0.0" iyy="0.00523599" iyz="0.0" izz="0.00785398"/>
    </inertial>
    <visual name="miro_robot__visual_valance">
      <origin rpy="0 0 0" xyz="0 0 0"/>
      <geometry>
        <mesh filename="meshes/body.dae" scale="1.0 1.0 1.0"/>
      </geometry>
    </visual>
    <!-- <collision name="miro_robot__collision_valance">
      <origin rpy="0 0 0" xyz="0 0 0"/>
      <geometry>
        <mesh filename="meshes/valance_collision.dae" scale="1.0 1.0 1.0"/>
      </geometry>
    </collision>
    <collision name="miro_robot__collision_skirt_lh">
      <origin rpy="0 0 0" xyz="0 0 0"/>
      <geometry>
        <mesh filename="meshes/skirt_lh_collision.dae" scale="1.0 1.0 1.0"/>
      </geometry>
    </collision>
    <collision name="miro_robot__collision_skirt_rh">
      <origin rpy="0 0 0" xyz="0 0 0"/>
      <geometry>
        <mesh filename="meshes/skirt_rh_collision.dae" scale="1.0 1.0 1.0"/>
      </geometry>
    </collision>
    <collision name="miro_robot__collision_body_shell">
      <origin rpy="0 0 0" xyz="0 0 0"/>
      <geometry>
        <mesh filename="meshes/body_shell_collision.dae" scale="1.0 1.0 1.0"/>
      </geometry>
    </collision>
    <collision name="miro_robot__collision_slider">
      <origin rpy="0 0 0" xyz="0 0 0"/>
      <geometry>
        <mesh filename="meshes/slider_collision.dae" scale="1.0 1.0 1.0"/>
      </geometry>
    </collision> -->
  </link>

  <joint name="miro_robot__body_wheel_lh" type="fixed">
    <parent link="miro_robot__body"/>
    <child link="miro_robot__wheel_lh"/>
    <origin rpy="0 0 0" xyz="0.00063 0.07779 0.04483"/>
    <axis xyz="0      0.99965 0.02618"/>
    <limit effort="0" lower="0" upper="0" velocity="0"/>
  </joint>

  <joint name="miro_robot__body_wheel_rh" type="fixed">
    <parent link="miro_robot__body"/>
    <child link="miro_robot__wheel_rh"/>
    <origin rpy="0 0 0" xyz="0.00063 -0.07779  0.04483"/>
    <axis xyz="0       0.99965 -0.02618"/>
    <limit effort="0" lower="0" upper="0" velocity="0"/>
  </joint>

  <joint name="miro_robot__body_tail_gmbl" type="revolute">
    <parent link="miro_robot__body"/>
    <child link="miro_robot__tail_gmbl"/>
    <origin rpy="0 0 0" xyz="-0.14299  0       0.085"/>
    <axis xyz="0 1 0"/>
    <limit effort="0.0" lower="-1.57" upper="1.57" velocity="0.0"/>
  </joint>

  <joint name="miro_robot__tail_gmbl_tail" type="revolute">
    <parent link="miro_robot__tail_gmbl"/>
    <child link="miro_robot__tail"/>
    <origin rpy="0 0 0" xyz="0 0 0"/>
    <axis xyz="0 0 1"/>
    <limit effort="0.0" lower="-1.57" upper="1.57" velocity="0.0"/>
  </joint>

  <joint name="miro_robot__body_neck" type="revolute">
    <parent link="miro_robot__body"/>
    <child link="miro_robot__neck"/>
    <origin rpy="0 0 0" xyz="-0.002  0     0.081"/>
    <axis xyz="0 1 0"/>
    <limit effort="0.0" lower="0.0" upper="1.57" velocity="0.0"/>
  </joint>

  <joint name="miro_robot__neck_gmbl" type="revolute">
    <parent link="miro_robot__neck"/>
    <child link="miro_robot__gmbl"/>
    <origin rpy="0 0 0" xyz="0   0   0.12"/>
    <axis xyz="0 0 1"/>
    <limit effort="0.0" lower="-1.57" upper="1.57" velocity="0.0"/>
  </joint>

  <joint name="miro_robot__gmbl_head" type="revolute">
    <parent link="miro_robot__gmbl"/>
    <child link="miro_robot__head"/>
    <origin rpy="0 0 0" xyz="0 0 0"/>
    <axis xyz="0 1 0"/>
    <limit effort="0.0" lower="-1.57" upper="1.57" velocity="0.0"/>
  </joint>

  <joint name="miro_robot__head_eyelid_lh" type="revolute">
    <parent link="miro_robot__head"/>
    <child link="miro_robot__eyelid_lh"/>
    <origin rpy="0 0 0" xyz="0.031 0.032 0.051"/>
    <axis xyz="-0.675   0.675  -0.2978"/>
    <limit effort="0.0" lower="-1.57" upper="1.57" velocity="0.0"/>
  </joint>

  <joint name="miro_robot__head_eyelid_rh" type="revolute">
    <parent link="miro_robot__head"/>
    <child link="miro_robot__eyelid_rh"/>
    <origin rpy="0 0 0" xyz="0.031 -0.032  0.051"/>
    <axis xyz="0.675  0.675  0.2978"/>
    <limit effort="0.0" lower="-1.57" upper="1.57" velocity="0.0"/>
  </joint>

  <joint name="miro_robot__head_ear_lh" type="revolute">
    <parent link="miro_robot__head"/>
    <child link="miro_robot__ear_lh"/>
    <origin rpy="0 0 0" xyz="-0.0417  0.0474  0.0763"/>
    <axis xyz="-0.57299  0.4344   0.6949"/>
    <limit effort="0.0" lower="-1.57" upper="1.57" velocity="0.0"/>
  </joint>

  <joint name="miro_robot__head_ear_rh" type="revolute">
    <parent link="miro_robot__head"/>
    <child link="miro_robot__ear_rh"/>
    <origin rpy="0 0 0" xyz="-0.0417 -0.0474  0.0763"/>
    <axis xyz="-0.57299 -0.4344   0.6949"/>
    <limit effort="0.0" lower="-1.57" upper="1.57" velocity="0.0"/>
  </joint>
  



  <link name="miro_robot__wheel_lh">
    <inertial>
      <mass value="0.134041"/>
      <origin rpy="-1.57 0 0" xyz="0.00063 0.07779 0.04483"/>
      <inertia ixx="0.00014298" ixy="0.0" ixz="0.0" iyy="0.00014298" iyz="0.0" izz="0.00014298"/>
    </inertial>
    <collision name="miro_robot__collision_wheel_tyre_lh">
      <origin rpy="0-1.57 0 0" xyz="-0.00063 -0.07779 -0.04483"/>
      <geometry>
        <mesh filename="meshes/wheel_tyre_lh_collision.dae" scale="1.0 1.0 1.0"/>
      </geometry>
    </collision>
    <visual name="miro_robot__visual_wheel_tyre_lh">
      <origin rpy="-1.57 0 0" xyz="-0.00063 -0.07779 -0.04483"/>
      <geometry>
        <mesh filename="meshes/wheel_tyre_lh.dae" scale="1.0 1.0 1.0"/>
      </geometry>
    </visual>
    <visual name="miro_robot__visual_wheel_rim_lh">
      <origin rpy="-1.57 0 0" xyz="-0.00063 -0.07779 -0.04483"/>
      <geometry>
        <mesh filename="meshes/wheel_rim_lh.dae" scale="1.0 1.0 1.0"/>
      </geometry>
    </visual>
  </link>

  <link name="miro_robot__wheel_rh">
    <inertial>
      <mass value="0.134041"/>
      <origin rpy="-1.57 0 0" xyz="0.00063 -0.07779  0.04483"/>
      <inertia ixx="0.00014298" ixy="0.0" ixz="0.0" iyy="0.00014298" iyz="0.0" izz="0.00014298"/>
    </inertial>
    <collision name="miro_robot__collision_wheel_tyre_rh">
      <origin rpy="-1.57 0 0" xyz="-0.00063  0.07779 -0.04483"/>
      <geometry>
        <mesh filename="meshes/wheel_tyre_rh_collision.dae" scale="1.0 1.0 1.0"/>
      </geometry>
    </collision>
    <visual name="miro_robot__visual_wheel_tyre_rh">
      <origin rpy="-1.57 0 0" xyz="-0.00063  0.07779 -0.04483"/>
      <geometry>
        <mesh filename="meshes/wheel_tyre_rh.dae" scale="1.0 1.0 1.0"/>
      </geometry>
    </visual>
    <visual name="miro_robot__visual_wheel_rim_rh">
      <origin rpy="-1.57 0 0" xyz="-0.00063  0.07779 -0.04483"/>
      <geometry>
        <mesh filename="meshes/wheel_rim_rh.dae" scale="1.0 1.0 1.0"/>
      </geometry>
    </visual>
  </link>

  <link name="miro_robot__tail_gmbl">
    <inertial>
      <mass value="0.056549"/>
      <origin rpy="0 0 0" xyz="-0.14299  0       0.085"/>
      <inertia ixx="0.00003393" ixy="0.0" ixz="0.0" iyy="0.00003393" iyz="0.0" izz="0.00003393"/>
    </inertial>
  </link>

  <link name="miro_robot__tail">
    <inertial>
      <mass value="0.056549"/>
      <origin rpy="-1.57 0 0" xyz="-0.14299  0       0.085"/>
      <inertia ixx="0.00003393" ixy="0.0" ixz="0.0" iyy="0.00003393" iyz="0.0" izz="0.00003393"/>
    </inertial>
    <collision name="miro_robot__collision_tail">
      <origin rpy="-1.57 0 0" xyz="0.14299  0      -0.085"/>
      <geometry>
        <mesh filename="meshes/tail_collision.dae" scale="1.0 1.0 1.0"/>
      </geometry>
    </collision>
    <visual name="miro_robot__visual_tail">
      <origin rpy="-1.57 0 0" xyz="0.14299  0      -0.085"/>
      <geometry>
        <mesh filename="meshes/tail.dae" scale="1.0 1.0 1.0"/>
      </geometry>
    </visual>
  </link>

  <link name="miro_robot__neck">
    <inertial>
      <mass value="0.075398"/>
      <origin rpy="-1.57 0 0" xyz="-0.002    0       0.14099"/>
      <inertia ixx="0.00009802" ixy="0.0" ixz="0.0" iyy="0.00009802" iyz="0.0" izz="0.00001508"/>
    </inertial>
    <visual name="miro_robot__visual_neck_member_main">
      <origin rpy="-1.57 0 0" xyz="0.002  0    -0.081"/>
      <geometry>
        <mesh filename="meshes/neck_member_main.dae" scale="1.0 1.0 1.0"/>
      </geometry>
    </visual>
    <visual name="miro_robot__visual_neck_mount_upper_pin">
      <origin rpy="-1.57 0 0" xyz="0.002  0    -0.081"/>
      <geometry>
        <mesh filename="meshes/neck_mount_upper_pin.dae" scale="1.0 1.0 1.0"/>
      </geometry>
    </visual>
    <visual name="miro_robot__visual_neck_mount_lower_pin">
      <origin rpy="-1.57 0 0" xyz="0.002  0    -0.081"/>
      <geometry>
        <mesh filename="meshes/neck_mount_lower_pin.dae" scale="1.0 1.0 1.0"/>
      </geometry>
    </visual>
  </link>

  <link name="miro_robot__gmbl">
    <inertial>
      <mass value="0.039270"/>
      <origin rpy="-1.57 0 0" xyz="-0.002  0     0.171"/>
      <inertia ixx="0.00002487" ixy="0.0" ixz="0.0" iyy="0.00002487" iyz="0.0" izz="0.00004909"/>
    </inertial>
    <visual name="miro_robot__visual_collar">
      <origin rpy="-1.57 0 0" xyz="0.002  0    -0.201"/>
      <geometry>
        <mesh filename="meshes/collar.dae" scale="1.0 1.0 1.0"/>
      </geometry>
    </visual>
  </link>

  <link name="miro_robot__head">
    <inertial>
      <mass value="0.261799"/>
      <origin rpy="0 0 0" xyz="-0.002  0     0.221"/>
      <inertia ixx="0.00043633" ixy="0.0" ixz="0.0" iyy="0.00043633" iyz="0.0" izz="0.00043633"/>
    </inertial>
    <!-- <collision name="miro_robot__collision_head_lower">
      <origin rpy="0 0 0" xyz="0.002  0    -0.201"/>
      <geometry>
        <mesh filename="meshes/head_lower_collision.dae" scale="1.0 1.0 1.0"/>
      </geometry>
    </collision>
    <collision name="miro_robot__collision_head_upper">
      <origin rpy="0 0 0" xyz="0.002  0    -0.201"/>
      <geometry>
        <mesh filename="meshes/head_upper_collision.dae" scale="1.0 1.0 1.0"/>
      </geometry>
    </collision>
    <collision name="miro_robot__collision_nose">
      <origin rpy="0 0 0" xyz="0.002  0    -0.201"/>
      <geometry>
        <mesh filename="meshes/nose_collision.dae" scale="1.0 1.0 1.0"/>
      </geometry>
    </collision> -->
    <visual name="miro_robot__visual_head_lower">
      <origin rpy="0 0 0" xyz="0  0  -0.2001"/>
      <geometry>
        <mesh filename="meshes/head.dae" scale="1.0 1.0 1.0"/>
      </geometry>
    </visual>
  </link>

  <link name="miro_robot__eyelid_lh">
    <inertial>
      <mass value="0.016755"/>
      <origin rpy="-1.57 0 0" xyz="0.029 0.032 0.252"/>
      <inertia ixx="0.00000447" ixy="0.0" ixz="0.0" iyy="0.00000447" iyz="0.0" izz="0.00000447"/>
    </inertial>
    <visual name="miro_robot__visual_eyelid_lh">
      <origin rpy="-1.57 0 0" xyz="-0.029 -0.032 -0.252"/>
      <geometry>
        <mesh filename="meshes/eyelid_lh.dae" scale="1.0 1.0 1.0"/>
      </geometry>
    </visual>
  </link>

  <link name="miro_robot__eyelid_rh">
    <inertial>
      <mass value="0.016755"/>
      <origin rpy="-1.57 0 0" xyz="0.029 -0.032  0.252"/>
      <inertia ixx="0.00000447" ixy="0.0" ixz="0.0" iyy="0.00000447" iyz="0.0" izz="0.00000447"/>
    </inertial>
    <visual name="miro_robot__visual_eyelid_rh">
      <origin rpy="-1.57 0 0" xyz="-0.029  0.032 -0.252"/>
      <geometry>
        <mesh filename="meshes/eyelid_rh.dae" scale="1.0 1.0 1.0"/>
      </geometry>
    </visual>
  </link>

  <link name="miro_robot__ear_lh">
    <inertial>
      <mass value="0.056549"/>
      <origin rpy="-1.57 0 0" xyz="-0.0437  0.0474  0.2773"/>
      <inertia ixx="0.00003393" ixy="0.0" ixz="0.0" iyy="0.00003393" iyz="0.0" izz="0.00003393"/>
    </inertial>
    <collision name="miro_robot__collision_ear_lh">
      <origin rpy="-1.57 0 0" xyz="0.0437 -0.0474 -0.2773"/>
      <geometry>
        <mesh filename="meshes/ear_lh_collision.dae" scale="1.0 1.0 1.0"/>
      </geometry>
    </collision>
    <visual name="miro_robot__visual_ear_lh">
      <origin rpy="-1.57 0 0" xyz="0.0437 -0.0474 -0.2773"/>
      <geometry>
        <mesh filename="meshes/ear_lh.dae" scale="1.0 1.0 1.0"/>
      </geometry>
    </visual>
  </link>

  <link name="miro_robot__ear_rh">
    <inertial>
      <mass value="0.056549"/>
      <origin rpy="-1.57 0 0" xyz="-0.0437 -0.0474  0.2773"/>
      <inertia ixx="0.00003393" ixy="0.0" ixz="0.0" iyy="0.00003393" iyz="0.0" izz="0.00003393"/>
    </inertial>
    <collision name="miro_robot__collision_ear_rh">
      <origin rpy="-1.57 0 0" xyz="0.0437  0.0474 -0.2773"/>
      <geometry>
        <mesh filename="meshes/ear_rh_collision.dae" scale="1.0 1.0 1.0"/>
      </geometry>
    </collision>
    <visual name="miro_robot__visual_ear_rh">
      <origin rpy="-1.57 0 0" xyz="0.0437  0.0474 -0.2773"/>
      <geometry>
        <mesh filename="meshes/ear_rh.dae" scale="1.0 1.0 1.0"/>
      </geometry>
    </visual>
  </link>

</robot>
