<robot name="Artus3D_RightHand">

<link name= "base_link"/>

<joint name="virtual" type="fixed">
	<origin xyz="0 0 0" rpy="1.67 0 0"/>
	<parent link="base_link"/>
	<child link="right_forearm_and_palm_subassembly"/>
</joint>
            
<link name="right_forearm_and_palm_subassembly">
	<visual>
		<origin xyz="0.27022215162266061128 0.22117640734292376425 0.029159033846879255092" rpy="0 0 3.141592653589793116" />
		<geometry>
			<mesh filename="meshes/front_palm_l.stl"/>
		</geometry>
		<material name="front_palm_l_material">
			<color rgba="0.26274509803921569651 0.28235294117647058432 0.30196078431372547213 1.0"/>
		</material>
	</visual>
	<collision>
		<origin xyz="0.27022215162266061128 0.22117640734292376425 0.029159033846879255092" rpy="0 0 3.141592653589793116" />
		<geometry>
			<mesh filename="meshes/front_palm_l.stl"/>
		</geometry>
	</collision>
	<visual>
		<origin xyz="0.21465692079361570199 0.16859189386105288833 -0.068046090206641096643" rpy="1.0663166621722239835 -1.0057357117289853488 -6.5311260328378797868e-15" />
		<geometry>
			<mesh filename="meshes/part_1.stl"/>
		</geometry>
		<material name="part_1_material">
			<color rgba="0.76862745098039220171 0.88627450980392152857 0.95294117647058818044 1.0"/>
		</material>
	</visual>
	<collision>
		<origin xyz="0.21465692079361570199 0.16859189386105288833 -0.068046090206641096643" rpy="1.0663166621722239835 -1.0057357117289853488 -6.5311260328378797868e-15" />
		<geometry>
			<mesh filename="meshes/part_1.stl"/>
		</geometry>
	</collision>
	<visual>
		<origin xyz="0.27022215162266061128 0.22117640734292376425 0.029159033846879255092" rpy="0 0 3.141592653589793116" />
		<geometry>
			<mesh filename="meshes/r_forearm_back_cover.stl"/>
		</geometry>
		<material name="r_forearm_back_cover_material">
			<color rgba="0.26274509803921569651 0.28235294117647058432 0.30196078431372547213 1.0"/>
		</material>
	</visual>
	<collision>
		<origin xyz="0.27022215162266061128 0.22117640734292376425 0.029159033846879255092" rpy="0 0 3.141592653589793116" />
		<geometry>
			<mesh filename="meshes/r_forearm_back_cover.stl"/>
		</geometry>
	</collision>
	<visual>
		<origin xyz="0.27022215162266061128 0.22117640734292376425 0.029159033846879255092" rpy="0 0 3.141592653589793116" />
		<geometry>
			<mesh filename="meshes/r_pinky_side_forearm_cover.stl"/>
		</geometry>
		<material name="r_pinky_side_forearm_cover_material">
			<color rgba="0.91764705882352937127 0.91764705882352937127 0.91764705882352937127 1.0"/>
		</material>
	</visual>
	<collision>
		<origin xyz="0.27022215162266061128 0.22117640734292376425 0.029159033846879255092" rpy="0 0 3.141592653589793116" />
		<geometry>
			<mesh filename="meshes/r_pinky_side_forearm_cover.stl"/>
		</geometry>
	</collision>
	<visual>
	<origin xyz="0.27022215162266061128 0.22117640734292376425 0.029159033846879255092" rpy="0 0 3.141592653589793116" />
		<geometry>
			<mesh filename="meshes/r_forearm_front_cover.stl"/>
		</geometry>
		<material name="r_forearm_front_cover_material">
			<color rgba="0.26274509803921569651 0.28235294117647058432 0.30196078431372547213 1.0"/>
		</material>
	</visual>
	<collision>
		<origin xyz="0.27022215162266061128 0.22117640734292376425 0.029159033846879255092" rpy="0 0 3.141592653589793116" />
		<geometry>
			<mesh filename="meshes/r_forearm_front_cover.stl"/>
		</geometry>
	</collision>
	<visual>
		<origin xyz="0.27022215162266061128 0.22117640734292376425 0.029159033846879255092" rpy="0 0 3.141592653589793116" />
		<geometry>
			<mesh filename="meshes/back_palm_l.stl"/>
		</geometry>
		<material name="back_palm_l_material">
			<color rgba="0.26274509803921569651 0.28235294117647058432 0.30196078431372547213 1.0"/>
		</material>
	</visual>
	<collision>
		<origin xyz="0.27022215162266061128 0.22117640734292376425 0.029159033846879255092" rpy="0 0 3.141592653589793116" />
		<geometry>
			<mesh filename="meshes/back_palm_l.stl"/>
		</geometry>
	</collision>
	<visual>
		<origin xyz="0.24317582107437840655 0.29568034405808418796 0.017509033846879382829" rpy="8.6736173798836595305e-17 1.3601620973396744881e-15 -1.500983156715123501" />
		<geometry>
			<mesh filename="meshes/part_1.stl"/>
		</geometry>
		<material name="part_1_material">
			<color rgba="0.98039215686274505668 0.71372549019607844922 0.0039215686274509803377 1.0"/>
		</material>
	</visual>
		<collision>
		<origin xyz="0.24317582107437840655 0.29568034405808418796 0.017509033846879382829" rpy="8.6736173798836595305e-17 1.3601620973396744881e-15 -1.500983156715123501" />
		<geometry>
			<mesh filename="meshes/part_1.stl"/>
		</geometry>
	</collision>
	<visual>
		<origin xyz="0.27022215162266061128 0.22117640734292376425 0.029159033846879255092" rpy="0 0 3.141592653589793116" />
		<geometry>
			<mesh filename="meshes/forearm_front_heat_sink.stl"/>
		</geometry>
		<material name="forearm_front_heat_sink_material">
			<color rgba="0.91764705882352937127 0.91764705882352937127 0.91764705882352937127 1.0"/>
		</material>
	</visual>
	<collision>
		<origin xyz="0.27022215162266061128 0.22117640734292376425 0.029159033846879255092" rpy="0 0 3.141592653589793116" />
		<geometry>
			<mesh filename="meshes/forearm_front_heat_sink.stl"/>
		</geometry>
	</collision>
	<visual>
		<origin xyz="0.27022215162266061128 0.22117640734292379201 0.029159033846879196111" rpy="6.1062266354382594065e-16 -1.4674862355444682429e-16 -3.141592653589793116" />
		<geometry>
			<mesh filename="meshes/palm_back_r.stl"/>
		</geometry>
		<material name="palm_back_r_material">
			<color rgba="0.26274509803921569651 0.28235294117647058432 0.30196078431372547213 1.0"/>
		</material>
	</visual>
	<collision>
		<origin xyz="0.27022215162266061128 0.22117640734292379201 0.029159033846879196111" rpy="6.1062266354382594065e-16 -1.4674862355444682429e-16 -3.141592653589793116" />
		<geometry>
			<mesh filename="meshes/palm_back_r.stl"/>
		</geometry>
	</collision>
	<visual>
		<origin xyz="0.32151616221501622128 0.28638553038391317829 0.014509033846879387103" rpy="-1.7347234759768169552e-16 1.1724579715493670881e-15 -1.6929693744344997963" />
		<geometry>
			<mesh filename="meshes/part_1.stl"/>
		</geometry>
		<material name="part_1_material">
			<color rgba="0.98039215686274505668 0.71372549019607844922 0.0039215686274509803377 1.0"/>
		</material>
	</visual>
	<collision>
		<origin xyz="0.32151616221501622128 0.28638553038391317829 0.014509033846879387103" rpy="-1.7347234759768169552e-16 1.1724579715493670881e-15 -1.6929693744344997963" />
		<geometry>
			<mesh filename="meshes/part_1.stl"/>
		</geometry>
	</collision>
	<visual>
		<origin xyz="0.27042215162266058925 0.2211764073429234867 0.029159033846879199581" rpy="4.4408920985005088186e-16 -1.0814508560609147443e-16 -3.141592653589793116" />
		<geometry>
			<mesh filename="meshes/palm_front_r.stl"/>
		</geometry>
		<material name="palm_front_r_material">
			<color rgba="0.26274509803921569651 0.28235294117647058432 0.30196078431372547213 1.0"/>
		</material>
	</visual>
	<collision>
		<origin xyz="0.27042215162266058925 0.2211764073429234867 0.029159033846879199581" rpy="4.4408920985005088186e-16 -1.0814508560609147443e-16 -3.141592653589793116" />
		<geometry>
			<mesh filename="meshes/palm_front_r.stl"/>
		</geometry>
	</collision>
	<visual>
		<origin xyz="0.2702221516226607223 0.298926407342923528 0.020509033846879385493" rpy="-2.6131017485446026564e-30 1.3010426069825970378e-15 -1.57079632679489678" />
		<geometry>
			<mesh filename="meshes/part_1.stl"/>
		</geometry>
		<material name="part_1_material">
			<color rgba="0.98039215686274505668 0.71372549019607844922 0.0039215686274509803377 1.0"/>
		</material>
	</visual>
	<collision>
		<origin xyz="0.2702221516226607223 0.298926407342923528 0.020509033846879385493" rpy="-2.6131017485446026564e-30 1.3010426069825970378e-15 -1.57079632679489678" />
		<geometry>
			<mesh filename="meshes/part_1.stl"/>
		</geometry>
	</collision>
	<visual>
		<origin xyz="0.27022215162266061128 0.22117640734292376425 0.029159033846879255092" rpy="0 0 3.141592653589793116" />
		<geometry>
			<mesh filename="meshes/r_thumb_side_forearm_cover.stl"/>
		</geometry>
		<material name="r_thumb_side_forearm_cover_material">
			<color rgba="0.91764705882352937127 0.91764705882352937127 0.91764705882352937127 1.0"/>
		</material>
	</visual>
	<collision>
		<origin xyz="0.27022215162266061128 0.22117640734292376425 0.029159033846879255092" rpy="0 0 3.141592653589793116" />
		<geometry>
			<mesh filename="meshes/r_thumb_side_forearm_cover.stl"/>
		</geometry>
	</collision>
	<visual>
		<origin xyz="0.27042215162266047823 0.22117640734292354221 0.029159033846879213459" rpy="1.4988357199199227105e-29 -4.0922159458340092503e-30 3.141592653589793116" />
		<geometry>
			<mesh filename="meshes/palm_grip.stl"/>
		</geometry>
		<material name="palm_grip_material">
			<color rgba="1 1 1 1.0"/>
		</material>
	</visual>
	<collision>
		<origin xyz="0.27042215162266047823 0.22117640734292354221 0.029159033846879213459" rpy="1.4988357199199227105e-29 -4.0922159458340092503e-30 3.141592653589793116" />
		<geometry>
			<mesh filename="meshes/palm_grip.stl"/>
		</geometry>
	</collision>
	<visual>
		<origin xyz="0.27022215162266061128 0.22117640734292376425 0.029159033846879255092" rpy="0 0 3.141592653589793116" />
		<geometry>
			<mesh filename="meshes/forearm_base_plate.stl"/>
		</geometry>
		<material name="forearm_base_plate_material">
			<color rgba="0.91764705882352937127 0.91764705882352937127 0.91764705882352937127 1.0"/>
		</material>
	</visual>
	<collision>
		<origin xyz="0.27022215162266061128 0.22117640734292376425 0.029159033846879255092" rpy="0 0 3.141592653589793116" />
		<geometry>
			<mesh filename="meshes/forearm_base_plate.stl"/>
		</geometry>
	</collision>
	<visual>
		<origin xyz="0.29701049375490701232 0.29429252243242220999 0.01750903384687943487" rpy="-8.6736173798841685923e-17 1.2376974174249377622e-15 -1.640609496874669837" />
		<geometry>
			<mesh filename="meshes/part_1.stl"/>
		</geometry>
		<material name="part_1_material">
			<color rgba="0.98039215686274505668 0.71372549019607844922 0.0039215686274509803377 1.0"/>
		</material>
	</visual>
	<collision>
		<origin xyz="0.29701049375490701232 0.29429252243242220999 0.01750903384687943487" rpy="-8.6736173798841685923e-17 1.2376974174249377622e-15 -1.640609496874669837" />
		<geometry>
			<mesh filename="meshes/part_1.stl"/>
		</geometry>
	</collision>
	<inertial>
		<origin xyz="0.27833018982470036917 0.11381895022192221878 0.014058984322116387447" rpy="0 0 0"/>
		<mass value="0.25122938234437303118" />
		<inertia ixx="0.00086395203424330488558" ixy="-6.6055071488837621993e-07"  ixz="1.831068863468126472e-06" iyy="0.00020198744439617747942" iyz="1.1024803871899870917e-06" izz="0.00090795209910098052461" />
	</inertial>
</link>

<link name="part_1_1">
	<visual>
		<origin xyz="-0.0049999999999999766853 5.5511151231257827021e-17 -0.018500000000000103167" rpy="-1.4485681946286609539e-16 8.5979375613828716732e-16 -1.0813019735923997568e-17" />
		<geometry>
			<mesh filename="meshes/part_1_1.stl"/>
		</geometry>
		<material name="part_1_1_material">
			<color rgba="0.64705882352941179736 0.64705882352941179736 0.64705882352941179736 1.0"/>
		</material>
	</visual>
	<collision>
		<origin xyz="-0.0049999999999999766853 5.5511151231257827021e-17 -0.018500000000000103167" rpy="-1.4485681946286609539e-16 8.5979375613828716732e-16 -1.0813019735923997568e-17" />
		<geometry>
			<mesh filename="meshes/part_1_1.stl"/>
		</geometry>
	</collision>
	<inertial>
		<origin xyz="0 0 0" rpy="0 0 0"/>
		<mass value="0" />
		<inertia ixx="0" ixy="0"  ixz="0" iyy="0" iyz="0" izz="0" />
	</inertial>
</link>

<link name="part_1_6">
	<visual>
		<origin xyz="-0.02855240728970959152 -0.0078589767938891108567 -0.0060000000000051678661" rpy="-1.570796326794896558 9.2227433296556115776e-16 -3.4758332546525652334e-19" />
		<geometry>
			<mesh filename="meshes/part_1_6.stl"/>
		</geometry>
		<material name="part_1_6_material">
			<color rgba="0.61568627450980395466 0.81176470588235294379 0.92941176470588238168 1.0"/>
		</material>
	</visual>
	<collision>
		<origin xyz="-0.02855240728970959152 -0.0078589767938891108567 -0.0060000000000051678661" rpy="-1.570796326794896558 9.2227433296556115776e-16 -3.4758332546525652334e-19" />
		<geometry>
			<mesh filename="meshes/part_1_6.stl"/>
		</geometry>
	</collision>
	<inertial>
		<origin xyz="0 0 0" rpy="0 0 0"/>
		<mass value="0" />
		<inertia ixx="0" ixy="0"  ixz="0" iyy="0" iyz="0" izz="0" />
	</inertial>
</link>

<link name="part_1_12">
<visual>
	<origin xyz="-0.017524803018038714875 -0.0071295923980049125818 -0.0050000000000001709743" rpy="-1.5707963267948970021 3.9805887644381489929e-16 -1.7015608569879365403e-18" />
		<geometry>
			<mesh filename="meshes/part_1_12.stl"/>
		</geometry>
		<material name="part_1_12_material">
			<color rgba="0.91764705882352937127 0.91764705882352937127 0.91764705882352937127 1.0"/>
		</material>
	</visual>
	<collision>
		<origin xyz="-0.017524803018038714875 -0.0071295923980049125818 -0.0050000000000001709743" rpy="-1.5707963267948970021 3.9805887644381489929e-16 -1.7015608569879365403e-18" />
		<geometry>
			<mesh filename="meshes/part_1_12.stl"/>
		</geometry>
	</collision>
	<inertial>
		<origin xyz="0 0 0" rpy="0 0 0"/>
		<mass value="0" />
		<inertia ixx="0" ixy="0"  ixz="0" iyy="0" iyz="0" izz="0" />
	</inertial>
</link>

<link name="d1_urdf_mk_5_1">
	<visual>
		<origin xyz="-0.0090000000000001745271 -0.005999999999999961961 -0.0047499999999967013053" rpy="-1.5707963267948961139 8.2391162688449915636e-17 -5.047128124993360392e-20" />
		<geometry>
			<mesh filename="meshes/d1_urdf_mk_5_1.stl"/>
		</geometry>
		<material name="d1_urdf_mk_5_1_material">
			<color rgba="0.2313725490196078538 0.38039215686274507888 0.7058823529411765163 1.0"/>
		</material>
	</visual>
	<collision>
		<origin xyz="-0.0090000000000001745271 -0.005999999999999961961 -0.0047499999999967013053" rpy="-1.5707963267948961139 8.2391162688449915636e-17 -5.047128124993360392e-20" />
		<geometry>
			<mesh filename="meshes/d1_urdf_mk_5_1.stl"/>
		</geometry>
	</collision>
	<inertial>
		<origin xyz="0 0 0" rpy="0 0 0"/>
		<mass value="0" />
		<inertia ixx="0" ixy="0"  ixz="0" iyy="0" iyz="0" izz="0" />
	</inertial>
</link>

<joint name="Rpinky_34" type="revolute">
	<origin xyz="-0.024999999999999911182 -2.7755575615628913511e-17 -0.00024999999999997246647" rpy="-2.5846105577199350155e-16 -5.3507205217156890532e-15 -8.4916248960276647562e-17" />
	<parent link="part_1_12" />
	<child link="d1_urdf_mk_5_1" />
	<axis xyz="0 0 1"/>
	<limit effort="100" velocity="20" lower="0" upper="1.570796326794896558"/>
	<joint_properties friction="0.0"/>
</joint>

<joint name="Rpinky_23" type="revolute">
	<origin xyz="-0.03800000000000142153 0.00075000000000003883005 -0.00075000000000030597747" rpy="1.0977252163979831959e-16 -9.4553083945861459176e-15 -2.050712254777831462e-16" />
	<parent link="part_1_6" />
	<child link="part_1_12" />
	<axis xyz="0 0 1"/>
	<limit effort="100" velocity="20" lower="0" upper="1.570796326794896558"/>
	<joint_properties friction="0.0"/>
</joint>

<joint name="Rpinky_12" type="revolute">
	<origin xyz="-0.014749999999999902078 -0.0060000000000000053291 -0.0095000000000000413974" rpy="1.570796326794896558 -0.01706612535995265939 1.0521033289812813459e-14" />
	<parent link="part_1_1" />
	<child link="part_1_6" />
	<axis xyz="0 0 1"/>
	<limit effort="100" velocity="20" lower="0" upper="1.570796326794896558"/>
	<joint_properties friction="0.0"/>
</joint>

<joint name="Rpinky_01" type="revolute">
	<origin xyz="0.31204082076526601375 0.20921506709380074951 0.023259033846879245688" rpy="-1.7347233743320178269e-16 3.0509623903233751317e-16 -1.6929693744344997963" />
	<parent link="right_forearm_and_palm_subassembly" />
	<child link="part_1_1" />
	<axis xyz="0 0 1"/>
	<limit effort="100" velocity="20" lower="-0.29670597283903604735" upper="0.29670597283903604735"/>
	<joint_properties friction="0.0"/>
</joint>

<link name="part_1_2">
	<visual>
		<origin xyz="-0.0050000000000000044409 1.1102230246251565404e-16 -0.018500000000000103167" rpy="-1.4485681946286612004e-16 8.5979375613828706871e-16 -2.5862199565044873083e-18" />
		<geometry>
			<mesh filename="meshes/part_1_2.stl"/>
		</geometry>
		<material name="part_1_2_material">
			<color rgba="0.64705882352941179736 0.64705882352941179736 0.64705882352941179736 1.0"/>
		</material>
	</visual>
	<collision>
		<origin xyz="-0.0050000000000000044409 1.1102230246251565404e-16 -0.018500000000000103167" rpy="-1.4485681946286612004e-16 8.5979375613828706871e-16 -2.5862199565044873083e-18" />
		<geometry>
			<mesh filename="meshes/part_1_2.stl"/>
		</geometry>
	</collision>
	<inertial>
		<origin xyz="0 0 0" rpy="0 0 0"/>
		<mass value="0" />
		<inertia ixx="0" ixy="0"  ixz="0" iyy="0" iyz="0" izz="0" />
	</inertial>
</link>

<link name="part_1_7">
	<visual>
		<origin xyz="-0.028552407289709647031 -0.0078589767938891941235 -0.006000000000005112355" rpy="-1.570796326794896558 9.1947983766684973522e-16 -1.79717864462358042e-18" />
		<geometry>
			<mesh filename="meshes/part_1_7.stl"/>
		</geometry>
		<material name="part_1_7_material">
			<color rgba="0.61568627450980395466 0.81176470588235294379 0.92941176470588238168 1.0"/>
		</material>
	</visual>
	<collision>
		<origin xyz="-0.028552407289709647031 -0.0078589767938891941235 -0.006000000000005112355" rpy="-1.570796326794896558 9.1947983766684973522e-16 -1.79717864462358042e-18" />
		<geometry>
			<mesh filename="meshes/part_1_7.stl"/>
		</geometry>
	</collision>
	<inertial>
		<origin xyz="0 0 0" rpy="0 0 0"/>
		<mass value="0" />
		<inertia ixx="0" ixy="0"  ixz="0" iyy="0" iyz="0" izz="0" />
	</inertial>
</link>

<link name="part_1_11">
	<visual>
		<origin xyz="-0.017524803018038770386 -0.0071295923980055908586 -0.0052500000000002544631" rpy="-1.5707963267948970021 5.1748430582404409511e-16 1.3049018622486970354e-18" />
		<geometry>
			<mesh filename="meshes/part_1_11.stl"/>
		</geometry>
		<material name="part_1_11_material">
			<color rgba="0.91764705882352937127 0.91764705882352937127 0.91764705882352937127 1.0"/>
		</material>
	</visual>
	<collision>
		<origin xyz="-0.017524803018038770386 -0.0071295923980055908586 -0.0052500000000002544631" rpy="-1.5707963267948970021 5.1748430582404409511e-16 1.3049018622486970354e-18" />
		<geometry>
			<mesh filename="meshes/part_1_11.stl"/>
		</geometry>
	</collision>
	<inertial>
		<origin xyz="0 0 0" rpy="0 0 0"/>
		<mass value="0" />
		<inertia ixx="0" ixy="0"  ixz="0" iyy="0" iyz="0" izz="0" />
	</inertial>
</link>

<link name="d1_urdf_mk_5_4">
	<visual>
		<origin xyz="-0.0090000000000002855494 -0.0059999999999999636957 -0.0047499999999967568165" rpy="-1.5707963267948961139 7.9254826366592100803e-17 3.8105364859119316186e-18" />
		<geometry>
			<mesh filename="meshes/d1_urdf_mk_5_4.stl"/>
		</geometry>
		<material name="d1_urdf_mk_5_4_material">
			<color rgba="0.2313725490196078538 0.38039215686274507888 0.7058823529411765163 1.0"/>
		</material>
	</visual>
	<collision>
		<origin xyz="-0.0090000000000002855494 -0.0059999999999999636957 -0.0047499999999967568165" rpy="-1.5707963267948961139 7.9254826366592100803e-17 3.8105364859119316186e-18" />
		<geometry>
			<mesh filename="meshes/d1_urdf_mk_5_4.stl"/>
		</geometry>
	</collision>
	<inertial>
		<origin xyz="0 0 0" rpy="0 0 0"/>
		<mass value="0" />
		<inertia ixx="0" ixy="0"  ixz="0" iyy="0" iyz="0" izz="0" />
	</inertial>
</link>

<joint name="Rring_34" type="revolute">
	<origin xyz="-0.025000000000000022204 -7.0776717819853729452e-16 -0.00050000000000000044409" rpy="-3.4444741466707755292e-16 3.1101387747979473909e-15 9.0334115344911956749e-16" />
	<parent link="part_1_11" />
	<child link="d1_urdf_mk_5_4" />
	<axis xyz="0 0 1"/>
	<limit effort="100" velocity="20" lower="0" upper="1.570796326794896558"/>
	<joint_properties friction="0.0"/>
</joint>

<joint name="Rring_23" type="revolute">
	<origin xyz="-0.038000000000000588862 0.00074999999999995209388 -0.00074999999999986188826" rpy="3.2470459141724979497e-16 2.8338639236892840841e-16 -2.4126804377698217969e-16" />
	<parent link="part_1_7" />
	<child link="part_1_11" />
	<axis xyz="0 0 1"/>
	<limit effort="100" velocity="20" lower="0" upper="1.570796326794896558"/>
	<joint_properties friction="0.0"/>
</joint>

<joint name="Rring_12" type="revolute">
	<origin xyz="-0.014749999999999791056 -0.0059999999999998943068 -0.00950000000000005701" rpy="1.57079632679489678 -0.021451570053433375446 -1.9183758915016864414e-15" />
	<parent link="part_1_2" />
	<child link="part_1_7" />
	<axis xyz="0 0 1"/>
	<limit effort="100" velocity="20" lower="0" upper="1.570796326794896558"/>
	<joint_properties friction="0.0"/>
</joint>

<joint name="Rring_01" type="revolute">
	<origin xyz="0.29158692792130114224 0.21673191752472104055 0.026259033846879276108" rpy="-1.2430645101731211509e-15 3.0910333916306608256e-16 -1.640609496874669837" />
	<parent link="right_forearm_and_palm_subassembly" />
	<child link="part_1_2" />
	<axis xyz="0 0 1"/>
	<limit effort="100" velocity="20" lower="-0.29670597283903604735" upper="0.29670597283903604735"/>
	<joint_properties friction="0.0"/>
</joint>

<link name="part_1_4">
	<visual>
		<origin xyz="-0.0049999999999999766853 5.5511151231257827021e-17 -0.018500000000000106637" rpy="-1.4485681946286607074e-16 8.5979375613828716732e-16 1.5390339806567089152e-33" />
		<geometry>
			<mesh filename="meshes/part_1_4.stl"/>
		</geometry>
		<material name="part_1_4_material">
			<color rgba="0.64705882352941179736 0.64705882352941179736 0.64705882352941179736 1.0"/>
		</material>
	</visual>
	<collision>
		<origin xyz="-0.0049999999999999766853 5.5511151231257827021e-17 -0.018500000000000106637" rpy="-1.4485681946286607074e-16 8.5979375613828716732e-16 1.5390339806567089152e-33" />
		<geometry>
			<mesh filename="meshes/part_1_4.stl"/>
		</geometry>
	</collision>
	<inertial>
		<origin xyz="0 0 0" rpy="0 0 0"/>
		<mass value="0" />
		<inertia ixx="0" ixy="0"  ixz="0" iyy="0" iyz="0" izz="0" />
	</inertial>
</link>

<link name="part_1_5">
	<visual>
		<origin xyz="-0.028552407289709647031 -0.0078589767938891108567 -0.006000000000005112355" rpy="-1.570796326794896558 9.131239013115349202e-16 -1.0718988740600774058e-19" />
		<geometry>
			<mesh filename="meshes/part_1_5.stl"/>
		</geometry>
		<material name="part_1_5_material">
			<color rgba="0.61568627450980395466 0.81176470588235294379 0.92941176470588238168 1.0"/>
		</material>
	</visual>
	<collision>
		<origin xyz="-0.028552407289709647031 -0.0078589767938891108567 -0.006000000000005112355" rpy="-1.570796326794896558 9.131239013115349202e-16 -1.0718988740600774058e-19" />
		<geometry>
			<mesh filename="meshes/part_1_5.stl"/>
		</geometry>
	</collision>
	<inertial>
		<origin xyz="0 0 0" rpy="0 0 0"/>
		<mass value="0" />
		<inertia ixx="0" ixy="0"  ixz="0" iyy="0" iyz="0" izz="0" />
	</inertial>
</link>

<link name="part_1_10">
	<visual>
		<origin xyz="-0.017524803018038770386 -0.0071295923980055925934 -0.005250000000000198952" rpy="-1.5707963267948970021 5.1781495757909565313e-16 7.7640456620824948258e-20" />
		<geometry>
			<mesh filename="meshes/part_1_10.stl"/>
		</geometry>
		<material name="part_1_10_material">
			<color rgba="0.91764705882352937127 0.91764705882352937127 0.91764705882352937127 1.0"/>
		</material>
	</visual>
	<collision>
		<origin xyz="-0.017524803018038770386 -0.0071295923980055925934 -0.005250000000000198952" rpy="-1.5707963267948970021 5.1781495757909565313e-16 7.7640456620824948258e-20" />
		<geometry>
			<mesh filename="meshes/part_1_10.stl"/>
		</geometry>
	</collision>
	<inertial>
		<origin xyz="0 0 0" rpy="0 0 0"/>
		<mass value="0" />
		<inertia ixx="0" ixy="0"  ixz="0" iyy="0" iyz="0" izz="0" />
	</inertial>
</link>

<link name="d1_urdf_mk_5_2">
	<visual>
		<origin xyz="-0.0090000000000001745271 -0.0059999999999999636957 -0.0047499999999967013053" rpy="-1.5707963267948961139 8.3887279286788947566e-17 7.7658881428786524538e-20" />
		<geometry>
			<mesh filename="meshes/d1_urdf_mk_5_2.stl"/>
		</geometry>
		<material name="d1_urdf_mk_5_2_material">
			<color rgba="0.2313725490196078538 0.38039215686274507888 0.7058823529411765163 1.0"/>
		</material>
	</visual>
	<collision>
		<origin xyz="-0.0090000000000001745271 -0.0059999999999999636957 -0.0047499999999967013053" rpy="-1.5707963267948961139 8.3887279286788947566e-17 7.7658881428786524538e-20" />
		<geometry>
			<mesh filename="meshes/d1_urdf_mk_5_2.stl"/>
		</geometry>
	</collision>
	<inertial>
		<origin xyz="0 0 0" rpy="0 0 0"/>
		<mass value="0" />
		<inertia ixx="0" ixy="0"  ixz="0" iyy="0" iyz="0" izz="0" />
	</inertial>
</link>

<joint name="Rmiddle_34" type="revolute">
	<origin xyz="-0.02499999999999980016 -7.1123662515049090871e-16 -0.00050000000000011146639" rpy="-2.4979097638864784731e-17 1.0181015242615938875e-15 3.1302681449011877956e-17" />
	<parent link="part_1_10" />
	<child link="d1_urdf_mk_5_2" />
	<axis xyz="0 0 1"/>
	<limit effort="100" velocity="20" lower="0" upper="1.570796326794896558"/>
	<joint_properties friction="0.0"/>
</joint>

<joint name="Rmiddle_23" type="revolute">
	<origin xyz="-0.038000000000000921929 0.00075000000000003883005 -0.00074999999999986188826" rpy="2.4910612235077419823e-17 2.8843990411412831013e-16 -2.5694392889677114988e-17" />
	<parent link="part_1_5" />
	<child link="part_1_10" />
	<axis xyz="0 0 1"/>
	<limit effort="100" velocity="20" lower="0" upper="1.570796326794896558"/>
	<joint_properties friction="0.0"/>
</joint>

<joint name="Rmiddle_12" type="revolute">
	<origin xyz="-0.014749999999999957589 -0.0059999999999998943068 -0.0095000000000000639488" rpy="1.570796326794896558 -0.0021726770825793960407 -4.515507755625627385e-17" />
	<parent link="part_1_4" />
	<child link="part_1_5" />
	<axis xyz="0 0 1"/>
	<limit effort="100" velocity="20" lower="0" upper="1.570796326794896558"/>
	<joint_properties friction="0.0"/>
</joint>

<joint name="Rmiddle_01" type="revolute">
	<origin xyz="0.27022215162266066679 0.22117640734292387528 0.029259033846879119178" rpy="-6.3141689325766752614e-17 3.7244852903325913121e-16 -1.570796326794896558" />
	<parent link="right_forearm_and_palm_subassembly" />
	<child link="part_1_4" />
	<axis xyz="0 0 1"/>
	<limit effort="100" velocity="20" lower="-0.29670597283903604735" upper="0.29670597283903604735"/>
	<joint_properties friction="0.0"/>
</joint>

<link name="part_1_3">
	<visual>
		<origin xyz="-0.0049999999999999489297 0 -0.01831458565330660801" rpy="-1.4485681946286607074e-16 8.5979375613828726593e-16 -3.0106677737340463314e-18" />
		<geometry>
			<mesh filename="meshes/part_1_3.stl"/>
		</geometry>
		<material name="part_1_3_material">
			<color rgba="0.64705882352941179736 0.64705882352941179736 0.64705882352941179736 1.0"/>
		</material>
	</visual>
	<collision>
		<origin xyz="-0.0049999999999999489297 0 -0.01831458565330660801" rpy="-1.4485681946286607074e-16 8.5979375613828726593e-16 -3.0106677737340463314e-18" />
		<geometry>
			<mesh filename="meshes/part_1_3.stl"/>
		</geometry>
	</collision>
	<inertial>
		<origin xyz="0 0 0" rpy="0 0 0"/>
		<mass value="0" />
		<inertia ixx="0" ixy="0"  ixz="0" iyy="0" iyz="0" izz="0" />
	</inertial>
</link>

<link name="part_1_8">
	<visual>
		<origin xyz="-0.028552407289709647031 -0.007858976793889109122 -0.006000000000005112355" rpy="-1.570796326794896558 9.4390089060149465844e-16 3.5699684555961423107e-19" />
		<geometry>
			<mesh filename="meshes/part_1_8.stl"/>
		</geometry>
		<material name="part_1_8_material">
			<color rgba="0.61568627450980395466 0.81176470588235294379 0.92941176470588238168 1.0"/>
		</material>
	</visual>
	<collision>
		<origin xyz="-0.028552407289709647031 -0.007858976793889109122 -0.006000000000005112355" rpy="-1.570796326794896558 9.4390089060149465844e-16 3.5699684555961423107e-19" />
		<geometry>
			<mesh filename="meshes/part_1_8.stl"/>
		</geometry>
	</collision>
	<inertial>
		<origin xyz="0 0 0" rpy="0 0 0"/>
		<mass value="0" />
		<inertia ixx="0" ixy="0"  ixz="0" iyy="0" iyz="0" izz="0" />
	</inertial>
</link>

<link name="part_1_9">
	<visual>
		<origin xyz="-0.017524803018038770386 -0.0071295923980055943281 -0.005250000000000198952" rpy="-1.5707963267948970021 5.0919341028009480114e-16 -3.32444761789142605e-19" />
		<geometry>
			<mesh filename="meshes/part_1_9.stl"/>
		</geometry>
		<material name="part_1_9_material">
			<color rgba="0.91764705882352937127 0.91764705882352937127 0.91764705882352937127 1.0"/>
		</material>
	</visual>
	<collision>
		<origin xyz="-0.017524803018038770386 -0.0071295923980055943281 -0.005250000000000198952" rpy="-1.5707963267948970021 5.0919341028009480114e-16 -3.32444761789142605e-19" />
		<geometry>
			<mesh filename="meshes/part_1_9.stl"/>
		</geometry>
	</collision>
	<inertial>
		<origin xyz="0 0 0" rpy="0 0 0"/>
		<mass value="0" />
		<inertia ixx="0" ixy="0"  ixz="0" iyy="0" iyz="0" izz="0" />
	</inertial>
</link>

<link name="d1_urdf_mk_5_3">
	<visual>
		<origin xyz="-0.0090000000000002300382 -0.0059999999999999654304 -0.0047499999999967568165" rpy="-1.5707963267948961139 8.0525507663762797458e-17 -4.0838259419348788813e-19" />
		<geometry>
			<mesh filename="meshes/d1_urdf_mk_5_3.stl"/>
		</geometry>
		<material name="d1_urdf_mk_5_3_material">
			<color rgba="0.2313725490196078538 0.38039215686274507888 0.7058823529411765163 1.0"/>
		</material>
	</visual>
	<collision>
		<origin xyz="-0.0090000000000002300382 -0.0059999999999999654304 -0.0047499999999967568165" rpy="-1.5707963267948961139 8.0525507663762797458e-17 -4.0838259419348788813e-19" />
		<geometry>
			<mesh filename="meshes/d1_urdf_mk_5_3.stl"/>
		</geometry>
	</collision>
	<inertial>
		<origin xyz="0 0 0" rpy="0 0 0"/>
		<mass value="0" />
		<inertia ixx="0" ixy="0"  ixz="0" iyy="0" iyz="0" izz="0" />
	</inertial>
</link>

<joint name="Rindex_34" type="revolute">
	<origin xyz="-0.024999999999999911182 -7.0082828429463006614e-16 0.00025000000000013899992" rpy="-1.0930799161611205032e-19 -3.0429053379121260856e-17 5.5759055658801912845e-14" />
	<parent link="part_1_9" />
	<child link="d1_urdf_mk_5_3" />
	<axis xyz="0 0 1"/>
	<limit effort="100" velocity="20" lower="0" upper="1.570796326794896558"/>
	<joint_properties friction="0.0"/>
</joint>

<joint name="Rindex_23" type="revolute">
	<origin xyz="-0.038000000000001032952 0.00075000000000002495226 1.1102230246251565404e-16" rpy="-4.3192083050426755398e-15 -1.3091345168015273789e-15 -4.059328245564483734e-14" />
	<parent link="part_1_8" />
	<child link="part_1_9" />
	<axis xyz="0 0 1"/>
	<limit effort="100" velocity="20" lower="0" upper="1.570796326794896558"/>
	<joint_properties friction="0.0"/>
</joint>

<joint name="Rindex_12" type="revolute">
	<origin xyz="-0.014749999999999957589 -0.0060000000000002273737 -0.0093145856533065340965" rpy="1.5707963267948945596 -0.0030671090189098395608 8.3436012011691075534e-16" />
	<parent link="part_1_3" />
	<child link="part_1_8" />
	<axis xyz="0 0 1"/>
	<limit effort="100" velocity="20" lower="0" upper="1.570796326794896558"/>
	<joint_properties friction="0.0"/>
</joint>

<joint name="Rindex_01" type="revolute">
	<origin xyz="0.24859938690798402683 0.21811973915038307403 0.026259033846879248353" rpy="8.6736173788093875172e-17 4.9280035934342335256e-16 -1.500983156715123501" />
	<parent link="right_forearm_and_palm_subassembly" />
	<child link="part_1_3" />
	<axis xyz="0 0 1"/>
	<limit effort="100" velocity="20" lower="-0.29670597283903604735" upper="0.29670597283903604735"/>
	<joint_properties friction="0.0"/>
</joint>

<link name="part_1_13">
	<visual>
		<origin xyz="-0.0050000000000000044409 0 0.00062867965644042289597" rpy="-3.141592653589793116 2.2259065974197463063e-17 -3.1349458403680724895e-17" />
		<geometry>
			<mesh filename="meshes/part_1_13.stl"/>
		</geometry>
		<material name="part_1_13_material">
			<color rgba="0.2313725490196078538 0.38039215686274507888 0.7058823529411765163 1.0"/>
		</material>
	</visual>
	<collision>
		<origin xyz="-0.0050000000000000044409 0 0.00062867965644042289597" rpy="-3.141592653589793116 2.2259065974197463063e-17 -3.1349458403680724895e-17" />
		<geometry>
			<mesh filename="meshes/part_1_13.stl"/>
		</geometry>
	</collision>
	<inertial>
		<origin xyz="0 0 0" rpy="0 0 0"/>
		<mass value="0" />
		<inertia ixx="0" ixy="0"  ixz="0" iyy="0" iyz="0" izz="0" />
	</inertial>
</link>

<link name="part_1_14">
	<visual>
		<origin xyz="-0.029277356236810214707 -0.0078134566939175309486 -0.0067500000000003251843" rpy="-1.5707963267948961139 3.9585767009635685762e-16 3.162545811456038734e-17" />
		<geometry>
			<mesh filename="meshes/part_1_14.stl"/>
		</geometry>
		<material name="part_1_14_material">
			<color rgba="0.64705882352941179736 0.64705882352941179736 0.64705882352941179736 1.0"/>
		</material>
	</visual>
	<collision>
		<origin xyz="-0.029277356236810214707 -0.0078134566939175309486 -0.0067500000000003251843" rpy="-1.5707963267948961139 3.9585767009635685762e-16 3.162545811456038734e-17" />
		<geometry>
			<mesh filename="meshes/part_1_14.stl"/>
		</geometry>
	</collision>
	<inertial>
		<origin xyz="0 0 0" rpy="0 0 0"/>
		<mass value="0" />
		<inertia ixx="0" ixy="0"  ixz="0" iyy="0" iyz="0" izz="0" />
	</inertial>
</link>

<link name="part_1_15">
	<visual>
		<origin xyz="-0.017524803018038631608 -0.0071295923980052022806 -0.0062499999999999639178" rpy="-1.57079632679489678 5.4727023498301658739e-16 -6.7447808807866834097e-18" />
		<geometry>
			<mesh filename="meshes/part_1_15.stl"/>
		</geometry>
		<material name="part_1_15_material">
			<color rgba="0.61568627450980395466 0.81176470588235294379 0.92941176470588238168 1.0"/>
		</material>
	</visual>
	<collision>
		<origin xyz="-0.017524803018038631608 -0.0071295923980052022806 -0.0062499999999999639178" rpy="-1.57079632679489678 5.4727023498301658739e-16 -6.7447808807866834097e-18" />
		<geometry>
			<mesh filename="meshes/part_1_15.stl"/>
		</geometry>
	</collision>
	<inertial>
		<origin xyz="0 0 0" rpy="0 0 0"/>
		<mass value="0" />
		<inertia ixx="0" ixy="0"  ixz="0" iyy="0" iyz="0" izz="0" />
	</inertial>
</link>

<link name="part_1_16">
	<visual>
		<origin xyz="-0.0089999999999997512545 -0.0060000000000001163514 -0.0057500000000044876325" rpy="-1.570796326794896558 2.7383719824292942009e-16 1.1406760560585945855e-17" />
		<geometry>
			<mesh filename="meshes/part_1_16.stl"/>
		</geometry>
		<material name="part_1_16_material">
			<color rgba="0.49803921568627451677 0.49803921568627451677 0.49803921568627451677 1.0"/>
		</material>
	</visual>
	<collision>
		<origin xyz="-0.0089999999999997512545 -0.0060000000000001163514 -0.0057500000000044876325" rpy="-1.570796326794896558 2.7383719824292942009e-16 1.1406760560585945855e-17" />
		<geometry>
			<mesh filename="meshes/part_1_16.stl"/>
		</geometry>
	</collision>
	<inertial>
	<origin xyz="0 0 0" rpy="0 0 0"/>
	<mass value="0" />
	<inertia ixx="0" ixy="0"  ixz="0" iyy="0" iyz="0" izz="0" />
	</inertial>
</link>

<joint name="Rthumb_34" type="revolute">
	<origin xyz="-0.024999999999999703015 -4.4408920985006261617e-16 0.0010000000000001119105" rpy="7.190853025056170776e-15 1.5881675766873069476e-14 -1.0527834464743926316e-13" />
	<parent link="part_1_15" />
	<child link="part_1_16" />
	<axis xyz="0 0 1"/>
	<limit effort="100" velocity="20" lower="0" upper="1.570796326794896558"/>
	<joint_properties friction="0.0"/>
</joint>

<joint name="Rthumb_23" type="revolute">
	<origin xyz="-0.038000000000000797029 0.00075000000000041699977 -0.00050000000000000044409" rpy="-2.3414011226030129463e-15 -3.6553634511977772008e-14 2.2018853588283082281e-14" />
	<parent link="part_1_14" />
	<child link="part_1_15" />
	<axis xyz="0 0 1"/>
	<limit effort="100" velocity="20" lower="0" upper="1.570796326794896558"/>
	<joint_properties friction="0.0"/>
</joint>

<joint name="Rthumb_12" type="revolute">
	<origin xyz="-0.014749999999999971467 0.006750000000000019873 -0.0077499999999999236167" rpy="-1.57079632679489678 4.8576610287913724728e-06 -1.1395153954890297715e-14" />
	<parent link="part_1_13" />
	<child link="part_1_14" />
	<axis xyz="0 0 1"/>
	<limit effort="100" velocity="20" lower="0" upper="1.570796326794896558"/>
	<joint_properties friction="0.0"/>
</joint>

<joint name="Rthumb_01" type="revolute">
	<origin xyz="0.25975933290346764348 0.17603301569461013432 -0.0045818118468336655608" rpy="-2.0752759914175813449 -1.0057357117290099957 3.3224635203616947282e-14" />
	<parent link="right_forearm_and_palm_subassembly" />
	<child link="part_1_13" />
	<axis xyz="0 0 1"/>
	<limit effort="100" velocity="20" lower="-0.64577182323790194296" upper="0.64577182323790194296"/>
	<joint_properties friction="0.0"/>
</joint>


</robot>
