<?xml version="1.0" ?>
<!-- =================================================================================== -->
<!-- |    This document was autogenerated by xacro from ../processed/ABB/IRB6600/xacro/irb6600.xacro | -->
<!-- |    EDITING THIS FILE BY HAND IS NOT RECOMMENDED                                 | -->
<!-- =================================================================================== -->
<robot xmlns:xacro="http://ros.org/wiki/xacro" name="abb_irb6600_225_255">
  <link name="base_link">
    <visual>
      <origin xyz="0 0 0" rpy="0 0 0"/>
      <geometry>
        <mesh filename="package://abb_irb6600_support/meshes/irb6600_225_255/visual/base_link.dae"/>
      </geometry>
    </visual>
    <collision>
      <origin xyz="0 0 0" rpy="0 0 0"/>
      <geometry>
        <mesh filename="package://abb_irb6600_support/meshes/irb6600_225_255/collision/base_link.stl"/>
      </geometry>
      <material name="">
        <color rgba="1 1 0 1"/>
      </material>
    </collision>
  </link>
  <link name="link_1">
    <visual>
      <origin xyz="0 0 0" rpy="0 0 0"/>
      <geometry>
        <mesh filename="package://abb_irb6600_support/meshes/irb6600_225_255/visual/link_1.dae"/>
      </geometry>
    </visual>
    <collision>
      <origin xyz="0 0 0" rpy="0 0 0"/>
      <geometry>
        <mesh filename="package://abb_irb6600_support/meshes/irb6600_225_255/collision/link_1.stl"/>
      </geometry>
      <material name="">
        <color rgba="1 1 0 1"/>
      </material>
    </collision>
  </link>
  <link name="link_2">
    <visual>
      <origin xyz="0 0 0" rpy="0 0 0"/>
      <geometry>
        <mesh filename="package://abb_irb6600_support/meshes/irb6600_225_255/visual/link_2.dae"/>
      </geometry>
    </visual>
    <collision>
      <origin xyz="0 0 0" rpy="0 0 0"/>
      <geometry>
        <mesh filename="package://abb_irb6600_support/meshes/irb6600_225_255/collision/link_2.stl"/>
      </geometry>
      <material name="">
        <color rgba="1 1 0 1"/>
      </material>
    </collision>
  </link>
  <link name="link_3">
    <visual>
      <origin xyz="0 0 0" rpy="0 0 0"/>
      <geometry>
        <mesh filename="package://abb_irb6600_support/meshes/irb6600_225_255/visual/link_3.dae"/>
      </geometry>
    </visual>
    <collision>
      <origin xyz="0 0 0" rpy="0 0 0"/>
      <geometry>
        <mesh filename="package://abb_irb6600_support/meshes/irb6600_225_255/collision/link_3.stl"/>
      </geometry>
      <material name="">
        <color rgba="1 1 0 1"/>
      </material>
    </collision>
  </link>
  <link name="link_4">
    <visual>
      <origin xyz="0 0 0" rpy="0 0 0"/>
      <geometry>
        <mesh filename="package://abb_irb6600_support/meshes/irb6600_225_255/visual/link_4.dae"/>
      </geometry>
    </visual>
    <collision>
      <origin xyz="0 0 0" rpy="0 0 0"/>
      <geometry>
        <mesh filename="package://abb_irb6600_support/meshes/irb6600_225_255/collision/link_4.stl"/>
      </geometry>
      <material name="">
        <color rgba="1 1 0 1"/>
      </material>
    </collision>
  </link>
  <link name="link_5">
    <visual>
      <origin xyz="0 0 0" rpy="0 0 0"/>
      <geometry>
        <mesh filename="package://abb_irb6600_support/meshes/irb6600_225_255/visual/link_5.dae"/>
      </geometry>
    </visual>
    <collision>
      <origin xyz="0 0 0" rpy="0 0 0"/>
      <geometry>
        <mesh filename="package://abb_irb6600_support/meshes/irb6600_225_255/collision/link_5.stl"/>
      </geometry>
      <material name="">
        <color rgba="1 1 0 1"/>
      </material>
    </collision>
  </link>
  <link name="link_6">
    <visual>
      <origin xyz="0 0 0" rpy="0 0 0"/>
      <geometry>
        <mesh filename="package://abb_irb6600_support/meshes/irb6600_225_255/visual/link_6.dae"/>
      </geometry>
    </visual>
    <collision>
      <origin xyz="0 0 0" rpy="0 0 0"/>
      <geometry>
        <mesh filename="package://abb_irb6600_support/meshes/irb6600_225_255/collision/link_6.stl"/>
      </geometry>
      <material name="">
        <color rgba="1 1 0 1"/>
      </material>
    </collision>
  </link>
  <link name="tool0"/>
  <link name="link_cylinder">
    <visual name="visual">
      <geometry>
        <mesh filename="package://abb_irb6600_support/meshes/irb6600_225_255/visual/link_cylinder.dae"/>
      </geometry>
    </visual>
    <collision name="collision">
      <geometry>
        <mesh filename="package://abb_irb6600_support/meshes/irb6600_225_255/collision/link_cylinder.stl"/>
      </geometry>
      <material name="">
        <color rgba="1 1 0 1"/>
      </material>
    </collision>
  </link>
  <link name="link_piston">
    <visual name="visual">
      <geometry>
        <mesh filename="package://abb_irb6600_support/meshes/irb6600_225_255/visual/link_piston.dae"/>
      </geometry>
    </visual>
    <collision name="collision">
      <geometry>
        <mesh filename="package://abb_irb6600_support/meshes/irb6600_225_255/collision/link_piston.stl"/>
      </geometry>
      <material name="">
        <color rgba="1 1 0 1"/>
      </material>
    </collision>
    <bow name="arm" functions="goto point"/>
  </link>
  <joint name="joint_1" type="revolute">
    <origin xyz="0 0 0.780" rpy="0 0 0"/>
    <parent link="base_link"/>
    <child link="link_1"/>
    <axis xyz="0 0 1"/>
    <limit lower="-3.14159265" upper="3.14159265" effort="0" velocity="1.74532925"/>
  </joint>
  <joint name="joint_2" type="revolute">
    <origin xyz="0.320 0 0" rpy="0 0 0"/>
    <parent link="link_1"/>
    <child link="link_2"/>
    <axis xyz="0 1 0"/>
    <limit lower="-1.13446401" upper="1.3962634" effort="0" velocity="1.57079633"/>
  </joint>
  <joint name="joint_3" type="revolute">
    <origin xyz="0 0 1.075" rpy="0 0 0"/>
    <parent link="link_2"/>
    <child link="link_3"/>
    <axis xyz="0 1 0"/>
    <limit lower="-3.14159265" upper="1.04719755" effort="0" velocity="1.57079633"/>
  </joint>
  <joint name="joint_4" type="revolute">
    <origin xyz="0 0 0.2" rpy="0 0 0"/>
    <parent link="link_3"/>
    <child link="link_4"/>
    <axis xyz="1 0 0"/>
    <limit lower="-5.23598776" upper="5.23598776" effort="0" velocity="2.61799388"/>
  </joint>
  <joint name="joint_5" type="revolute">
    <origin xyz="1.142 0 0" rpy="0 0 0"/>
    <parent link="link_4"/>
    <child link="link_5"/>
    <axis xyz="0 1 0"/>
    <limit lower="-2.0943951" upper="2.0943951" effort="0" velocity="2.0943951"/>
  </joint>
  <joint name="joint_6" type="revolute">
    <origin xyz="0.2 0 0" rpy="0 0 0"/>
    <parent link="link_5"/>
    <child link="link_6"/>
    <axis xyz="1 0 0"/>
    <limit lower="-5.23598776" upper="5.23598776" effort="0" velocity="3.31612558"/>
  </joint>
  <joint name="joint_6-tool0" type="fixed">
    <origin xyz="0 0 0" rpy="0 1.57079632679 0"/>
    <parent link="link_6"/>
    <child link="tool0"/>
  </joint>
  <joint type="continuous" name="joint_cylinder">
    <origin xyz="-0.286 0 -0.13" rpy="0 0 0"/>
    <axis xyz="0 1 0"/>
    <parent link="link_1"/>
    <child link="link_cylinder"/>
    <mimic joint="joint_2" multiplier="-0.165"/>
  </joint>
  <joint type="continuous" name="joint_piston">
    <origin xyz="-0.137 0 -0.025" rpy="0 0 0"/>
    <axis xyz="0 1 0"/>
    <parent link="link_2"/>
    <child link="link_piston"/>
    <mimic joint="joint_2" multiplier="-1.165"/>
  </joint>
  <link name="base"/>
  <joint name="base_link-base" type="fixed">
    <origin xyz="0 0 0" rpy="0 0 0"/>
    <parent link="base_link"/>
    <child link="base"/>
  </joint>
</robot>
