<robot name="Artus3D_LeftHand">

<link name= "base_link"/>

<joint name="virtual" type="fixed">
<origin xyz="0 0 0" rpy="1.67 0 0"/>
<parent link="base_link"/>
<child link="left_forearm_and_palm_subassembly"/>
</joint>

<link name="left_forearm_and_palm_subassembly">
<visual>
<origin xyz="-0.082104404950782056138 0.15253711492388200011 0.021138679244508587485" rpy="0 -0 3.141592653589793116" />
<geometry>
<mesh filename="meshes/l_pinky_side_forearm_cover.stl"/>
</geometry>
<material name="l_pinky_side_forearm_cover_material">
<color rgba="0.91764705882352937127 0.91764705882352937127 0.91764705882352937127 1.0"/>
</material>
</visual>
<collision>
<origin xyz="-0.082104404950782056138 0.15253711492388200011 0.021138679244508587485" rpy="0 -0 3.141592653589793116" />
<geometry>
<mesh filename="meshes/l_pinky_side_forearm_cover.stl"/>
</geometry>
</collision>
<visual>
<origin xyz="-0.12613917412173653032 0.099952601442010749477 -0.076066444809012298545" rpy="-1.066316662172226204 -1.0057357117289822401 -3.1415926535897922278" />
<geometry>
<mesh filename="meshes/part_1.stl"/>
</geometry>
<material name="part_1_material">
<color rgba="0.76862745098039220171 0.88627450980392152857 0.95294117647058818044 1.0"/>
</material>
</visual>
<collision>
<origin xyz="-0.12613917412173653032 0.099952601442010749477 -0.076066444809012298545" rpy="-1.066316662172226204 -1.0057357117289822401 -3.1415926535897922278" />
<geometry>
<mesh filename="meshes/part_1.stl"/>
</geometry>
</collision>
<visual>
<origin xyz="-0.082104404950782056138 0.15253711492388200011 0.021138679244508587485" rpy="0 -0 3.141592653589793116" />
<geometry>
<mesh filename="meshes/l_forearm_back_cover.stl"/>
</geometry>
<material name="l_forearm_back_cover_material">
<color rgba="0.26274509803921569651 0.28235294117647058432 0.30196078431372547213 1.0"/>
</material>
</visual>
<collision>
<origin xyz="-0.082104404950782056138 0.15253711492388200011 0.021138679244508587485" rpy="0 -0 3.141592653589793116" />
<geometry>
<mesh filename="meshes/l_forearm_back_cover.stl"/>
</geometry>
</collision>
<visual>
<origin xyz="-0.18190440495078197269 0.23028711492388134752 0.012488679244508716151" rpy="-1.613736433077298981e-16 1.3010426069826057152e-15 -1.5707963267948970021" />
<geometry>
<mesh filename="meshes/part_1.stl"/>
</geometry>
<material name="part_1_material">
<color rgba="0.98039215686274505668 0.71372549019607844922 0.0039215686274509803377 1.0"/>
</material>
</visual>
<collision>
<origin xyz="-0.18190440495078197269 0.23028711492388134752 0.012488679244508716151" rpy="-1.613736433077298981e-16 1.3010426069826057152e-15 -1.5707963267948970021" />
<geometry>
<mesh filename="meshes/part_1.stl"/>
</geometry>
</collision>
<visual>
<origin xyz="-0.15485807440249962919 0.22704105163904281239 0.0094886792445087134867" rpy="-2.4771671902375037252e-16 1.3489052410272972017e-15 -1.6406094968746700591" />
<geometry>
<mesh filename="meshes/part_1.stl"/>
</geometry>
<material name="part_1_material">
<color rgba="0.98039215686274505668 0.71372549019607844922 0.0039215686274509803377 1.0"/>
</material>
</visual>
<collision>
<origin xyz="-0.15485807440249962919 0.22704105163904281239 0.0094886792445087134867" rpy="-2.4771671902375037252e-16 1.3489052410272972017e-15 -1.6406094968746700591" />
<geometry>
<mesh filename="meshes/part_1.stl"/>
</geometry>
</collision>
<visual>
<origin xyz="-0.1979044049507819869 0.15253711492388208337 0.021138679244508601363" rpy="2.3526207937657885182e-32 -1.6137364330773172235e-16 3.141592653589793116" />
<geometry>
<mesh filename="meshes/forearm_front_heat_sink.stl"/>
</geometry>
<material name="forearm_front_heat_sink_material">
<color rgba="0.91764705882352937127 0.91764705882352937127 0.91764705882352937127 1.0"/>
</material>
</visual>
<collision>
<origin xyz="-0.1979044049507819869 0.15253711492388208337 0.021138679244508601363" rpy="2.3526207937657885182e-32 -1.6137364330773172235e-16 3.141592653589793116" />
<geometry>
<mesh filename="meshes/forearm_front_heat_sink.stl"/>
</geometry>
</collision>
<visual>
<origin xyz="-0.082104404950782056138 0.15253711492388200011 0.021138679244508587485" rpy="0 -0 3.141592653589793116" />
<geometry>
<mesh filename="meshes/l_thumb_side_forearm_cover.stl"/>
</geometry>
<material name="l_thumb_side_forearm_cover_material">
<color rgba="0.91764705882352937127 0.91764705882352937127 0.91764705882352937127 1.0"/>
</material>
</visual>
<collision>
<origin xyz="-0.082104404950782056138 0.15253711492388200011 0.021138679244508587485" rpy="0 -0 3.141592653589793116" />
<geometry>
<mesh filename="meshes/l_thumb_side_forearm_cover.stl"/>
</geometry>
</collision>
<visual>
<origin xyz="-0.22122267743413071006 -0.054184990877222768968 0.021138679244508594424" rpy="0 -1.4313686678903165613e-16 -3.05311331771919084e-16" />
<geometry>
<mesh filename="meshes/part_3.stl"/>
</geometry>
<material name="part_3_material">
<color rgba="0.2313725490196078538 0.38039215686274507888 0.7058823529411765163 1.0"/>
</material>
</visual>
<collision>
<origin xyz="-0.22122267743413071006 -0.054184990877222768968 0.021138679244508594424" rpy="0 -1.4313686678903165613e-16 -3.05311331771919084e-16" />
<geometry>
<mesh filename="meshes/part_3.stl"/>
</geometry>
</collision>
<visual>
<origin xyz="-0.11649749168457114445 0.14796341800011014733 0.021138679244508580546" rpy="-1.9428902930940251783e-16 -5.5511151231257738274e-16 3.0019663134302465579" />
<geometry>
<mesh filename="meshes/left_palm_grip.stl"/>
</geometry>
<material name="left_palm_grip_material">
<color rgba="1 1 1 1.0"/>
</material>
</visual>
<collision>
<origin xyz="-0.11649749168457114445 0.14796341800011014733 0.021138679244508580546" rpy="-1.9428902930940251783e-16 -5.5511151231257738274e-16 3.0019663134302465579" />
<geometry>
<mesh filename="meshes/left_palm_grip.stl"/>
</geometry>
</collision>
<visual>
<origin xyz="-0.22122267743413082108 -0.054184990877223102035 0.021138679244508601363" rpy="-9.5531463282139081189e-34 -1.4313686678903170543e-16 -3.0327332911414330937e-16" />
<geometry>
<mesh filename="meshes/part_4.stl"/>
</geometry>
<material name="part_4_material">
<color rgba="0.76862745098039220171 0.88627450980392152857 0.95294117647058818044 1.0"/>
</material>
</visual>
<collision>
<origin xyz="-0.22122267743413082108 -0.054184990877223102035 0.021138679244508601363" rpy="-9.5531463282139081189e-34 -1.4313686678903170543e-16 -3.0327332911414330937e-16" />
<geometry>
<mesh filename="meshes/part_4.stl"/>
</geometry>
</collision>
<visual>
<origin xyz="-0.20869274708302831822 0.22565323001338080666 0.0094886792445087447118" rpy="-7.4244371424405918453e-17 1.2489542737373337839e-15 -1.5009831567151239451" />
<geometry>
<mesh filename="meshes/part_1.stl"/>
</geometry>
<material name="part_1_material">
<color rgba="0.98039215686274505668 0.71372549019607844922 0.0039215686274509803377 1.0"/>
</material>
</visual>
<collision>
<origin xyz="-0.20869274708302831822 0.22565323001338080666 0.0094886792445087447118" rpy="-7.4244371424405918453e-17 1.2489542737373337839e-15 -1.5009831567151239451" />
<geometry>
<mesh filename="meshes/part_1.stl"/>
</geometry>
</collision>
<visual>
<origin xyz="-0.082104404950782056138 0.15253711492388200011 0.021138679244508587485" rpy="0 -0 3.141592653589793116" />
<geometry>
<mesh filename="meshes/dim_part.stl"/>
</geometry>
<material name="dim_part_material">
<color rgba="0.91764705882352937127 0.91764705882352937127 0.91764705882352937127 1.0"/>
</material>
</visual>
<collision>
<origin xyz="-0.082104404950782056138 0.15253711492388200011 0.021138679244508587485" rpy="0 -0 3.141592653589793116" />
<geometry>
<mesh filename="meshes/dim_part.stl"/>
</geometry>
</collision>
<visual>
<origin xyz="-0.082104404950782056138 0.15253711492388200011 0.021138679244508587485" rpy="0 -0 3.141592653589793116" />
<geometry>
<mesh filename="meshes/l_forearm_front_cover.stl"/>
</geometry>
<material name="l_forearm_front_cover_material">
<color rgba="0.26274509803921569651 0.28235294117647058432 0.30196078431372547213 1.0"/>
</material>
</visual>
<collision>
<origin xyz="-0.082104404950782056138 0.15253711492388200011 0.021138679244508587485" rpy="0 -0 3.141592653589793116" />
<geometry>
<mesh filename="meshes/l_forearm_front_cover.stl"/>
</geometry>
</collision>
<visual>
<origin xyz="-0.23319841554313755494 0.21774623796487163618 0.006488679244508693475" rpy="1.3301558956251336654e-17 1.1921244715021859299e-15 -1.4486232791552937638" />
<geometry>
<mesh filename="meshes/part_1.stl"/>
</geometry>
<material name="part_1_material">
<color rgba="0.98039215686274505668 0.71372549019607844922 0.0039215686274509803377 1.0"/>
</material>
</visual>
<collision>
<origin xyz="-0.23319841554313755494 0.21774623796487163618 0.006488679244508693475" rpy="1.3301558956251336654e-17 1.1921244715021859299e-15 -1.4486232791552937638" />
<geometry>
<mesh filename="meshes/part_1.stl"/>
</geometry>
</collision>
<inertial>
<origin xyz="-0.18997784060482203472 0.0077244037879468695554 0.0055030076977804608801" rpy="0 0 0"/>
<mass value="0.16052153521062662023" />
<inertia ixx="0.00021189020045041657937" ixy="-7.6447420158413642781e-07"  ixz="-6.4860598027749192247e-07" iyy="0.0001554029046737161082" iyz="7.3079137388787183491e-06" izz="0.00021989509324150252612" />
</inertial>
</link>

<link name="part_1_3">
<visual>
<origin xyz="-0.0049999999999999766853 2.7755575615628913511e-17 -0.018500000000000103167" rpy="-1.4485681946286607074e-16 8.5979375613828716732e-16 2.5039820783697988254e-19" />
<geometry>
<mesh filename="meshes/part_1_3.stl"/>
</geometry>
<material name="part_1_3_material">
<color rgba="0.64705882352941179736 0.64705882352941179736 0.64705882352941179736 1.0"/>
</material>
</visual>
<collision>
<origin xyz="-0.0049999999999999766853 2.7755575615628913511e-17 -0.018500000000000103167" rpy="-1.4485681946286607074e-16 8.5979375613828716732e-16 2.5039820783697988254e-19" />
<geometry>
<mesh filename="meshes/part_1_3.stl"/>
</geometry>
</collision>
<inertial>
<origin xyz="0 0 0" rpy="0 0 0"/>
<mass value="0" />
<inertia ixx="0" ixy="0"  ixz="0" iyy="0" iyz="0" izz="0" />
</inertial>
</link>

<link name="part_1_8">
<visual>
<origin xyz="-0.028552407289709647031 -0.0078589767938891941235 -0.006000000000005112355" rpy="-1.570796326794896558 9.2431948996916529366e-16 5.9666104232661371964e-32" />
<geometry>
<mesh filename="meshes/part_1_8.stl"/>
</geometry>
<material name="part_1_8_material">
<color rgba="0.61568627450980395466 0.81176470588235294379 0.92941176470588238168 1.0"/>
</material>
</visual>
<collision>
<origin xyz="-0.028552407289709647031 -0.0078589767938891941235 -0.006000000000005112355" rpy="-1.570796326794896558 9.2431948996916529366e-16 5.9666104232661371964e-32" />
<geometry>
<mesh filename="meshes/part_1_8.stl"/>
</geometry>
</collision>
<inertial>
<origin xyz="0 0 0" rpy="0 0 0"/>
<mass value="0" />
<inertia ixx="0" ixy="0"  ixz="0" iyy="0" iyz="0" izz="0" />
</inertial>
</link>

<link name="part_1_9">
<visual>
<origin xyz="-0.017524803018038770386 -0.0071295923980055951955 -0.005250000000000198952" rpy="-1.5707963267948970021 5.0594306907981429674e-16 -1.1115609025989811146e-32" />
<geometry>
<mesh filename="meshes/part_1_9.stl"/>
</geometry>
<material name="part_1_9_material">
<color rgba="0.91764705882352937127 0.91764705882352937127 0.91764705882352937127 1.0"/>
</material>
</visual>
<collision>
<origin xyz="-0.017524803018038770386 -0.0071295923980055951955 -0.005250000000000198952" rpy="-1.5707963267948970021 5.0594306907981429674e-16 -1.1115609025989811146e-32" />
<geometry>
<mesh filename="meshes/part_1_9.stl"/>
</geometry>
</collision>
<inertial>
<origin xyz="0 0 0" rpy="0 0 0"/>
<mass value="0" />
<inertia ixx="0" ixy="0"  ixz="0" iyy="0" iyz="0" izz="0" />
</inertial>
</link>

<link name="d1_urdf_mk_5_3">
<visual>
<origin xyz="-0.0090000000000002022826 -0.0060000000000000001249 -0.0047499999999967290609" rpy="-1.5707963267948961139 8.3307334127440364476e-17 1.6305527293976841051e-32" />
<geometry>
<mesh filename="meshes/d1_urdf_mk_5_3.stl"/>
</geometry>
<material name="d1_urdf_mk_5_3_material">
<color rgba="0.2313725490196078538 0.38039215686274507888 0.7058823529411765163 1.0"/>
</material>
</visual>
<collision>
<origin xyz="-0.0090000000000002022826 -0.0060000000000000001249 -0.0047499999999967290609" rpy="-1.5707963267948961139 8.3307334127440364476e-17 1.6305527293976841051e-32" />
<geometry>
<mesh filename="meshes/d1_urdf_mk_5_3.stl"/>
</geometry>
</collision>
<inertial>
<origin xyz="0 0 0" rpy="0 0 0"/>
<mass value="0" />
<inertia ixx="0" ixy="0"  ixz="0" iyy="0" iyz="0" izz="0" />
</inertial>
</link>

<joint name="Lindex_34" type="revolute">
<origin xyz="-0.024999999999999855671 -6.9735883734267645195e-16 -0.00049999999999991717736" rpy="2.5304377465003366302e-17 1.3411311184299451363e-17 -6.1394159135529489301e-17" />
<parent link="part_1_9" />
<child link="d1_urdf_mk_5_3" />
<axis xyz="0 0 1"/>
<limit effort="100" velocity="20" lower="0" upper="1.570796326794896558"/>
<joint_properties friction="0.0"/>
</joint>

<joint name="Lindex_23" type="revolute">
<origin xyz="-0.038000000000001032952 0.0007499999999999017869 -0.00074999999999991739941" rpy="2.633923199780482224e-16 1.4039087997615957701e-15 1.6106092236899431285e-15" />
<parent link="part_1_8" />
<child link="part_1_9" />
<axis xyz="0 0 1"/>
<limit effort="100" velocity="20" lower="0" upper="1.570796326794896558"/>
<joint_properties friction="0.0"/>
</joint>

<joint name="Lindex_12" type="revolute">
<origin xyz="-0.014749999999999902078 -0.0060000000000000053291 -0.0095000000000000240502" rpy="1.570796326794896558 9.5297758072252420905e-16 -1.2875254874669294351e-15" />
<parent link="part_1_3" />
<child link="part_1_8" />
<axis xyz="0 0 1"/>
<limit effort="100" velocity="20" lower="0" upper="1.570796326794896558"/>
<joint_properties friction="0.0"/>
</joint>

<joint name="Lindex_01" type="revolute">
<origin xyz="-0.16028164023610538824 0.14948044673134122662 0.018238679244508611971" rpy="-2.4771671902211437361e-16 4.8154350303711388572e-16 -1.6406094968746700591" />
<parent link="left_forearm_and_palm_subassembly" />
<child link="part_1_3" />
<axis xyz="0 0 1"/>
<limit effort="100" velocity="20" lower="-0.29670597283903604735" upper="0.29670597283903604735"/>
<joint_properties friction="0.0"/>
</joint>

<link name="part_1_2">
<visual>
<origin xyz="-0.0049999999999999766853 0 -0.018500000000000099698" rpy="-1.4485681946286607074e-16 8.5979375613828716732e-16 -1.5295923154279766373e-19" />
<geometry>
<mesh filename="meshes/part_1_2.stl"/>
</geometry>
<material name="part_1_2_material">
<color rgba="0.64705882352941179736 0.64705882352941179736 0.64705882352941179736 1.0"/>
</material>
</visual>
<collision>
<origin xyz="-0.0049999999999999766853 0 -0.018500000000000099698" rpy="-1.4485681946286607074e-16 8.5979375613828716732e-16 -1.5295923154279766373e-19" />
<geometry>
<mesh filename="meshes/part_1_2.stl"/>
</geometry>
</collision>
<inertial>
<origin xyz="0 0 0" rpy="0 0 0"/>
<mass value="0" />
<inertia ixx="0" ixy="0"  ixz="0" iyy="0" iyz="0" izz="0" />
</inertial>
</link>

<link name="part_1_7">
<visual>
<origin xyz="-0.028552407289709619276 -0.0078589767938891941235 -0.0060000000000050845994" rpy="-1.570796326794896558 9.2248626095824611511e-16 -1.9721522630525299514e-31" />
<geometry>
<mesh filename="meshes/part_1_7.stl"/>
</geometry>
<material name="part_1_7_material">
<color rgba="0.61568627450980395466 0.81176470588235294379 0.92941176470588238168 1.0"/>
</material>
</visual>
<collision>
<origin xyz="-0.028552407289709619276 -0.0078589767938891941235 -0.0060000000000050845994" rpy="-1.570796326794896558 9.2248626095824611511e-16 -1.9721522630525299514e-31" />
<geometry>
<mesh filename="meshes/part_1_7.stl"/>
</geometry>
</collision>
<inertial>
<origin xyz="0 0 0" rpy="0 0 0"/>
<mass value="0" />
<inertia ixx="0" ixy="0"  ixz="0" iyy="0" iyz="0" izz="0" />
</inertial>
</link>

<link name="part_1_11">
<visual>
<origin xyz="-0.017524803018038798141 -0.0071295923980049134491 -0.0052500000000001711964" rpy="-1.5707963267948970021 5.1210507312625532671e-16 0" />
<geometry>
<mesh filename="meshes/part_1_11.stl"/>
</geometry>
<material name="part_1_11_material">
<color rgba="0.91764705882352937127 0.91764705882352937127 0.91764705882352937127 1.0"/>
</material>
</visual>
<collision>
<origin xyz="-0.017524803018038798141 -0.0071295923980049134491 -0.0052500000000001711964" rpy="-1.5707963267948970021 5.1210507312625532671e-16 0" />
<geometry>
<mesh filename="meshes/part_1_11.stl"/>
</geometry>
</collision>
<inertial>
<origin xyz="0 0 0" rpy="0 0 0"/>
<mass value="0" />
<inertia ixx="0" ixy="0"  ixz="0" iyy="0" iyz="0" izz="0" />
</inertial>
</link>

<link name="d1_urdf_mk_5_4">
<visual>
<origin xyz="-0.0090000000000002022826 -0.006000000000000002727 -0.0047499999999967013053" rpy="-1.5707963267948961139 8.9497140061701936076e-17 -6.1629758220399834664e-32" />
<geometry>
<mesh filename="meshes/d1_urdf_mk_5_4.stl"/>
</geometry>
<material name="d1_urdf_mk_5_4_material">
<color rgba="0.2313725490196078538 0.38039215686274507888 0.7058823529411765163 1.0"/>
</material>
</visual>
<collision>
<origin xyz="-0.0090000000000002022826 -0.006000000000000002727 -0.0047499999999967013053" rpy="-1.5707963267948961139 8.9497140061701936076e-17 -6.1629758220399834664e-32" />
<geometry>
<mesh filename="meshes/d1_urdf_mk_5_4.stl"/>
</geometry>
</collision>
<inertial>
<origin xyz="0 0 0" rpy="0 0 0"/>
<mass value="0" />
<inertia ixx="0" ixy="0"  ixz="0" iyy="0" iyz="0" izz="0" />
</inertial>
</link>

<joint name="Lring_34" type="revolute">
<origin xyz="-0.024999999999999966693 -2.7755575615628913511e-17 -0.00050000000000002819966" rpy="5.1674743535605903421e-17 9.020325859057924895e-16 -3.4694469519567153983e-17" />
<parent link="part_1_11" />
<child link="d1_urdf_mk_5_4" />
<axis xyz="0 0 1"/>
<limit effort="100" velocity="20" lower="0" upper="1.570796326794896558"/>
<joint_properties friction="0.0"/>
</joint>

<joint name="Lring_23" type="revolute">
<origin xyz="-0.038000000000001032952 0.00074999999999993821609 -0.00074999999999994515498" rpy="-2.2185327369992283668e-17 -9.0028536306555107568e-16 -6.7571691218505094307e-19" />
<parent link="part_1_7" />
<child link="part_1_11" />
<axis xyz="0 0 1"/>
<limit effort="100" velocity="20" lower="0" upper="1.570796326794896558"/>
<joint_properties friction="0.0"/>
</joint>

<joint name="Lring_12" type="revolute">
<origin xyz="-0.014749999999999957589 -0.0060000000000000330846 -0.0095000000000000413974" rpy="1.570796326794896558 8.5979375613832513125e-16 -1.1491900863518788493e-16" />
<parent link="part_1_2" />
<child link="part_1_7" />
<axis xyz="0 0 1"/>
<limit effort="100" velocity="20" lower="0" upper="1.570796326794896558"/>
<joint_properties friction="0.0"/>
</joint>

<joint name="Lring_01" type="revolute">
<origin xyz="-0.20326918124942178201 0.14809262510567919313 0.018238679244508650135" rpy="-7.4244371424259424518e-17 3.815925357489116985e-16 -1.50098315671495941" />
<parent link="left_forearm_and_palm_subassembly" />
<child link="part_1_2" />
<axis xyz="0 0 1"/>
<limit effort="100" velocity="20" lower="-0.29670597283903604735" upper="0.29670597283903604735"/>
<joint_properties friction="0.0"/>
</joint>

<link name="part_1_4">
<visual>
<origin xyz="-0.0049999999999999766853 2.7755575615628913511e-17 -0.018500000000000099698" rpy="-1.4485681946286607074e-16 8.597937561382868715e-16 -5.4673680191676249868e-30" />
<geometry>
<mesh filename="meshes/part_1_4.stl"/>
</geometry>
<material name="part_1_4_material">
<color rgba="0.64705882352941179736 0.64705882352941179736 0.64705882352941179736 1.0"/>
</material>
</visual>
<collision>
<origin xyz="-0.0049999999999999766853 2.7755575615628913511e-17 -0.018500000000000099698" rpy="-1.4485681946286607074e-16 8.597937561382868715e-16 -5.4673680191676249868e-30" />
<geometry>
<mesh filename="meshes/part_1_4.stl"/>
</geometry>
</collision>
<inertial>
<origin xyz="0 0 0" rpy="0 0 0"/>
<mass value="0" />
<inertia ixx="0" ixy="0"  ixz="0" iyy="0" iyz="0" izz="0" />
</inertial>
</link>

<link name="part_1_5">
<visual>
<origin xyz="-0.028552407289709674787 -0.0078589767938891941235 -0.0060000000000051401106" rpy="-1.570796326794896558 9.1312390131153590628e-16 1.9721522630525295135e-31" />
<geometry>
<mesh filename="meshes/part_1_5.stl"/>
</geometry>
<material name="part_1_5_material">
<color rgba="0.61568627450980395466 0.81176470588235294379 0.92941176470588238168 1.0"/>
</material>
</visual>
<collision>
<origin xyz="-0.028552407289709674787 -0.0078589767938891941235 -0.0060000000000051401106" rpy="-1.570796326794896558 9.1312390131153590628e-16 1.9721522630525295135e-31" />
<geometry>
<mesh filename="meshes/part_1_5.stl"/>
</geometry>
</collision>
<inertial>
<origin xyz="0 0 0" rpy="0 0 0"/>
<mass value="0" />
<inertia ixx="0" ixy="0"  ixz="0" iyy="0" iyz="0" izz="0" />
</inertial>
</link>

<link name="part_1_10">
<visual>
<origin xyz="-0.017524803018038770386 -0.0071295923980049125818 -0.005250000000000198952" rpy="-1.5707963267948970021 5.1781495757909308933e-16 1.9721522630525295135e-31" />
<geometry>
<mesh filename="meshes/part_1_10.stl"/>
</geometry>
<material name="part_1_10_material">
<color rgba="0.91764705882352937127 0.91764705882352937127 0.91764705882352937127 1.0"/>
</material>
</visual>
<collision>
<origin xyz="-0.017524803018038770386 -0.0071295923980049125818 -0.005250000000000198952" rpy="-1.5707963267948970021 5.1781495757909308933e-16 1.9721522630525295135e-31" />
<geometry>
<mesh filename="meshes/part_1_10.stl"/>
</geometry>
</collision>
<inertial>
<origin xyz="0 0 0" rpy="0 0 0"/>
<mass value="0" />
<inertia ixx="0" ixy="0"  ixz="0" iyy="0" iyz="0" izz="0" />
</inertial>
</link>

<link name="d1_urdf_mk_5_2">
<visual>
<origin xyz="-0.0090000000000001745271 -0.0059999999999999645631 -0.0047499999999967013053" rpy="-1.5707963267948961139 8.3887279286783339258e-17 1.9721522630525295135e-31" />
<geometry>
<mesh filename="meshes/d1_urdf_mk_5_2.stl"/>
</geometry>
<material name="d1_urdf_mk_5_2_material">
<color rgba="0.2313725490196078538 0.38039215686274507888 0.7058823529411765163 1.0"/>
</material>
</visual>
<collision>
<origin xyz="-0.0090000000000001745271 -0.0059999999999999645631 -0.0047499999999967013053" rpy="-1.5707963267948961139 8.3887279286783339258e-17 1.9721522630525295135e-31" />
<geometry>
<mesh filename="meshes/d1_urdf_mk_5_2.stl"/>
</geometry>
</collision>
<inertial>
<origin xyz="0 0 0" rpy="0 0 0"/>
<mass value="0" />
<inertia ixx="0" ixy="0"  ixz="0" iyy="0" iyz="0" izz="0" />
</inertial>
</link>

<joint name="Lmiddle_34" type="revolute">
<origin xyz="-0.024999999999999994449 -2.9490299091605720605e-17 -0.00050000000000000044409" rpy="-1.5886902484737662051e-18 -3.1439676169748260452e-30 1.9428902930939837631e-16" />
<parent link="part_1_10" />
<child link="d1_urdf_mk_5_2" />
<axis xyz="0 0 1"/>
<limit effort="100" velocity="20" lower="0" upper="1.570796326794896558"/>
<joint_properties friction="0.0"/>
</joint>

<joint name="Lmiddle_23" type="revolute">
<origin xyz="-0.038000000000001060707 0.00074999999999993648137 -0.00075000000000000066613" rpy="4.5529756813604885173e-16 1.0445279554695405798e-29 -2.734052644706137323e-15" />
<parent link="part_1_5" />
<child link="part_1_10" />
<axis xyz="0 0 1"/>
<limit effort="100" velocity="20" lower="0" upper="1.570796326794896558"/>
<joint_properties friction="0.0"/>
</joint>

<joint name="Lmiddle_12" type="revolute">
<origin xyz="-0.014749999999999929834 -0.0059999999999999775735 -0.0095000000000000413974" rpy="1.570796326794896558 -1.7799547329187419598e-15 -1.2888655552049692247e-16" />
<parent link="part_1_4" />
<child link="part_1_5" />
<axis xyz="0 0 1"/>
<limit effort="100" velocity="20" lower="0" upper="1.570796326794896558"/>
<joint_properties friction="0.0"/>
</joint>

<joint name="Lmiddle_01" type="revolute">
<origin xyz="-0.18190440495078175065 0.15253711492388191684 0.021238679244508618105" rpy="-1.6137364330639933628e-16 4.3368086899411987998e-16 -1.5707963267948421571" />
<parent link="left_forearm_and_palm_subassembly" />
<child link="part_1_4" />
<axis xyz="0 0 1"/>
<limit effort="100" velocity="20" lower="-0.29670597283903604735" upper="0.29670597283903604735"/>
<joint_properties friction="0.0"/>
</joint>

<link name="part_1_1">
<visual>
<origin xyz="-0.0049999999999999766853 2.7755575615628913511e-17 -0.018500000000000099698" rpy="-1.4485681946286607074e-16 8.5979375613828706871e-16 7.6269552567960846755e-18" />
<geometry>
<mesh filename="meshes/part_1_1.stl"/>
</geometry>
<material name="part_1_1_material">
<color rgba="0.64705882352941179736 0.64705882352941179736 0.64705882352941179736 1.0"/>
</material>
</visual>
<collision>
<origin xyz="-0.0049999999999999766853 2.7755575615628913511e-17 -0.018500000000000099698" rpy="-1.4485681946286607074e-16 8.5979375613828706871e-16 7.6269552567960846755e-18" />
<geometry>
<mesh filename="meshes/part_1_1.stl"/>
</geometry>
</collision>
<inertial>
<origin xyz="0 0 0" rpy="0 0 0"/>
<mass value="0" />
<inertia ixx="0" ixy="0"  ixz="0" iyy="0" iyz="0" izz="0" />
</inertial>
</link>

<link name="part_1_6">
<visual>
<origin xyz="-0.028552407289709619276 -0.0078589767938891108567 -0.006000000000005112355" rpy="-1.570796326794896558 9.0908852002610283241e-16 6.4711246131415022024e-31" />
<geometry>
<mesh filename="meshes/part_1_6.stl"/>
</geometry>
<material name="part_1_6_material">
<color rgba="0.61568627450980395466 0.81176470588235294379 0.92941176470588238168 1.0"/>
</material>
</visual>
<collision>
<origin xyz="-0.028552407289709619276 -0.0078589767938891108567 -0.006000000000005112355" rpy="-1.570796326794896558 9.0908852002610283241e-16 6.4711246131415022024e-31" />
<geometry>
<mesh filename="meshes/part_1_6.stl"/>
</geometry>
</collision>
<inertial>
<origin xyz="0 0 0" rpy="0 0 0"/>
<mass value="0" />
<inertia ixx="0" ixy="0"  ixz="0" iyy="0" iyz="0" izz="0" />
</inertial>
</link>

<link name="part_1_12">
<visual>
<origin xyz="-0.017524803018038770386 -0.0071295923980055934607 -0.0052500000000001711964" rpy="-1.5707963267948970021 5.4010723607971334827e-16 -3.9443045261048243096e-31" />
<geometry>
<mesh filename="meshes/part_1_12.stl"/>
</geometry>
<material name="part_1_12_material">
<color rgba="0.91764705882352937127 0.91764705882352937127 0.91764705882352937127 1.0"/>
</material>
</visual>
<collision>
<origin xyz="-0.017524803018038770386 -0.0071295923980055934607 -0.0052500000000001711964" rpy="-1.5707963267948970021 5.4010723607971334827e-16 -3.9443045261048243096e-31" />
<geometry>
<mesh filename="meshes/part_1_12.stl"/>
</geometry>
</collision>
<inertial>
<origin xyz="0 0 0" rpy="0 0 0"/>
<mass value="0" />
<inertia ixx="0" ixy="0"  ixz="0" iyy="0" iyz="0" izz="0" />
</inertial>
</link>

<link name="d1_urdf_mk_5_1">
<visual>
<origin xyz="-0.0090000000000001745271 -0.0059999999999999636957 -0.0047499999999966735498" rpy="-1.5707963267948961139 6.8414173103028337299e-17 1.9721522630525295135e-31" />
<geometry>
<mesh filename="meshes/d1_urdf_mk_5_1.stl"/>
</geometry>
<material name="d1_urdf_mk_5_1_material">
<color rgba="0.2313725490196078538 0.38039215686274507888 0.7058823529411765163 1.0"/>
</material>
</visual>
<collision>
<origin xyz="-0.0090000000000001745271 -0.0059999999999999636957 -0.0047499999999966735498" rpy="-1.5707963267948961139 6.8414173103028337299e-17 1.9721522630525295135e-31" />
<geometry>
<mesh filename="meshes/d1_urdf_mk_5_1.stl"/>
</geometry>
</collision>
<inertial>
<origin xyz="0 0 0" rpy="0 0 0"/>
<mass value="0" />
<inertia ixx="0" ixy="0"  ixz="0" iyy="0" iyz="0" izz="0" />
</inertial>
</link>

<joint name="Lpinky_34" type="revolute">
<origin xyz="-0.024999999999999938938 -7.0689981646054889097e-16 -0.00050000000000000044409" rpy="4.6845789658601521163e-15 1.2451566657709276037e-14 2.3858480570263377984e-15" />
<parent link="part_1_12" />
<child link="d1_urdf_mk_5_1" />
<axis xyz="0 0 1"/>
<limit effort="100" velocity="20" lower="0" upper="1.570796326794896558"/>
<joint_properties friction="0.0"/>
</joint>

<joint name="Lpinky_23" type="revolute">
<origin xyz="-0.038000000000001032952 0.00075000000000002148282 -0.00074999999999997291056" rpy="-1.782449066306226429e-15 -6.2139394438100824626e-15 -1.0963452368173269375e-14" />
<parent link="part_1_6" />
<child link="part_1_12" />
<axis xyz="0 0 1"/>
<limit effort="100" velocity="20" lower="0" upper="1.570796326794896558"/>
<joint_properties friction="0.0"/>
</joint>

<joint name="Lpinky_12" type="revolute">
<origin xyz="-0.014749999999999985345 -0.0059999999999999498179 -0.0095000000000000396627" rpy="1.570796326794896558 -7.7355014228884119488e-15 -6.3479015660543924523e-15" />
<parent link="part_1_1" />
<child link="part_1_6" />
<axis xyz="0 0 1"/>
<limit effort="100" velocity="20" lower="0" upper="1.570796326794896558"/>
<joint_properties friction="0.0"/>
</joint>

<joint name="Lpinky_01" type="revolute">
<origin xyz="-0.22372307409338731965 0.14057577467475887434 0.015238679244508579816" rpy="1.3301558958854186292e-17 3.2476273351568403052e-16 -1.4486232791552937638" />
<parent link="left_forearm_and_palm_subassembly" />
<child link="part_1_1" />
<axis xyz="0 0 1"/>
<limit effort="100" velocity="20" lower="-0.29670597283903604735" upper="0.29670597283903604735"/>
<joint_properties friction="0.0"/>
</joint>

<link name="part_1_17">
<visual>
<origin xyz="-0.0049999999999999766853 0 0.00062867965644033962924" rpy="-3.141592653589793116 -2.0975514987374448586e-17 -1.2178546317827320757e-18" />
<geometry>
<mesh filename="meshes/part_1_17.stl"/>
</geometry>
<material name="part_1_17_material">
<color rgba="0.2313725490196078538 0.38039215686274507888 0.7058823529411765163 1.0"/>
</material>
</visual>
<collision>
<origin xyz="-0.0049999999999999766853 0 0.00062867965644033962924" rpy="-3.141592653589793116 -2.0975514987374448586e-17 -1.2178546317827320757e-18" />
<geometry>
<mesh filename="meshes/part_1_17.stl"/>
</geometry>
</collision>
<inertial>
<origin xyz="0 0 0" rpy="0 0 0"/>
<mass value="0" />
<inertia ixx="0" ixy="0"  ixz="0" iyy="0" iyz="0" izz="0" />
</inertial>
</link>

<link name="part_1_18">
<visual>
<origin xyz="-0.029277356236810186951 -0.0078134566939178085043 -0.0067500000000003251843" rpy="-1.570796326794896336 4.8623430361183478783e-16 -3.5162334485555108458e-17" />
<geometry>
<mesh filename="meshes/part_1_18.stl"/>
</geometry>
<material name="part_1_18_material">
<color rgba="0.64705882352941179736 0.64705882352941179736 0.64705882352941179736 1.0"/>
</material>
</visual>
<collision>
<origin xyz="-0.029277356236810186951 -0.0078134566939178085043 -0.0067500000000003251843" rpy="-1.570796326794896336 4.8623430361183478783e-16 -3.5162334485555108458e-17" />
<geometry>
<mesh filename="meshes/part_1_18.stl"/>
</geometry>
</collision>
<inertial>
<origin xyz="0 0 0" rpy="0 0 0"/>
<mass value="0" />
<inertia ixx="0" ixy="0"  ixz="0" iyy="0" iyz="0" izz="0" />
</inertial>
</link>

<link name="part_1_19">
<visual>
<origin xyz="-0.017524803018038624669 -0.0071295923980052022806 -0.0062499999999999361622" rpy="-1.57079632679489678 6.3121236051819880868e-16 -2.6758692065306660511e-17" />
<geometry>
<mesh filename="meshes/part_1_19.stl"/>
</geometry>
<material name="part_1_19_material">
<color rgba="0.61568627450980395466 0.81176470588235294379 0.92941176470588238168 1.0"/>
</material>
</visual>
<collision>
<origin xyz="-0.017524803018038624669 -0.0071295923980052022806 -0.0062499999999999361622" rpy="-1.57079632679489678 6.3121236051819880868e-16 -2.6758692065306660511e-17" />
<geometry>
<mesh filename="meshes/part_1_19.stl"/>
</geometry>
</collision>
<inertial>
<origin xyz="0 0 0" rpy="0 0 0"/>
<mass value="0" />
<inertia ixx="0" ixy="0"  ixz="0" iyy="0" iyz="0" izz="0" />
</inertial>
</link>

<link name="part_1_20">
<visual>
<origin xyz="-0.0089999999999997304378 -0.0060000000000001163514 -0.0057500000000045153881" rpy="-1.570796326794896558 2.2586083449859545637e-16 2.4580531496619517172e-17" />
<geometry>
<mesh filename="meshes/part_1_20.stl"/>
</geometry>
<material name="part_1_20_material">
<color rgba="0.49803921568627451677 0.49803921568627451677 0.49803921568627451677 1.0"/>
</material>
</visual>
<collision>
<origin xyz="-0.0089999999999997304378 -0.0060000000000001163514 -0.0057500000000045153881" rpy="-1.570796326794896558 2.2586083449859545637e-16 2.4580531496619517172e-17" />
<geometry>
<mesh filename="meshes/part_1_20.stl"/>
</geometry>
</collision>
<inertial>
<origin xyz="0 0 0" rpy="0 0 0"/>
<mass value="0" />
<inertia ixx="0" ixy="0"  ixz="0" iyy="0" iyz="0" izz="0" />
</inertial>
</link>

<joint name="Lthumb_34" type="revolute">
<origin xyz="-0.025000000000000122818 -8.6042284408449631883e-16 0.0010000000000002229328" rpy="-4.7679692275343041977e-15 4.4959326954502218291e-15 1.6836456841789364934e-14" />
<parent link="part_1_19" />
<child link="part_1_20" />
<axis xyz="0 0 1"/>
<limit effort="100" velocity="20" lower="0" upper="1.570796326794896558"/>
<joint_properties friction="0.0"/>
</joint>

<joint name="Lthumb_23" type="revolute">
<origin xyz="-0.038000000000000769274 0.00075000000000011168844 -0.0004999999999999865663" rpy="9.8266833422420554545e-16 2.0874140411211021438e-16 -1.6707749441501944104e-14" />
<parent link="part_1_18" />
<child link="part_1_19" />
<axis xyz="0 0 1"/>
<limit effort="100" velocity="20" lower="0" upper="1.570796326794896558"/>
<joint_properties friction="0.0"/>
</joint>

<joint name="Lthumb_12" type="revolute">
<origin xyz="-0.014750000000000068612 0.0067500000000000753841 -0.0077500000000000068834" rpy="-1.5707963267948972241 -2.0836577888207361949e-15 1.908755618073153476e-14" />
<parent link="part_1_17" />
<child link="part_1_18" />
<axis xyz="0 0 1"/>
<limit effort="100" velocity="20" lower="0" upper="1.570796326794896558"/>
<joint_properties friction="0.0"/>
</joint>

<joint name="Lthumb_01" type="revolute">
<origin xyz="-0.17124158623158930448 0.10739372327556818976 -0.012602166449204452864" rpy="2.0752759914175786804 -1.0057357117289742465 3.141592653589763362" />
<parent link="left_forearm_and_palm_subassembly" />
<child link="part_1_17" />
<axis xyz="0 0 1"/>
<limit effort="100" velocity="20" lower="-0.64577182323790194296" upper="0.64577182323790194296"/>
<joint_properties friction="0.0"/>
</joint>


</robot>
