<?xml version="1.0" ?>
<robot name="spot" xmlns:xacro="http://www.ros.org/wiki/xacro">
    <link name="ground">
    <tag part="base"/>
    </link>
    
    <joint name="ground_link_joint" type="fixed">
            <origin xyz="0 0 0.69" rpy="0 0 0" />
            <parent link="ground" />
            <child link="body" />
    </joint>
    
    <link name="body">
        <visual>
            <geometry>
                <mesh filename="meshes/body.dae" />
            </geometry>
        </visual>
        <collision>
            <geometry>
                <mesh filename="meshes/body_collision.stl" />
            </geometry>
        </collision>
    </link>

    <link name="base_link"/>
    <joint name="base_link_joint" type="fixed">
        <origin xyz="0 0 0" rpy="0 0 0" />
        <parent link="body" />
        <child link="base_link" />
    </joint>
    
    <link name="head_link">
        <tag part="head"/>
        <sensor>
           <type name="camera"/>
           <type name="audio_source"/>
           <type name="microphone"/>
        </sensor>
    </link>
    <joint name="head_link_joint" type="fixed">
        <origin xyz="0.4 0 0" rpy="0 0 0" />
        <parent link="base_link" />
        <child link="head_link" />
    </joint>

    <link name="front_rail"/>
    <joint name="front_rail_joint" type="fixed">
        <origin xyz="0.223 0 0.0805" rpy="0 0 0" />
        <parent link="body" />
        <child link="front_rail" />
    </joint>

    <link name="rear_rail"/>
    <joint name="rear_rail_joint" type="fixed">
        <origin xyz="-0.223 0 0.0805" rpy="0 0 0" />
        <parent link="body" />
        <child link="rear_rail" />
    </joint>

    <link name="front_left_hip">
        <visual>
            <geometry>
                <mesh filename="meshes/front_left_hip.dae" />
            </geometry>
        </visual>
        <collision>
            <geometry>
                <mesh filename="meshes/front_left_hip_collision.stl" />
            </geometry>
        </collision>
    </link>
    <joint name="front_left_hip_x" type="revolute">
        <origin xyz="0.29785 0.05500 0.00000" rpy="0 0 0" />
        <axis xyz="1 0 0" />
        <parent link="body" />
        <child link="front_left_hip" />
        <limit effort="1000" velocity="1000.00" lower="-0.78539816339744827899" upper="0.78539816339744827899" />
    </joint>
    <link name="front_left_upper_leg">
        <visual>
            <geometry>
                <mesh filename="meshes/front_left_upper_leg.dae" />
            </geometry>
        </visual>
        <collision>
            <geometry>
                <mesh filename="meshes/front_left_upper_leg_collision.stl" />
            </geometry>
        </collision>
    </link>
    <joint name="front_left_hip_y" type="revolute">
        <origin xyz="0.0 0.110945 0.0" rpy="0 0 0" />
        <axis xyz="0 1 0" />
        <parent link="front_left_hip" />
        <child link="front_left_upper_leg" />
        <limit effort="1000" velocity="1000.00" lower="-0.89884456477707963539" upper="2.2951079663725435509" />
    </joint>
    <link name="front_left_lower_leg">
        <visual>
            <geometry>
                <mesh filename="meshes/front_left_lower_leg.dae" />
            </geometry>
        </visual>
        <collision>
            <geometry>
                <mesh filename="meshes/front_left_lower_leg_collision.stl" />
            </geometry>
        </collision>
    </link>
    <joint name="front_left_knee" type="revolute">
        <origin xyz="0.025 0.000 -0.3205" rpy="0 0 0" />
        <axis xyz="0 1 0" />
        <parent link="front_left_upper_leg" />
        <child link="front_left_lower_leg" />
        <limit effort="1000" velocity="1000.00" lower="-2.7929" upper="-0.254801" />
    </joint>
    <link name="front_right_hip">
        <visual>
            <geometry>
                <mesh filename="meshes/front_right_hip.dae" />
            </geometry>
        </visual>
        <collision>
            <geometry>
                <mesh filename="meshes/front_right_hip_collision.stl" />
            </geometry>
        </collision>
    </link>
    <joint name="front_right_hip_x" type="revolute">
        <origin xyz="0.29785 -0.05500 0.00000" rpy="0 0 0" />
        <axis xyz="1 0 0" />
        <parent link="body" />
        <child link="front_right_hip" />
        <limit effort="1000" velocity="1000.00" lower="-0.78539816339744827899" upper="0.78539816339744827899" />
    </joint>
    <link name="front_right_upper_leg">
        <visual>
            <geometry>
                <mesh filename="meshes/front_right_upper_leg.dae" />
            </geometry>
        </visual>
        <collision>
            <geometry>
                <mesh filename="meshes/front_right_upper_leg_collision.stl" />
            </geometry>
        </collision>
    </link>
    <joint name="front_right_hip_y" type="revolute">
        <origin xyz="0.0 -0.110945 0.0" rpy="0 0 0" />
        <axis xyz="0 1 0" />
        <parent link="front_right_hip" />
        <child link="front_right_upper_leg" />
        <limit effort="1000" velocity="1000.00" lower="-0.89884456477707963539" upper="2.2951079663725435509" />
    </joint>
    <link name="front_right_lower_leg">
        <visual>
            <geometry>
                <mesh filename="meshes/front_right_lower_leg.dae" />
            </geometry>
        </visual>
        <collision>
            <geometry>
                <mesh filename="meshes/front_right_lower_leg_collision.stl" />
            </geometry>
        </collision>
    </link>
    <joint name="front_right_knee" type="revolute">
        <origin xyz="0.025 0.000 -0.3205" rpy="0 0 0" />
        <axis xyz="0 1 0" />
        <parent link="front_right_upper_leg" />
        <child link="front_right_lower_leg" />
        <limit effort="1000" velocity="1000.00" lower="-2.7929" upper="-0.247563" />
    </joint>
    <link name="rear_left_hip">
        <visual>
            <geometry>
                <mesh filename="meshes/rear_left_hip.dae" />
            </geometry>
        </visual>
        <collision>
            <geometry>
                <mesh filename="meshes/rear_left_hip_collision.stl" />
            </geometry>
        </collision>
    </link>
    <joint name="rear_left_hip_x" type="revolute">
        <origin xyz="-0.29785 0.05500 0.00000" rpy="0 0 0" />
        <axis xyz="1 0 0" />
        <parent link="body" />
        <child link="rear_left_hip" />
        <limit effort="1000" velocity="1000.00" lower="-0.78539816339744827899" upper="0.78539816339744827899" />
    </joint>
    <link name="rear_left_upper_leg">
        <visual>
            <geometry>
                <mesh filename="meshes/rear_left_upper_leg.dae" />
            </geometry>
        </visual>
        <collision>
            <geometry>
                <mesh filename="meshes/rear_left_upper_leg_collision.stl" />
            </geometry>
        </collision>
    </link>
    <joint name="rear_left_hip_y" type="revolute">
        <origin xyz="0.0 0.110945 0.0" rpy="0 0 0" />
        <axis xyz="0 1 0" />
        <parent link="rear_left_hip" />
        <child link="rear_left_upper_leg" />
        <limit effort="1000" velocity="1000.00" lower="-0.89884456477707963539" upper="2.2951079663725435509" />
    </joint>
    <link name="rear_left_lower_leg">
        <visual>
            <geometry>
                <mesh filename="meshes/rear_left_lower_leg.dae" />
            </geometry>
        </visual>
        <collision>
            <geometry>
                <mesh filename="meshes/rear_left_lower_leg_collision.stl" />
            </geometry>
        </collision>
    </link>
    <joint name="rear_left_knee" type="revolute">
        <origin xyz="0.025 0.000 -0.3205" rpy="0 0 0" />
        <axis xyz="0 1 0" />
        <parent link="rear_left_upper_leg" />
        <child link="rear_left_lower_leg" />
        <limit effort="1000" velocity="1000.00" lower="-2.7929" upper="-0.267153" />
    </joint>
    <link name="rear_right_hip">
        <visual>
            <geometry>
                <mesh filename="meshes/rear_right_hip.dae" />
            </geometry>
        </visual>
        <collision>
            <geometry>
                <mesh filename="meshes/rear_right_hip_collision.stl" />
            </geometry>
        </collision>
    </link>
    <joint name="rear_right_hip_x" type="revolute">
        <origin xyz="-0.29785 -0.05500 0.00000" rpy="0 0 0" />
        <axis xyz="1 0 0" />
        <parent link="body" />
        <child link="rear_right_hip" />
        <limit effort="1000" velocity="1000.00" lower="-0.78539816339744827899" upper="0.78539816339744827899" />
    </joint>
    <link name="rear_right_upper_leg">
        <visual>
            <geometry>
                <mesh filename="meshes/rear_right_upper_leg.dae" />
            </geometry>
        </visual>
        <collision>
            <geometry>
                <mesh filename="meshes/rear_right_upper_leg_collision.stl" />
            </geometry>
        </collision>
    </link>
    <joint name="rear_right_hip_y" type="revolute">
        <origin xyz="0.0 -0.110945 0.0" rpy="0 0 0" />
        <axis xyz="0 1 0" />
        <parent link="rear_right_hip" />
        <child link="rear_right_upper_leg" />
        <limit effort="1000" velocity="1000.00" lower="-0.89884456477707963539" upper="2.2951079663725435509" />
    </joint>
    <link name="rear_right_lower_leg">
        <visual>
            <geometry>
                <mesh filename="meshes/rear_right_lower_leg.dae" />
            </geometry>
        </visual>
        <collision>
            <geometry>
                <mesh filename="meshes/rear_right_lower_leg_collision.stl" />
            </geometry>
        </collision>
    </link>
    <joint name="rear_right_knee" type="revolute">
        <origin xyz="0.025 0.000 -0.3205" rpy="0 0 0" />
        <axis xyz="0 1 0" />
        <parent link="rear_right_upper_leg" />
        <child link="rear_right_lower_leg" />
        <limit effort="1000" velocity="1000.00" lower="-2.7929" upper="-0.257725" />
    </joint>
    
    <joint name="arm_mount_joint" type="fixed">
          <parent link="base_link"/>
          <child link="arm_mount"/>
          <origin xyz="0.3 0 0.0842" rpy="0 0 0"/>
    </joint>
        
    <link name="arm_mount">
          <visual>
            <geometry>
              <box size="0.1 0.1 0.05"/>
            </geometry>
            <origin rpy="0 0 0" xyz="0 0 0.025"/>
            <material name="Black">
                    <color rgba="1.0 1.0 1.0 1.0"/>
            </material>
          </visual>
          <collision>
            <geometry>
              <box size="0.1 0.1 0.05"/>
            </geometry>
          </collision>
    </link>
    
    <joint name="joint_1" type="revolute">
        <parent link="arm_mount"/>
        <child link="joint_1_link"/>
        <origin rpy="0 0 3.14159" xyz="0 0 0.05"/>
        <axis xyz="0 0 1"/>
        <limit effort="150.0" lower="-2.61799" upper="3.14159" velocity="3.15"/>
        <dynamics damping="0.0" friction="0.0"/>
    </joint>

    <link name="joint_1_link">
        <visual>
           <geometry>
             <box size="0.11 0.11 0.1"/>
           </geometry>
           <origin rpy="0 0 0" xyz="0 0 0.05"/>
        </visual>
        <collision>
           <geometry>
             box size="0.11 0.11 0.1"/>
           </geometry>
           <origin rpy="0 0 0" xyz="0 0 0.05"/>
        </collision>
    </link>
     
    <joint name="joint_2" type="revolute">
         <parent link="joint_1_link"/>
         <child link="joint_2_link"/>
         <origin rpy="0 -1.5708 0" xyz="0 0 0.05"/>
         <axis xyz="0 -1 0"/>
         <limit effort="150.0" lower="-3.14159" upper="0.5236" velocity="3.15"/>
         <dynamics damping="0.0" friction="0.0"/>
    </joint>
    
   <link name="joint_2_link">
       <visual>
          <geometry>
            <box size="0.3385 0.075 0.075"/>
          </geometry>
          <origin rpy="0 1.5708 0" xyz="0 0 0.16925"/>
       </visual>
       <collision>
          <geometry>
            <box size="0.3385 0.075 0.075"/>
          </geometry>
          <origin rpy="0 1.5708 0" xyz="0 0 0.16925"/>
       </collision>
   </link>
   
    <joint name="joint_3" type="revolute">
         <parent link="joint_2_link"/>
         <child link="joint_3_link"/>
         <origin rpy="0 3.14159 0" xyz="0 0 0.3385"/>
         <axis xyz="0 -1 0"/>
         <limit effort="150.0" lower="0" upper="3.1415" velocity="3.15"/>
         <dynamics damping="0.0" friction="0.0"/>
    </joint>
    
   <link name="joint_3_link"/>
   
   <joint name="joint_4" type="revolute">
            <parent link="joint_3_link"/>
            <child link="joint_4_link"/>
            <origin rpy="0 0 1.5708" xyz="-0.075 0 -0.1375"/>
            <axis xyz="0 0 -1"/>
            <limit effort="150.0" lower="-2.79253" upper="2.79253" velocity="3.15"/>
            <dynamics damping="0.0" friction="0.0"/>
   </joint>
   
  <link name="joint_4_link">
      <visual>
         <geometry>
            <box size="0.300 0.075 0.075"/>
         </geometry>
         <origin rpy="0 1.5708 0" xyz="0 0 -0.15"/>
      </visual>
      <collision>
         <geometry>
            <box size="0.300 0.075 0.075"/>
         </geometry>
         <origin rpy="0 1.5708 -0.349066" xyz="0 0 -0.15"/>
      </collision>
  </link>
  
  <joint name="joint_5" type="revolute">
      <parent link="joint_4_link"/>
      <child link="joint_5_link"/>
      <origin rpy="0 0 0" xyz="0 0 -0.3"/>
      <axis xyz="-1 0 0"/>
      <limit effort="150.0" lower="-1.8326" upper="1.8326" velocity="3.15"/>
      <dynamics damping="0.0" friction="0.0"/>
  </joint>

  <link name="joint_5_link">
      <visual>
         <geometry>
            <box size="0.075 0.075 0.075"/>
         </geometry>
         <origin rpy="0 0 0" xyz="0 0 -0.0375"/>
      </visual>
      <collision>
         <geometry>
            <box size="0.075 0.075 0.075"/>
         </geometry>
         <origin rpy="0 0 0" xyz="0 0 0"/>
      </collision>
  </link>
  
  <joint name="joint_6" type="revolute">
        <parent link="joint_5_link"/>
        <child link="joint_6_link"/>
        <origin rpy="0 0 0" xyz="0 0 -0.075"/>
        <axis xyz="0 0 1"/>
        <limit effort="150.0" lower="-2.87979" upper="2.87979" velocity="3.15"/>
        <dynamics damping="0.0" friction="0.0"/>
    </joint>
  
    <link name="joint_6_link">
        <visual>
           <geometry>
              <box size="0.075 0.075 0.04245"/>
           </geometry>
           <origin rpy="0 0 0" xyz="0 0 -0.021225"/>
        </visual>
        <collision>
           <geometry>
              <box size="0.075 0.075 0.075"/>
           </geometry>
           <origin rpy="0 0 0" xyz="0 0 0"/>
        </collision>
    </link>
    
    <joint name="joint_7" type="revolute">
        <parent link="joint_6_link"/>
        <child link="joint_7_link"/>
        <origin rpy="0 0 0" xyz="0 -0.0375 -0.04245"/>
        <axis xyz="-1 0 0"/>
        <limit effort="150.0" lower="0" upper="1.5708" velocity="3.15"/>
        <dynamics damping="0.0" friction="0.0"/>
    </joint>
      
  <link name="joint_7_link">
     <visual>
       <geometry>
          <box size="0.075 0.01 0.12482"/>
       </geometry>
       <origin rpy="0 0 0" xyz="0 0 -0.06241"/>
    </visual>
    <collision>
       <geometry>
          <box size="0.075 0.01 0.12482"/>
       </geometry>
       <origin rpy="0 0 0" xyz="0 0 -0.06241"/>
    </collision>
  </link>
        
  <joint name="fixed_jaw" type="fixed">
       <parent link="joint_6_link"/>
       <child link="fixed_jaw_link"/>
       <origin rpy="0 0 0" xyz="0 0.0375 -0.04245"/>
  </joint>
         
  <link name="fixed_jaw_link">
       <visual>
          <geometry>
             <box size="0.075 0.01 0.12482"/>
          </geometry>
          <origin rpy="0 0 0" xyz="0 0 -0.06241"/>
       </visual>
       <collision>
          <geometry>
             <box size="0.075 0.01 0.12482"/>
          </geometry>
          <origin rpy="0 0 0" xyz="0 0 -0.06241"/>
       </collision>
  </link>
  
  <joint name="grab_point" type="fixed">
         <parent link="joint_6_link"/>
         <child link="grab_point_link"/>
         <origin rpy="0 0 0" xyz="0 0 -0.062415"/>
  </joint>
    
 <link name="grab_point_link">
    <objective>
         <type name="position" weight="100" xyz="0 0 0" />
         <type name="orientation" weight="300" rpy="0 -90 90"/>
    </objective>
    <tag part="right_hand"/>
 </link>
 
</robot>