<?xml version="1.0" ?>
<!-- =================================================================================== -->
<!-- |    This document was autogenerated by xacro from ../processed\Fanuc\CR7IAL\xacro\cr7ial.xacro | -->
<!-- |    EDITING THIS FILE BY HAND IS NOT RECOMMENDED                                 | -->
<!-- =================================================================================== -->
<robot xmlns:xacro="http://wiki.ros.org/xacro" name="fanuc_cr7ial">
  <link name="base_link">
    <visual>
      <origin xyz="0 0 0" rpy="0 0 0"/>
      <geometry>
        <mesh filename="package://fanuc_cr7ia_support/meshes/cr7ia/visual/base_link.stl"/>
      </geometry>
      <material name="">
        <color rgba="0.23921568627450981 0.23921568627450981 0.23921568627450981 1.0"/>
      </material>
    </visual>
    <collision>
      <origin xyz="0 0 0" rpy="0 0 0"/>
      <geometry>
        <mesh filename="package://fanuc_cr7ia_support/meshes/cr7ia/collision/base_link.stl"/>
      </geometry>
    </collision>
  </link>
  <link name="link_1">
    <visual>
      <origin xyz="0 0 0" rpy="0 0 0"/>
      <geometry>
        <mesh filename="package://fanuc_cr7ia_support/meshes/cr7ia/visual/link_1.stl"/>
      </geometry>
      <material name="">
        <color rgba="0.0 0.6078431372549019 0.27450980392156865 1.0"/>
      </material>
    </visual>
    <collision>
      <origin xyz="0 0 0" rpy="0 0 0"/>
      <geometry>
        <mesh filename="package://fanuc_cr7ia_support/meshes/cr7ia/collision/link_1.stl"/>
      </geometry>
    </collision>
  </link>
  <link name="link_2">
    <visual>
      <origin xyz="0 0 0" rpy="0 0 0"/>
      <geometry>
        <mesh filename="package://fanuc_cr7ia_support/meshes/cr7ial/visual/link_2.stl"/>
      </geometry>
      <material name="">
        <color rgba="0.0 0.6078431372549019 0.27450980392156865 1.0"/>
      </material>
    </visual>
    <collision>
      <origin xyz="0 0 0" rpy="0 0 0"/>
      <geometry>
        <mesh filename="package://fanuc_cr7ia_support/meshes/cr7ial/collision/link_2.stl"/>
      </geometry>
    </collision>
  </link>
  <link name="link_3">
    <visual>
      <origin xyz="0 0 0" rpy="0 0 0"/>
      <geometry>
        <mesh filename="package://fanuc_cr7ia_support/meshes/cr7ia/visual/link_3.stl"/>
      </geometry>
      <material name="">
        <color rgba="0.0 0.6078431372549019 0.27450980392156865 1.0"/>
      </material>
    </visual>
    <collision>
      <origin xyz="0 0 0" rpy="0 0 0"/>
      <geometry>
        <mesh filename="package://fanuc_cr7ia_support/meshes/cr7ia/collision/link_3.stl"/>
      </geometry>
    </collision>
  </link>
  <link name="link_4">
    <visual>
      <origin xyz="0 0 0" rpy="0 0 0"/>
      <geometry>
        <mesh filename="package://fanuc_cr7ia_support/meshes/cr7ial/visual/link_4.stl"/>
      </geometry>
      <material name="">
        <color rgba="0.0 0.6078431372549019 0.27450980392156865 1.0"/>
      </material>
    </visual>
    <collision>
      <origin xyz="0 0 0" rpy="0 0 0"/>
      <geometry>
        <mesh filename="package://fanuc_cr7ia_support/meshes/cr7ial/collision/link_4.stl"/>
      </geometry>
    </collision>
  </link>
  <link name="link_5">
    <visual>
      <origin xyz="0 0 0" rpy="0 0 0"/>
      <geometry>
        <mesh filename="package://fanuc_cr7ia_support/meshes/cr7ia/visual/link_5.stl"/>
      </geometry>
      <material name="">
        <color rgba="0.0 0.6078431372549019 0.27450980392156865 1.0"/>
      </material>
    </visual>
    <collision>
      <origin xyz="0 0 0" rpy="0 0 0"/>
      <geometry>
        <mesh filename="package://fanuc_cr7ia_support/meshes/cr7ia/collision/link_5.stl"/>
      </geometry>
    </collision>
  </link>
  <link name="link_6">
    <visual>
      <origin xyz="0 0 0" rpy="0 0 0"/>
      <geometry>
        <mesh filename="package://fanuc_cr7ia_support/meshes/cr7ia/visual/link_6.stl"/>
      </geometry>
      <material name="">
        <color rgba="0.23921568627450981 0.23921568627450981 0.23921568627450981 1.0"/>
      </material>
    </visual>
    <collision>
      <origin xyz="0 0 0" rpy="0 0 0"/>
      <geometry>
        <mesh filename="package://fanuc_cr7ia_support/meshes/cr7ia/collision/link_6.stl"/>
      </geometry>
    </collision>
  </link>
  <joint name="joint_1" type="revolute">
    <origin xyz="0 0 0.457" rpy="0 0 0"/>
    <parent link="base_link"/>
    <child link="link_1"/>
    <axis xyz="0 0 1"/>
    <limit effort="0" lower="-2.9671" upper="2.9671" velocity="6.4577"/>
  </joint>
  <joint name="joint_2" type="revolute">
    <origin xyz="0.05 0 0" rpy="0 0 0"/>
    <parent link="link_1"/>
    <child link="link_2"/>
    <axis xyz="0 1 0"/>
    <limit effort="0" lower="-1.1519" upper="1.7453" velocity="5.4105"/>
  </joint>
  <joint name="joint_3" type="revolute">
    <origin xyz="0 0 0.440" rpy="0 0 0"/>
    <parent link="link_2"/>
    <child link="link_3"/>
    <axis xyz="0 -1 0"/>
    <limit effort="0" lower="-2.4397" upper="4.2586" velocity="7.1558"/>
  </joint>
  <joint name="joint_4" type="revolute">
    <origin xyz="0 0 0.035" rpy="0 0 0"/>
    <parent link="link_3"/>
    <child link="link_4"/>
    <axis xyz="-1 0 0"/>
    <limit effort="0" lower="-3.3161" upper="3.3161" velocity="9.5993"/>
  </joint>
  <joint name="joint_5" type="revolute">
    <origin xyz="0.420 0 0" rpy="0 0 0"/>
    <parent link="link_4"/>
    <child link="link_5"/>
    <axis xyz="0 -1 0"/>
    <limit effort="0" lower="-2.0944" upper="2.0944" velocity="9.5120"/>
  </joint>
  <joint name="joint_6" type="revolute">
    <origin xyz="0.080 0 0" rpy="0 0 0"/>
    <parent link="link_5"/>
    <child link="link_6"/>
    <axis xyz="-1 0 0"/>
    <limit effort="0" lower="-6.2832" upper="6.2832" velocity="17.4532"/>
  </joint>
  <link name="base"/>
  <joint name="base_link-base" type="fixed">
    <origin xyz="0 0 0.457" rpy="0 0 0"/>
    <parent link="base_link"/>
    <child link="base"/>
  </joint>
  <link name="flange"/>
  <joint name="joint_6-flange" type="fixed">
    <origin xyz="0 0 0" rpy="0 0 0"/>
    <parent link="link_6"/>
    <child link="flange"/>
  </joint>
  <link name="tool0"/>
  <joint name="link_6-tool0" type="fixed">
    <origin xyz="0 0 0" rpy="3.141592653589793 -1.5707963267948966 0"/>
    <parent link="flange"/>
    <child link="tool0"/>
  </joint>
</robot>
